Workbook

Sheet README
A1: TFM - Master Revision Matrix v30
A2: Single source of truth for the jury-revision process. Updated 9-Oct-2026 after closing the Econometric Panel Data Freeze Gate. The reproducible builder now writes and validates panel_main_and_robustness_rebuilt.xlsx with 4,648 bond-month rows, 19 columns, 103 bonds and 48 issuers while preserving the legacy 4,229-row workbook unchanged. BCB SGS 13762 Gross General Government Debt (% GDP) now uses the frozen uniform L2 reference-month timing. Sovereign Risk (BRL) keeps the validated WP-02 LTN/NTN-F-vs-DI arithmetic and is mapped contemporaneously inside WP-06: 3,918 rows are populated from Jan-2016 onward and 730 pre-2016 rows remain intentionally missing; there is no backward time extrapolation and the legacy synthetic-CDS/latest-curve mapper remains rejected. Full overlap reconciliation passed: metadata plus VIX/Fed 3M OIS/USD-BRL/GDP reconcile exactly on 4,226 common bond-months; relative issue size is exact; accounting differences follow the frozen PIT timing; residual maturity differs by at most 1/252 year from the legacy convention; the revised spread and fiscal/sovereign constructs change by design. Reproducibility commit 23435a4 contains the builder, candidate panel and required canonical inputs. CURRENT: WP-07 is active — reset inference to the single bond-FE / Driscoll-Kraay core table, then run the agreed targeted robustness checks.
A3: v30 update | B3: 9-Oct-2026: Data Freeze Gate PASSED. Sovereign panel mapping was frozen and implemented without reopening WP-02: same-date nominal government nodes are used only from 2016 onward; flat-forward interpolation is used between contemporaneous tenor nodes, endpoint-flat mapping outside the available tenor range, and a single observed node is carried across corporate maturities on that same date. No sovereign value is time-extrapolated back into 2010-2015, leaving 730 intentionally missing rows and 3,918 populated rows. BCB SGS 13762 public-debt/GDP now applies the frozen uniform L2 reference-month timing across all 175 panel months. The candidate panel was assembled and validated at 4,648 rows x 19 columns, 103 bonds, 48 issuers, 0 duplicate bond-month keys and complete coverage for every baseline field other than the documented pre-2016 sovereign gap. Sample reconciliation: 4,226 legacy bond-months retained, 422 newly recovered observations added, and three AN275276 Corp legacy rows (May-Jul 2017) intentionally removed because the revised ANDE replacement history begins 29-Aug-2017; net change +419. Unchanged metadata and VIX/Fed3M/USD-BRL/GDP match exactly on all 4,226 common rows; relative issue size also matches exactly. Expected differences in spreads, public debt/GDP, PIT liquidity/leverage, BUS/252 maturity and sovereign risk are documented. The rebuilt panel and reproducible builder were committed as 23435a4 (Build reproducible frozen econometrics panel). WP-06 is Done; WP-07 is now In progress.
A4: Purpose and governance
A5: Purpose | B5: Use the Master Matrix as the authoritative record of every jury issue, Martin's disposition, the required evidence/change, dependencies and completion status.
A6: Workflow status | B6: The Econometric Panel Data Freeze Gate is CLOSED/PASSED. The authoritative reproducible candidate is datos_y_modelos/db/econometrics_db/panel_main_and_robustness_rebuilt.xlsx (4,648 x 19; 103 bonds; 48 issuers). The legacy panel_main_and_robustness.xlsx remains an untouched archival comparison file. Fiscal control is BCB SGS 13762 Gross General Government Debt (% GDP) with uniform L2 timing; accounting controls use the frozen PIT quarter-selection rules; relative issue size and BUS/252 residual maturity are reproducible; Sovereign Risk (BRL) is populated contemporaneously from 2016 onward with 730 documented pre-2016 missing rows and no backward time extrapolation. Ratings remain descriptive and the revised corporate-pricing/BVAL source hierarchy remains frozen. CURRENT: WP-07 — audit/execute the final bond-FE Driscoll-Kraay setup and produce the single core table, followed by targeted robustness under WP-08.
A7: Scope rule | B7: Every jury point must map to a change, diagnostic, defense answer or reasoned non-change. Not every suggested extension must be estimated.
A8: v16 update | B8: 2-Oct-2026: nominal Fed 3M Forward audit completed end-to-end. Bloomberg USSOC Curncy / PX_LAST (3M USD OIS) matched all 164 distinct panel months exactly (0 mismatches; max absolute difference 0.0). Baseline Stata uses the series directly in percentage points with no log, standardization or /100 scaling; only the separate macro-difference robustness creates D.fed_3m_forward. Thesis wording now keeps “Fed 3M Forward” as the intuitive label but defines the underlying 3M USD OIS precisely and states that it is forward-looking in economic content, not a forward-starting 3Mx3M rate. MR-09 is closed; any post-freeze raw/partial correlations and final VIX sign/H1 interpretation are tracked under MR-18/MR-19. Next pre-freeze audit: USD/BRL.
A9: v23 update | B9: 4-Oct-2026: days_to_maturity completed the six-step audit. Source field is contractual MATURITY from universo_brazil_deb_des.xlsx / db_values_only; all 103 panel bonds map uniquely with 0 missing maturities. The monthly calendar is the common corporate-YTM / real-curve obs_date set: 175 unique dates from Dec-2010 to Jun-2025, exactly one per month and identical across both inputs; 62 dates are before literal calendar month-end. The stored panel variable is not days: days_to_maturity x 252 is an integer for every row, and 4,229/4,229 observations reproduce exactly as ANBIMA business days from obs_date through maturity, inclusive of a valid maturity date, divided by 252, with 20 November included as a holiday from 2024 onward. Stata uses this BUS/252-year level directly. Preferred label: residual bond maturity (BUS/252 years) / plazo residual al vencimiento (años, BUS/252). The current DayCounts helper omits 20 November and excludes the terminal date, so align/document that helper during the final controlled rebuild; do not change the historical panel values ad hoc. NEXT: reconcile synthetic_cds_brl with the validated Sovereign Risk (BRL) / sovereign_spread_brl construction.
A10: Authoritative inputs
A11: Source file / message | B11: Role | C11: Date/pages | D11: How used | E11: Current status
A12: TFM_Maestria_Economia_Siqueira_Thiago_Abril_10_2026.pdf | B12: Submitted thesis baseline | C12: 69 pages | D12: Locations, equations, tables, figures and annexes | E12: Frozen baseline
A13: Ailin - Informe Preliminar TFM_Siqueira_Thiago (2).pdf | B13: Jury report + Martin annotations | C13: 11 pages | D13: Criticisms A-01 to A-18 and annotated dispositions | E13: Integrated
A14: Maximo Sangiacomo - Evaluacion_TFM_Siqueira_Thiago (2).pdf | B14: Jury report + Martin annotations | C14: 5 pages | D14: Criticisms M-01 to M-18 and priority technical exercises | E14: Integrated - primary substantive priority
A15: Devolucion DM - Daniel Milia.pdf | B15: Third jury report | C15: 18-Sep-2026; 3 pages | D15: Criticisms D-01 to D-18 and defense guidance | E15: Integrated; director reviewed 24-Sep-2026
A16: Martin Grandes - WhatsApp audio/text + Zoom meeting | B16: Director follow-up guidance | C16: Sep-2026 through 2-Oct-2026 | D16: SELIC, dynamics, sovereign ceiling, DK/PCSE, nominal FED3M, table design, robustness sequence, Sovereign Risk (BRL), two-spread specification, liquidity proxy, VIX defense, ratings scope, stale-price/BVAL treatment, presentation design and deadlines | E16: Integrated as MG-01 to MG-29
A17: Proceso de presentacion y evaluacion del Trabajo Final - Res.CD 1313/2023 | B17: Institutional process | C17: Sep-2023; 1 page | D17: Formal stages and generic time windows | E17: Exact project deadline still to enter
A18: Tabla para nuevas estimaciones panel-Siqueira & Grandes 25-9-2026.docx | B18: Director-provided estimation template | C18: 25-Sep-2026; 1 page | D18: Exact four-column FE-Driscoll-Kraay variable-inclusion grid and requested output statistics | E18: Integrated; two layout ambiguities flagged for confirmation
A19: Revision categories
A20: Category | B20: Definition | C20: Default implication
A21: A - Methodological issue / additional estimation | B21: Measurement, identification, data or inference concern. | C21: Change data/model and regenerate affected outputs.
A22: B - Clarification / reframing | B22: Valid criticism mainly solved through precise definitions, interpretation or wording. | C22: Rewrite after final estimates; may include a small diagnostic.
A23: C - Presentation / structure / literature / documentation | B23: Presentation, literature, reporting, provenance or reproducibility. | C23: Revise text/tables/appendix/package; not necessarily new estimation.
A24: D - Not endorsed / optional / response only | B24: Request rejected, narrowed or treated as optional/future research. | C24: No mandatory thesis change; answer in memo/defense or add only if low cost.
A26: Workbook map
A27: Dashboard | B27: Formula-driven overview of priorities, counts, current package and process status.
A28: Process & Deadlines | B28: Institutional stages, generic windows and project-specific control fields.
A29: Revision Tracker | B29: Sixteen dependency-based work packages. Update Status and Working notes.
A30: Master Matrix | B30: Thirty-four consolidated revision issues across all jurors and director guidance.
A31: Juror Log | B31: Every distinct juror criticism mapped to one or more master issues.
A32: Director Guidance | B32: Traceability for Martin's audio/text decisions through the 2-Oct-2026 Zoom meeting, including updated econometric, data-quality, ratings and delivery guidance.
A33: Overlap Map | B33: Unified resolution of recurring issues to prevent duplicate work.
A34: Action Sequence | B34: Dependency order that minimizes rework.
A35: Estimation Plan | B35: Current FE-Driscoll-Kraay model grid, post-freeze robustness checks, pricing-data QA controls, ratings response and 10-Oct delivery target; Data Freeze passed 9-Oct-2026.
A36: v4 Change Log | B36: Historical changes introduced on 24-Sep-2026.
A37: v5 Change Log | B37: Exact changes introduced from Martin Grandes' 25-Sep-2026 instructions.
A38: v6 Change Log | B38: Changes introduced from Martin Grandes' 25-Sep-2026 sovereign-risk clarification and workflow handoff from WP-01 to WP-02.
... A62: v30 Change Log | B62: Changes introduced on 9-Oct-2026 after implementing the frozen sovereign mapping and public-debt L2 timing, writing/reconciling the 4,648-row candidate panel, passing the Data Freeze Gate, and committing the reproducible econometrics panel under 23435a4.

Sheet Dashboard
A1: Revision Dashboard
A2: Formula-driven from the Master Matrix, Revision Tracker and Process & Deadlines. Updated 9-Oct-2026 after the Econometric Panel Data Freeze Gate PASSED. The reproducible builder now writes panel_main_and_robustness_rebuilt.xlsx with 4,648 rows, 19 columns, 103 bonds and 48 issuers while leaving the legacy 4,229-row panel untouched. BCB SGS 13762 uses the frozen uniform L2 timing. Sovereign Risk (BRL) retains the closed WP-02 LTN/NTN-F-vs-DI definition and now has a documented same-date panel mapping: 3,918 rows populated from 2016 onward and 730 pre-2016 rows intentionally missing, with no backward time extrapolation. Full overlap reconciliation passed and the reproducible package was committed as 23435a4. CURRENT: WP-07 — reset inference to the single bond-FE / Driscoll-Kraay table, then execute WP-08 targeted robustness.
A4: Issue portfolio
A5: Metric | B5: Count | C5: Meaning | E5: Martin position | F5: Count | G5: Meaning
A6: Total master issues | B6: =COUNTA('Master Matrix'!A4:A200) | C6: Distinct consolidated issues. | E6: Agrees / strongly agrees | F6: =COUNTIF('Master Matrix'!H4:H200,E6) | G6: Explicitly endorsed.
A7: Critical priority | B7: =COUNTIF('Master Matrix'!D4:D200,"Critical") | C7: Can affect acceptance or downstream results. | E7: Partially agrees | F7: =COUNTIF('Master Matrix'!H4:H200,E7) | G7: Accepted with scope limits.
A8: Category A | B8: =COUNTIF('Master Matrix'!K4:K200,"A*") | C8: Measurement/diagnostics/estimation. | E8: Disagrees / not endorsed | F8: =COUNTIF('Master Matrix'!H4:H200,E8) | G8: Response only or future research.
A9: Category B | B9: =COUNTIF('Master Matrix'!K4:K200,"B*") | C9: Clarification/reframing. | E9: No explicit position | F9: =COUNTIF('Master Matrix'!H4:H200,E9) | G9: No direct disposition.
A10: Category C | B10: =COUNTIF('Master Matrix'!K4:K200,"C*") | C10: Presentation/literature/documentation.
A11: Category D | B11: =COUNTIF('Master Matrix'!K4:K200,"D*") | C11: Optional or non-endorsed.
A12: Changes required | B12: =COUNTIF('Master Matrix'!Q4:Q200,"Yes*") | C12: Mandatory/minimum-scope changes.
A13: Done | B13: =COUNTIF('Master Matrix'!R4:R200,"Done") | C13: Completed master issues.
A15: Critical workstreams - recommended order
A16: Order | B16: Workstream | C16: Master issues | D16: Why
A17: 1 | B17: Correct spread construction - measurement audit closed | C17: MR-03 | D17: Dependent-variable measurement audit completed; downstream regressions remain to be regenerated.
A18: 2 | B18: Sovereign Risk (BRL) construction - WP-02 closed; WP-06 panel mapping resolved/frozen | C18: MR-01 / MR-02 | D18: WP-02 remains closed upstream: 252 LTN + 330 NTN-F = 582 sovereign observations validated against same-date exact-tenor DI, geometric bps, exact-node guard, pytest 5/5 and commit b551414. WP-06 now supplies the panel mapping without reviving the legacy synthetic-CDS/latest-curve mapper: same-date mapping only; flat-forward interpolation between tenor nodes; endpoint-flat mapping outside the contemporaneous tenor range; single-node flat mapping when only one nominal bond is available. No backward time extrapolation into 2010-2015. Result: 3,918 populated bond-dates and 730 documented missing pre-2016 rows.
A19: 3 | B19: Issue-size identification - closed (WP-03) | C19: MR-14 | D19: Closed 30-Sep: amount_issued_to_bs_tot_asset reconstructed for 4,229/4,229 observations; 98/103 bonds (95.15%) vary within bond; variable retained in bond FE; ‰ units and relative-size interpretation documented; one-quarter-lagged denominator reserved as robustness.
A20: 4 | B20: Baseline explanatory-variable audits / Data Freeze Gate - PASSED | C20: Reproducible 4,648 x 19 panel generated, reconciled and committed; legacy panel preserved | D20: Data Freeze PASS: rebuilt panel has 4,648 rows, 19 columns, 103 bonds, 48 issuers, 0 duplicate bond-month keys and complete baseline coverage except the documented 730 pre-2016 sovereign rows. SGS 13762 uniform L2 timing is implemented. Sample bridge versus legacy: 4,226 common bond-months, 422 new rows, three intentional AN275276 Corp removals (May-Jul 2017; revised ANDE history starts 29-Aug-2017), net +419. Metadata and VIX/Fed3M/USD-BRL/GDP match exactly on common rows; relative issue size matches exactly; accounting and maturity differences follow frozen timing/day-count rules; spread, fiscal and sovereign changes are intentional methodology revisions. Builder + candidate + required inputs committed as 23435a4.
A21: 5 | B21: Single DK results table and inference reset - CURRENT (WP-07) | C21: MR-16 / MR-17 / MR-18 / MR-24 | D21: Data Freeze has passed. CURRENT: audit the exact bond-FE / Driscoll-Kraay implementation, lock lag and finite-sample choices, document FE coefficient estimation versus DK covariance/inference, and rerun the four-model core table on the frozen rebuilt panel. Keep plain FE/PCSE out of the main table; retain them only as qualified diagnostics/appendix if useful. Then execute WP-08 targeted robustness, including Brazil 3M DI variants. Target package for Martin remains 10-Oct-2026.
A22: 6 | B22: Ratings evidence / bounded heterogeneity response - EVIDENCE AUDIT CLOSED | C22: MR-06 / MR-07 | D22: Bloomberg point-in-time rating audit completed on the exact 4,229 bond-month sample using bond_id + obs_date overrides. Global LT local-currency issuer fields are too sparse for a baseline control (>=1 usable agency 41.6%; 41/103 bonds, 17/48 legal issuers). Brazilian national-scale LT issuer fields provide broader complementary descriptive coverage (>=1 agency 75.8%; 84/103 bonds, 37/48 issuers) but are a distinct scale and must not be mixed with global ratings. Agencies remain separate; no silent parent/issue fallback or synthetic composite. Primary use is the issuer/company table, appendix and jury response. Extra interaction regressions remain optional only if later powered and useful. Audit files stored under datos_y_modelos/db/ratings/; commit b087203.
A23: 7 | B23: Hypothesis-result/sign rewrite | C23: MR-19 / MR-30 / MR-31 / MR-32 | D23: Daniel's valid contribution is primarily expositional and follows empirical freeze.
A24: 8 | B24: Replication and resubmission | C24: MR-27 | D24: Required alongside the revised thesis.
A25: Live revision status
A26: Current package | B26: =IFERROR(INDEX('Revision Tracker'!B12:B100,MATCH("In progress",'Revision Tracker'!J12:J100,0)),"")
A27: Current task | B27: =IFERROR(INDEX('Revision Tracker'!E12:E100,MATCH("In progress",'Revision Tracker'!J12:J100,0)),"")
A28: Completed packages | B28: =COUNTIF('Revision Tracker'!J12:J100,"Done") | C28: of 16
A29: Overall progress | B29: =B28/16
A30: Current gate | B30: =IFERROR(INDEX('Revision Tracker'!K12:K100,MATCH("In progress",'Revision Tracker'!J12:J100,0)),"")
A32: Institutional process status
A33: Third report | B33: ='Process & Deadlines'!B5
A34: Daniel resolution | B34: ='Process & Deadlines'!B6
A35: Director review | B35: ='Process & Deadlines'!B7
A36: Current branch | B36: ='Process & Deadlines'!B8
A37: Official due date | B37: ='Process & Deadlines'!B9
A38: Days remaining | B38: ='Process & Deadlines'!B10
A39: Next formal step | B39: ='Process & Deadlines'!B11
A40: Seminar table target | B40: ='Process & Deadlines'!B13

Sheet Process & Deadlines
A1: Institutional Process & Deadlines
A2: Official generic time windows plus project-specific controls. Enter the exact official resubmission deadline when confirmed.
A4: Current project control
A5: Third jury report received | B5: Yes - Daniel Milia report dated 18-Sep-2026
A6: Daniel formal resolution | B6: Pasa a Defensa (favorable)
A7: Director review of Daniel | B7: Completed 24-Sep-2026 - less substantive; selective exposition/diagnostics/bibliography changes
A8: Current formal branch | B8: Awaiting official confirmation
A9: Official resubmission deadline
A10: Days remaining | B10: =IF(B9="","",B9-TODAY())
A11: Next formal step | B11: Confirm Ailin and Maximo formal resolutions, exact due date and whether a revised filing is formally required.
A12: Control note | B12: The user reports that a deadline exists, but the exact date is not in the process sheet.
A13: Paper/seminar table target | B13: 10-Oct-2026 - send Martin updated corrected FE-Driscoll-Kraay regressions (core models plus agreed robustness checks) and an updated, more visual/concise presentation. Planned joint review: week of 13-Oct-2026; refine presentation/abstract after seeing the new results.
A14: Official process and generic time windows
A15: Step | B15: Process stage | C15: Trigger | D15: Official time limit | E15: Current relevance | F15: Owner | G15: Status | H15: Evidence / next action
A16: 1 | B16: PTFM evaluation | C16: Formal receipt of project proposal | D16: 30 days | E16: Historical - not current | F16: Academic authority | G16: Not current | H16: Included for completeness.
A17: 2 | B17: PTFM correction, if required | C17: Authority requests project corrections | D17: 1 to 3 months | E17: Historical - not current | F17: Student + director | G17: Not current | H17: Not the current thesis-evaluation branch.
A18: 3 | B18: TFM review / jury convocation | C18: Formal receipt of TFM | D18: 45 days | E18: Completed | F18: Academic authority | G18: Completed | H18: The thesis was sent to three jurors.
A19: 4 | B19: Preliminary individual reports | C19: Jurors receive the TFM | D19: 45 days | E19: Completed - all three reports received | F19: Each juror | G19: Completed | H19: Daniel is the third report; dated 18-Sep-2026 and favorable.
A20: 5 | B20: Revision and resubmission, if formally required | C20: One or more resolutions require revision | D20: 1 to 4 months, set by authority | E20: Current only if official branch is revision | F20: Student + director | G20: Pending confirmation | H20: Enter the exact date in C9.
A21: 6 | B21: Second preliminary reports | C21: Revised TFM is formally resubmitted | D21: 45 days | E21: Contingent on revision branch | F21: Each juror | G21: Not started | H21: Jurors decide whether the revised version can pass to defense.
A22: 7 | B22: Oral and public defense | C22: Three favorable reports received | D22: Within 45 days | E22: Current if all three resolutions are favorable | F22: Program direction + student + jurors | G22: Pending confirmation | H22: Confirm Ailin/Maximo resolutions and coordinate defense date.
A24: Source: Proceso de presentacion y evaluacion del Trabajo Final de Maestria o Especializacion, Res.CD No. 1313/23 (Sep-2023). Daniel status: Devolucion DM - Daniel Milia, 18-Sep-2026. Director guidance: WhatsApp 24-27 Sep-2026 plus Zoom meeting 2-Oct-2026, including DK/PCSE, VIX, liquidity, ratings, stale-price/BVAL treatment and the updated 10-Oct delivery / week-of-13-Oct review sequence. Estimation template: Tabla para nuevas estimaciones panel, 25-Sep-2026.

Sheet Revision Tracker
A1: TFM Jury Revision Tracker
A2: Sixteen dependency-based work packages consolidate 34 master issues. Updated 9-Oct-2026 after closing WP-06 / the Econometric Panel Data Freeze Gate. The reproducible builder writes and validates a 4,648-row x 19-column panel (103 bonds, 48 issuers), implements the frozen SGS 13762 L2 fiscal timing and documented Sovereign Risk (BRL) mapping, and preserves the legacy workbook unchanged. Reconciliation passed and commit 23435a4 records the frozen package. CURRENT: WP-07 is In progress — reset inference to the single bond-FE / Driscoll-Kraay table. WP-08 follows with the director-requested core grid and targeted robustness.
A4: Current package | B4: =IFERROR(INDEX(B12:B100,MATCH("In progress",J12:J100,0)),"")
A5: Current task | B5: =IFERROR(INDEX(E12:E100,MATCH("In progress",J12:J100,0)),"")
A6: Completed packages | B6: =COUNTIF(J12:J100,"Done")
A7: Overall progress | B7: =B6/16
A8: Current status | B8: =IFERROR(INDEX(J12:J100,MATCH("In progress",J12:J100,0)),"")
A9: Gate before moving on | B9: =IFERROR(INDEX(K12:K100,MATCH("In progress",J12:J100,0)),"")
A11: Seq. | B11: WP ID | C11: Phase | D11: Master issue IDs | E11: Work package | F11: Why this is sequenced here | G11: Thesis location(s) | H11: Concrete deliverable | I11: Dependencies | J11: Status | K11: Gate / acceptance criterion | L11: Working notes
A12: 1 | B12: WP-01 | C12: Measurement | D12: MR-03 | E12: Recalculate the corporate spread using consistent compounding | F12: The dependent variable feeds every regression and conclusion. | G12: Sec. 2.2; Sec. 4.3; Sec. 4.5.2; Annex 8.7; all results | H12: Audited conventions; corrected spread series; old-vs-new comparison; unit tests. | I12: Submitted code/data and curve audit | J12: Done | K12: Approve formula, units, day-count, compounding and field types; benchmark/corporate inputs pass hand checks. | L12: Completed 25-Sep-2026: corrected the 2012-2013 NTN-B field contamination, revalidated the relevant government-curve inputs, checked corporate bond price/yield fields, and closed the corporate-spread measurement audit. Downstream estimates will be regenerated after WP-02.
A13: 2 | B13: WP-02 | C13: Measurement | D13: MR-01, MR-02 | E13: Verify Sovereign Risk (BRL) construction, common-reference logic and terminology | F13: Martin confirmed the intended sovereign regressor and preferred two-spread transmission specification. The nominal sovereign implementation was validated end-to-end: LTN and NTN-F government yields are compared with the same-date DI reference curve at exact BUS/252 residual tenor. Thesis terminology and documentation were subsequently aligned, including the distinction between the nominal sovereign DI benchmark and the IPCA-real corporate benchmark. | G13: Secs. 2.2, 4.3, 4.5.1-4.5.3, 5.2.3; Annex 8.3 and 8.8-8.9 | H13: COMPLETED: code/formula audit; 252 LTN + 330 NTN-F maturity-matched sovereign spreads; same-date exact-tenor DI benchmark; geometric annual-effective spread; exact-node interpolation guard; regression tests; variable rename to sovereign_spread_brl; removal of synthetic-CDS wording; explicit methodology/appendix formula; literature/two-spread rationale; corporate-IPCA versus nominal-DI indexation clarification; affected figures/tables relabeled. | I13: WP-01 | J13: Done | K13: Corporate Spread is documented against the matched IPCA-real reference curve and sovereign_spread_brl against the matched nominal DI reference curve, each at the appropriate date/tenor/indexation. The thesis explains why the two spreads are modeled separately rather than collapsed into a direct corporate-minus-sovereign spread; CDS terminology is removed. Any final search for unintended USD CDS usage is a pre-estimation integrity check and does not reopen WP-02. | L13: Closed 29-Sep-2026. Nominal Sovereign Risk (BRL) implementation validated on 582/582 observations with 0 missing benchmarks and max absolute benchmark difference 5.33e-13 bp; spread arithmetic independently verified; BZDIOVRA cash + liquid DI futures + Pre x DI swaps; exact BUS/252 tenor; pytest 5/5; commit b551414 pushed. Canonical source governance reconfirmed 9-Oct-2026: domestic_sovereign_curve_brazil.xlsx = government-bond characteristics/metadata; govt_ya_ande.v3.xlsx = ANDE normalized government YAS yields (retaining the earlier NTN-B 2012-2013 field correction). Follow-up builder audit found no frozen rule for mapping the 582 nominal observations onto all 4,648 corporate bond-months and insufficient historical/tenor coverage in the current nominal universe. That is tracked under WP-06 and does not reopen the validated WP-02 spread formula/source decision.
A14: 3 | B14: WP-03 | C14: Data audit | D14: MR-14 | E14: Audit amount_issued_to_bs_tot_asset and within-bond variation | F14: A time-invariant issue-size variable cannot be estimated in bond FE. | G14: Table 1 H6; Secs. 4.5.3 and 4.7; Table 3; Sec. 5.2.4; Annex 8.6.2 and Table 7; Figure 3 | H14: COMPLETED: raw-field trace from AMT_ISSUED and issuer BS_TOT_ASSET; full-panel reconstruction; within-bond variation diagnostics; timing/scaling audit; retain/rename decision; one-quarter-lagged denominator robustness construction; thesis wording/table/figure alignment. | I14: Raw panel and construction code | J14: Done | K14: PASSED: 4,229/4,229 panel observations reconstructed from raw sources; 98/103 bonds (95.15%) have within-bond variation; the regressor is identified in bond FE; ‰ units, quarterly timing and interpretation are documented; lagged-quarter timing robustness is available. | L14: Closed 30-Sep-2026. The jury concern applies to AMT_ISSUED in levels, but the estimated variable is AMT_ISSUED / BS_TOT_ASSET. AMT_ISSUED is fixed by bond; quarterly issuer assets generate within-bond variation. Raw-source reconstruction matched all 4,229 panel observations essentially exactly. 98/103 bonds vary within bond; five very-short-history bonds do not. The stored scale is per-mille (‰). A one-quarter-lagged BS_TOT_ASSET version retains 4,223/4,229 observations, correlates 0.9918 with the original, and preserves 98/103 varying bonds; its six missing observations are limited to two Serena bonds in 2022Q1 due to unavailable 2021Q4 assets. Decision: retain the existing contemporaneous relative-size variable in the main specification, reserve the lagged denominator as robustness, and interpret the coefficient as relative issue size versus issuer scale—not as a change in original amount issued. Thesis edits were completed across H6, methodology/FE identification, results, conclusions, Tables 3/7, Figure 3 and Annex 8.6.2. 2-Oct director confirmation: the numerator is static but the quarterly asset denominator varies. Martin agreed the audited ratio can remain. Turnover/amount outstanding is conceptually closer to secondary-market liquidity, but for these illiquid Brazilian bonds it may contain many zeros and little useful time variation. Frame the retained variable as relative issue size / primary-market issuance-liquidity, not a clean secondary-market turnover measure.
A15: 4 | B15: WP-04 | C15: Variables | D15: MR-04 | E15: Clarify SELIC baseline non-inclusion and run post-freeze Brazil 3M DI robustness checks | F15: SELIC anchors the short end of the local reference curve and its influence propagates through the curve; Martin's 3M Forward SELIC exercise is only a low-cost referee diagnostic, not a competing baseline specification. | G15: Secs. 3.1-3.3, 4.3, 4.5.3, 5.2-5.4, 6.1 | H15: Dual-rationale note plus post-freeze robustness: add the Brazil 3M DI proxy to the finalized model and compare the agreed specifications with nominal FED3M retained versus omitted, under the specified FX/sovereign exclusions. Keep the domestic short-rate exercise separate from the baseline and report only if informative. | I15: WP-01; final curve definitions | J15: Deferred | K15: Baseline omission is explicit; the local-curve embedding of SELIC is explained; any SELIC 3M Forward check follows the required exclusions, is labeled referee-only and does not replace the preferred model. | L15: 2-Oct meeting reconfirmed that the domestic 3M rate is a robustness exercise, not a baseline replacement. Data preparation is complete; run only after the Data Freeze Gate and core rerun. Include the with-FED3M / without-FED3M comparison in the 10-Oct package if the gate has passed.
A16: 5 | B16: WP-05 | C16: Jury response / Heterogeneity | D16: MR-06, MR-07 | E16: Prepare local-currency ratings evidence; keep heterogeneity extensions bounded | F16: 2-Oct guidance narrows the minimum reviewer response: ratings lag market spreads and are not the core object of the thesis; a descriptive local-currency issuer-rating table is sufficient to answer the point before considering extra regressions. | G16: Secs. 3.1, 3.3.2, 4.1, 4.3, 5.2.3, 6.1, 6.3 | H16: Use point-in-time issuer-rating evidence in the issuer/company table or appendix. Global LT local-currency issuer ratings are the conceptually closest measure but have insufficient exact-sample coverage for a baseline control; Brazilian national-scale LT issuer ratings are retained as clearly labelled complementary descriptive evidence only. Preserve agencies separately, document source/date/missing rules, distinguish issuer vs issue and global vs national scale, and do not silently substitute ultimate-parent ratings. Optional heterogeneity estimation remains post-core. | I16: Final issuer list; Bloomberg PIT rating audit; source/timing and missing-value rules | J16: Done | K16: Minimum response satisfied at the data/method level: exact-sample issuer ratings and coverage are documented; ratings are not forced into the baseline FE-DK regression; global and national scales remain separate; extra heterogeneity is optional. | L16: 7-Oct-2026 closure. Exact 4,229-row audit using bond_id + obs_date + RATING_AS_OF_DATE_OVERRIDE. Global LT LC usable coverage: S&P 1,572 (37.2%), Moody's 360 (8.5%), Fitch 1,461 (34.5%); >=1 agency 1,760 (41.6%), >=2 1,273 (30.1%), all three 360 (8.5%); 41/103 bonds and 17/48 legal issuers ever rated. Brazilian national-scale usable coverage: S&P 2,408 (56.9%), Moody's 542 (12.8%), Fitch 2,872 (67.9%); >=1 agency 3,204 (75.8%), >=2 2,105 (49.8%), all three 513 (12.1%); 84/103 bonds, 37/48 legal issuers, 26/27 parent groups; 82 bonds fully covered, 19 never covered, 2 partial. Eight Fitch AA(dza) rows were excluded as non-Brazil scale. Files: datos_y_modelos/db/ratings/issuer_ratings_global_lc_bond_level_panel_audit.xlsx and issuer_ratings_national_bond_level_panel_audit.xlsx. Commit b087203. ISSUER LC RATING CONTROL — FROZEN: descriptive evidence, not baseline regressor.
A17: 6 | B17: WP-06 | C17: Data Freeze Gate | D17: Baseline audits/decisions closed; reproducible 4,648 x 19 panel generated, reconciled and frozen | E17: Close the Econometric Panel Data Freeze Gate with one reproducible authoritative candidate panel | F17: Daniel asks for a direct H1-result link and better explanation of the negative sign. | G17: Secs. 3.1, 3.3.1, 4.1, 4.5.3, 5.2.1, 6.1 | H17: COMPLETED. Reproducible builder assembles the revised 4,648-row bond-month panel with corrected corporate spread; VIX/Fed3M/USD-BRL/GDP; SGS 13762 public debt/GDP under uniform L2 timing; PIT liquidity/leverage; relative issue size; BUS/252 residual maturity; and the frozen Sovereign Risk (BRL) same-date mapping. Sovereign mapping yields 3,918 populated rows from 2016 onward and 730 intentional pre-2016 missing rows with no backward time extrapolation. Candidate output panel_main_and_robustness_rebuilt.xlsx passes row/bond/issuer/key/missingness and variable-by-variable reconciliation. Legacy workbook remains untouched. | I17: Frozen builder + candidate 4,648 x 19 panel + reconciliation evidence + reproducibility commit 23435a4 | J17: Done | K17: PASSED 9-Oct-2026: sovereign mapping is documented/reproducible; SGS 13762 uses uniform L2; candidate panel passes structural and variable-level reconciliation; legacy workbook is preserved. FE-DK estimation may now proceed from the frozen rebuilt panel. | L17: Closed 9-Oct-2026. Final panel: 4,648 rows x 19 columns; 103 bonds; 48 issuers; 0 duplicate bond-month keys. Sovereign present 3,918 / missing 730, with missingness confined to pre-2016 dates. Sample reconciliation versus legacy: 4,226 common, 422 new, three intentional AN275276 Corp removals (May-Jul 2017) because the revised ANDE replacement series starts 29-Aug-2017. Metadata plus VIX/Fed3M/USD-BRL/GDP reconcile exactly on all common rows; relative issue size is exact; maturity max difference is 1/252 year; PIT accounting differences and revised spread/fiscal/sovereign constructs are documented and expected. Reproducibility commit: 23435a4 Build reproducible frozen econometrics panel.
A18: 7 | B18: WP-07 | C18: Estimator | D18: MR-16, MR-17, MR-23 | E18: Reset inference to one bond-FE Driscoll-Kraay table; remove plain FE and PCSE | F18: Martin confirmed the PCSE rationale and requested no separate conventional-FE or PCSE columns. | G18: Secs. 4.2, 4.6, 4.8, 5.1-5.3; Tables 2-3; Annex 8.10-8.11 | H18: Audit the exact FE/DK/PCSE commands and diagnostics; set the final DK lag/finite-sample choices; explain that bond FE defines the coefficient estimator while Driscoll-Kraay/PCSE address the covariance/inference layer; document which forms of heteroskedasticity, serial correlation and cross-sectional dependence each treatment is intended to handle; keep one main DK table. | I18: WP-01 to WP-06 final variable definitions | J18: In progress | K18: All main significance uses one DK setup; diagnostics are shown; the core table has no separate plain-FE or PCSE columns. | L18: Activated 9-Oct-2026 immediately after WP-06 Data Freeze PASS. Use panel_main_and_robustness_rebuilt.xlsx as the frozen estimation input. First task: audit the exact FE-DK commands/setup, choose and document the DK lag/finite-sample treatment, verify panel dimensions and covariance assumptions, and produce the single four-column core table. Plain FE/PCSE remain diagnostic/appendix only.
A19: 8 | B19: WP-08 | C19: Estimator | D19: MR-18 | E19: Produce the single four-model DK table and targeted robustness checks | F19: Updated director deliverable: corrected post-freeze regressions and presentation package by 10-Oct-2026. | G19: Secs. 4.6-4.8, 5.1-5.4; Annex 8.11 | H19: Four core bond-FE / Driscoll-Kraay columns using nominal FED3M; sovereign/local-macro and NER/RER variants as finalized; within R2/rho and diagnostics; Brazil 3M DI robustness with FED3M retained vs omitted; correlation matrix; pricing-data sensitivity where feasible. Use the frozen panel only. | I19: WP-01, WP-02, WP-04, WP-07; confirm template ambiguities | J19: Not started | K19: Core grid matches the director template; old FED3M Real is excluded; NER/RER and stacking ambiguities are confirmed; any SELIC columns are separate, referee-only diagnostics. | L19: 2-Oct meeting resets the old 30-Sep target. Aim to send Martin the new regressions plus an updated deck by 10-Oct-2026, then review in the week of 13-Oct. Keep the main table DK-only; alternative covariance outputs are appendix/internal diagnostics, not a horse race.
A20: 9 | B20: WP-09 | C20: Data quality / pre-freeze | D20: MR-25 | E20: Finalize stale-quote, BVAL and missing-price treatment before panel freeze | F20: Lagged quotes may mechanically create anomalous signs. | G20: Secs. 2.1.1, 4.5.2, 4.6, 5.2.1, 5.2.3, 6.1-6.3; Annex 8.2 and 8.5 | H20: Treat the revised corporate-pricing/source-selection workflow as the authoritative baseline input. The problematic BVAL/indicative observation was replaced by the next-best available source rather than retained under its odd convention; do not reopen that source decision absent material new evidence. Keep BVAL/indicative semantics explicit in the data appendix. Any alternative no-fill-forward/missing-price convention may be reported later as sensitivity, but it no longer blocks the reproducible panel build. | I20: WP-01 revised corporate pricing dataset; source-selection audit trail | J20: Done | K20: Pricing-source decision is explicit for the baseline and BVAL/indicative marks are not silently treated as executed transaction prices. Alternative missing-price treatment is sensitivity only and does not block the controlled panel reconstruction. | L20: 7-Oct-2026 governance closure based on the completed corporate-spread work: the affected BVAL value had already been replaced by the second-best available source because of its problematic convention. User/director discussion treated this issue as solved; do not reopen absent material evidence. Preserve the source hierarchy and rationale in the reproducible builder/data appendix.
A21: 10 | B21: WP-10 | C21: Identification | D21: MR-13, MR-15 | E21: Clarify identifying variation and panel imbalance | F21: Common regressors vary monthly; bond histories are unequal. | G21: Secs. 4.2-4.4, 4.7-4.8, 5.1, 5.3-5.4, 6.1; Annex 8.10 | H21: Variation-level table and T_i/coverage profile. | I21: WP-03 and WP-07 | J21: Not started | K21: Months, bonds, issuers, T_i distribution and FE limits are reported.
A22: 11 | B22: WP-11 | C22: Text/literature | D22: MR-11, MR-12, MR-21, MR-32, MR-34 | E22: Correct language and make bounded literature/theory updates | F22: Daniel's literature comments are secondary and should support, not expand, the empirical design. | G22: Introduction; Secs. 3-4; references; defense literature map | H22: Non-causal wording; citation corrections; construct-proxy table; closest-study comparison. | I22: Final empirical framing from WP-04, WP-08, WP-09 | J22: Not started | K22: Every citation supports the statement; the gap/proxies are demonstrated without theoretical overhaul.
A23: 12 | B23: WP-12 | C23: Reporting | D23: MR-22, MR-24 | E23: Build the single consolidated regression table and run table-to-text checks | F23: Final DK evidence must be readable and auditable. | G23: Table 3; Sec. 5.2.2; Annex Table 7 | H23: One FE-DK table with SE, N, panel dimensions, within R2, rho, DK lag/FE metadata and diagnostics panel. | I23: WP-08 final estimates | J23: Not started | K23: The requested four core columns and any optional SELIC columns are readable, auditable and matched exactly by the prose. | L23: Table design source: Martin's 25-Sep-2026 template.
A24: 13 | B24: WP-13 | C24: Interpretation | D24: MR-19, MR-26 | E24: Rewrite results and explain counterintuitive signs | F24: Daniel's central contribution is better H-result linkage; Brazil-specific mechanisms must be separated from evidence. | G24: Secs. 5.2-5.4 and 6.1-6.3 | H24: Robust/partial/null/unresolved hierarchy; H-result map; Brazil-specific mechanisms. | I24: WP-02, WP-04, WP-05, WP-08, WP-09, WP-12 | J24: Not started | K24: Every hypothesis and sign is tied to a final table or labeled as a mechanism/limitation.
A25: 14 | B25: WP-14 | C25: Narrative | D25: MR-30, MR-31, MR-32, MR-33 | E25: Rewrite gap, contribution, abstract/conclusions and final copy-edit | F25: Do this only after the empirical freeze; Daniel is treated selectively as exposition. | G25: Resumen/Abstract; Introduction; Secs. 5.4 and 6; entire-thesis QA | H25: Closest-study contribution; one central question; hypothesis scorecard; final language consistency. | I25: WP-13 | J25: Not started | K25: Question, contribution, tables and conclusions are consistent and appropriately bounded.
A26: 15 | B26: WP-15 | C26: Reproducibility | D26: MR-27, MR-28 | E26: Complete replication package and data provenance | F26: Ailin requests a runnable pipeline and Martin agrees. | G26: Secs. 4.4-4.5; Annex 8.1-8.14; source notes | H26: README, environment, scripts, queries, dates, hashes, consolidation rules, curve settings and clean-run evidence. | I26: All final code/outputs | J26: Not started | K26: A clean run regenerates every permitted output and provenance is complete.
A27: 16 | B27: WP-16 | C27: Resubmission | D27: MR-05, MR-08, MR-10, MR-20, MR-29; synthesis MR-30/31/32 | E27: Prepare response memo, defense and Bordeaux/Geneva materials | F27: All comments must receive a change, diagnostic, answer or reasoned non-change. | G27: Response memo; future research; defense/seminar deck; deadline checklist | H27: Issue-by-issue response memo; final single DK table; diagnostics; scoped non-changes; descriptive local-currency ratings evidence; confirmed deadlines; concise defense/Bordeaux/Geneva deck. After the 10-Oct regression package, make slides more visual and parsimonious, with the econometric results given adequate space and dense literature/method detail cut or moved to appendix. | I27: WP-01 to WP-15 | J27: Not started | K27: Every observation maps to evidence or a reasoned non-change; seminar materials use the agreed table; deadlines and formal branch are tracked. | L27: Updated near-term target: regressions + revised presentation to Martin by 10-Oct-2026; joint review planned for the week of 13-Oct-2026.

Sheet Master Matrix
A1: Master Revision Matrix
A2: One row per distinct issue across all three jurors. Updated through 9-Oct-2026: the Econometric Panel Data Freeze Gate has PASSED. The reproducible builder now writes panel_main_and_robustness_rebuilt.xlsx with 4,648 rows, 19 columns, 103 bonds and 48 issuers and preserves the legacy workbook unchanged. BCB SGS 13762 public debt/GDP uses the frozen uniform L2 timing. WP-02 remains closed at the sovereign source/formula level; WP-06 now provides a frozen same-date Sovereign Risk (BRL) panel mapping with 3,918 populated rows from 2016 onward and 730 intentional pre-2016 missing rows, with no backward time extrapolation. Full overlap reconciliation passed and commit 23435a4 records the reproducible package. CURRENT: WP-07 — bond-FE / Driscoll-Kraay inference reset and core table rerun.
A3: ID | B3: Source IDs | C3: Overlap group | D3: Priority | E3: Juror(s) | F3: Consolidated juror criticism | G3: Report location | H3: Martin position | I3: Martin annotation / evidence | J3: My diagnosis | K3: Revision category | L3: Thesis location | M3: Required action | N3: Estimation / work type | O3: Dependencies | P3: Acceptance criterion | Q3: Change required? | R3: Status | S3: Working notes
A4: MR-01 | B4: A-03, A-10, A-13; M-04, M-17, M-18; D-10, D-17 | C4: OG-01 | D4: Critical | E4: Ailin + Maximo + Daniel | F4: The sovereign-risk regressor and the dependent corporate spread share the IPCA benchmark. The jury asks whether this creates mechanical covariance and how the negative coefficient should be interpreted. | G4: Ailin pp. 2, 6-7 and M1; Maximo p. 2 sec. 1.2 and pp. 4-5; Daniel pp. 2-3 | H4: Agrees / strongly agrees | I4: 24-Sep-2026: Martin identifies this as the main priority and frames corporate excess/shortfall relative to the sovereign through the sovereign-ceiling hypothesis. 25-Sep: the sovereign regressor is a local BRL sovereign spread, government YTM minus the matched local risk-free/reference yield, not a CDS. 27-Sep: USD CDS 5Y was never part of the economic model. Corporate Spread and Sovereign Risk (BRL) should remain separate spreads over the same local reference curve so the model estimates the response of corporate spread to sovereign risk; a direct corporate-minus-sovereign spread is a related alternative, not the preferred econometric specification. | J4: Resolved. The jurors' shared-benchmark/mechanical-covariance concern was separated from the actual final implementation. Corporate spreads are measured against an IPCA-real reference curve, while sovereign_spread_brl uses nominal LTN/NTN-F minus the DI reference curve. The thesis now states that each spread is matched to its own instrument/indexation benchmark and explains why they remain separate variables in the sovereign-transmission regression. | K4: A - Methodological issue / additional estimation | L4: Sec. 2.2; Sec. 4.3; Sec. 4.5.1-4.5.3; Sec. 5.2.3; Annex 8.3 and 8.8-8.9 | M4: Completed: audit/document both formulas and tenor matching; distinguish the IPCA-real corporate benchmark from the nominal DI sovereign benchmark; explain the preferred two-spread transmission specification and the direct corporate-minus-sovereign alternative; remove synthetic-CDS terminology and align thesis figures/tables/appendix. Final model-panel integrity checks are deferred to the pre-estimation gate. | N4: Code/formula audit + terminology correction + re-estimation if implementation changes | O4: MR-03 measurement audit; local curve inputs; government-bond matching | P4: The thesis and code use explicit Corporate Spread and sovereign_spread_brl constructions with date/tenor/indexation matching appropriate to each instrument. The shared-benchmark concern is addressed without falsely claiming an identical curve; the two-spread specification is justified; no CDS label or pure-default interpretation remains. Final estimates will be refreshed only after the remaining regressor audits. | Q4: Yes | R4: Done | S4: Closed 29-Sep-2026. Sovereign code audit: 252 LTN + 330 NTN-F = 582 observations; 582/582 DI benchmarks reproduced; 0 missing; max abs diff 5.33e-13 bp; geometric spread verified; exact-node guard; pytest 5/5; commit b551414 pushed. Thesis edits completed across Resumen/Abstract, sovereign-risk literature/methodology, results terminology, annex construction, and Figures 3/4. Corporate IPCA-real versus nominal sovereign DI benchmark distinction is now explicit. 9-Oct-2026 follow-up: canonical metadata/YAS sources and the 582-observation WP-02 arithmetic remain valid, but full corporate-panel mapping was not part of that closure. Current nominal coverage is insufficient for a defensible 2010-2025 contemporaneous tenor match; this downstream blocker is assigned to WP-06. 9-Oct-2026 WP-06 closure: downstream panel mapping is now frozen and reproducible — same-date nominal mapping only, 3,918 populated rows from 2016 onward and 730 intentional pre-2016 missing rows; no backward time extrapolation. This closes the former coverage blocker without reopening WP-02.
A5: MR-02 | B5: A-03, A-13; M-04 | C5: OG-01 | D5: High | E5: Ailin + Maximo | F5: The labels synthetic CDS BRL and risk-free real curve overstate what is measured when the benchmark includes sovereign NTN-B yields and market-basis components. | G5: Ailin pp. 2, 6-7; Maximo p. 2 sec. 1.2 | H5: Agrees / strongly agrees | I5: 25-Sep-2026: Martin explicitly rejects the "synthetic CDS" label; there is no credit default swap in the construction. 27-Sep: he further clarifies that USD CDS 5Y was never part of the economic model and should not be introduced. The intended object remains a maturity-matched local-currency sovereign spread: government-bond yield minus the relevant futures/swap/interpolated local reference curve yield. | J5: Resolved. The final variable is sovereign_spread_brl / local-currency sovereign spread, not a CDS. The nominal DI reference curve and exact-tenor matching are documented, and language that could imply a pure default-protection measure was removed. The corporate IPCA-real benchmark is described separately so the indexation treatment is transparent. | K5: B - Clarification / reframing | L5: Resumen/Abstract; Sec. 2.2; Sec. 4.5.1-4.5.3; Sec. 5.2.3; Annex 8.3 and 8.8-8.9; Glossary | M5: Completed: rename the variable consistently as sovereign_spread_brl / sovereign risk in local currency; define it algebraically as government YTM versus the matched nominal DI reference yield; explain the DI curve construction and tenor matching; remove synthetic CDS BRL from thesis text, diagrams and table labels. Keep the director-confirmed USD CDS 5Y non-use as a final pre-estimation code-integrity check only. | N5: Terminology correction + code/formula verification | O5: MR-01 measurement decision | P5: One name and one formula are used throughout; the variable is never described as a CDS; the nominal DI reference curve and maturity matching are transparent; the implementation reproduces the documented construction; the IPCA-real corporate benchmark is separately identified. No USD CDS variable is to be introduced into the model. | Q5: Yes | R5: Done | S5: Thesis terminology/documentation closed 29-Sep-2026: sovereign_spread_brl replaced synthetic-CDS language in text, tables/diagrams and Annex construction. Implementation reconciliation closed 4-Oct-2026: the existing econometric panel/Stata synthetic_cds_brl field was proven to be a different legacy fixed-curve proxy and is NOT the validated sovereign_spread_brl series. Replacement with the validated control is required during the controlled final panel rebuild before new estimates. 9-Oct-2026 follow-up: do not rename or revive any legacy synthetic surface. The current task is to obtain/document a reproducible full-panel sovereign mapping consistent with the validated nominal LTN/NTN-F-vs-DI definition; coverage resolution is tracked under WP-06, not as a reopening of MR-02 terminology. 9-Oct-2026 WP-06 closure: the final rebuilt panel uses sovereign_spread_brl, not synthetic CDS; same-date mapping is documented and legacy latest-curve/NSS logic remains rejected. Sovereign values are intentionally unavailable pre-2016 rather than backfilled.
A6: MR-03 | B6: A-05 | C6: OG-02 | D6: Critical | E6: Ailin | F6: Spreads were computed by linear subtraction of yields despite compounding conventions. Ailin requests a geometric or log-consistent spread on matched curves. | G6: Ailin p. 2 sec. 2(c), p. 7, M2 | H6: Agrees / strongly agrees | I6: Martin explicitly instructed the spread recalculation. 2-Oct-2026: he expects the geometric-vs-arithmetic compounding correction itself to have only a small quantitative effect; the corrected price/yield field problems can matter more. Re-estimate only after the explanatory-variable Data Freeze Gate passes. | J6: Genuine dependent-variable measurement correction. Exact units, signs, field types and compounding must be audited before coding. | K6: A - Methodological issue / additional estimation | L6: Sec. 2.2 eq. (1); Sec. 4.3; Sec. 4.5.2 eq. (3); Annex 8.7; all empirical outputs | M6: Recompute each bond-month spread with consistent compounding, matched tenor and consistent YTM/zero conventions. Unit-test hand cases, compare old versus new series, and regenerate all estimates, tables and conclusions. | N6: Dependent-variable rebuild + full re-estimation | O6: Curve and yield convention audit | P6: Formula, units, day count and compounding are documented; old/new summary statistics and hand checks reproduce; all downstream outputs use the corrected series. | Q6: Yes | R6: In progress | S6: Corporate-spread measurement stage completed 25-Sep-2026: NTN-B 2012-2013 field contamination corrected and corporate yield inputs rechecked. 2-Oct director expectation: geometric compounding alone should barely move results; price/yield corrections may matter. MR-03 remains open only because downstream estimates/tables still need regeneration on the frozen panel. Reproducible builder now calculates the corrected corporate spread for all 4,648 revised bond-month rows; MR-03 remains open only for the post-freeze regression/table regeneration and final old-vs-new results interpretation.
A7: MR-04 | B7: A-02, A-04, A-14 | C7: OG-02 | D7: High | E7: Ailin | F7: Subtracting the real curve implicitly imposes unit exposure to the curve factor; the level/slope of Brazilian real rates may be omitted. | G7: Ailin p. 2 sec. 2(b), pp. 5-7, M3 | H7: Partially agrees | I7: 25-Sep: baseline SELIC non-inclusion rests on UIP overlap with FED3M plus expected BRL depreciation and on SELIC anchoring the short end of the local reference curve. 27-Sep: the Brazil 3M rate is referee-only. 2-Oct meeting reconfirmed the robustness exercise: after panel freeze, add the Brazil 3M DI proxy and compare the specified model with nominal FED3M retained versus omitted. | J7: Baseline omission is economically defensible and the referee-only domestic short-rate proxy is now fully sourced/documented. Because Models 5-6 depend on the final common regressor set, the regression stage is intentionally parked until all baseline explanatory variables are audited and the authoritative panel is frozen. | K7: A - Methodological issue / additional estimation | L7: Secs. 3.1-3.3; Sec. 4.3; Sec. 4.5.3; Sec. 5.2-5.4; Sec. 6.1 | M7: Keep SELIC/Brazil 3M DI out of the baseline and explain both reasons. After the Data Freeze Gate, merge the validated 3M DI series only into the robustness panel and run the agreed with-FED3M / without-FED3M checks under the specified exclusions. Report correlations/VIF/incremental information and show the exercise only if informative. | N7: Clarification + diagnostics + optional two-column robustness | O7: MR-03; final curve definitions | P7: The baseline SELIC omission is explicit and tied to both UIP overlap and the curve construction; any SELIC 3M Forward columns obey the required exclusions, are labeled referee-only, and are not treated as a baseline replacement. | Q7: Yes - clarification / minimum scope | R7: Deferred | S7: Data package is complete. Regression-dependent closure remains deferred until the panel is frozen. The 2-Oct meeting makes the robustness comparison part of the intended new-estimates package rather than a pre-freeze task.
A8: MR-05 | B8: A-02, A-04, A-14 | C8: OG-02 | D8: Low | E8: Ailin | F8: Ailin proposes a full two-step Fama-MacBeth factor model with bond-specific betas to the real curve. | G8: Ailin pp. 5-7, M3 | H8: Disagrees / not endorsed | I8: Martin does not endorse a full theoretical redesign; treat it as a future extension. Current work should use bounded grouped heterogeneity tests. | J8: Interesting but disproportionate as a mandatory revision. | K8: D - Not endorsed / optional / response only | L8: Potentially Sec. 4.3-4.8 and Annex A | M8: Do not redesign the TFM around Fama-MacBeth. Mention it as future research and address the core concern through MR-04 and MR-06. | N8: No mandatory estimation | O8: MR-04 and MR-06 | P8: Response memo explains the scoped remedy and future extension. | Q8: No - response only | R8: Not started
A9: MR-06 | B9: A-07; M-01, M-16, M-17; D-10, D-18 | C9: OG-03 | D9: Critical | E9: Ailin + Maximo + Daniel | F9: The theory allows heterogeneous sovereign transmission, but the submitted model estimates one average coefficient and then invokes heterogeneous issuers to explain the sign. | G9: Ailin pp. 2, 9-10; Maximo pp. 1, 4; Daniel pp. 2-3 | H9: Partially agrees | I9: Earlier guidance supported bounded heterogeneity. In the 2-Oct meeting, when asked specifically about rating/sector grouping, Martin narrowed the immediate response: do not turn the thesis into a rating study; provide a small local-currency rating table for the reviewer/defense and keep any issuer/bond/sector heterogeneity exercises optional and subject to power. | J9: The jury concern should still be answered, but the minimum response is now descriptive evidence plus disciplined interpretation. Do not invoke issuer heterogeneity ex post as a proven explanation unless a powered test is actually run. | K9: A - Methodological issue / additional estimation | L9: Secs. 3.1, 3.3.2, 4.1, 4.3, 5.2.3, 6.1, 6.3 | M9: Use the completed point-in-time rating evidence descriptively in the jury response/appendix. Do not claim issuer heterogeneity as a proven mechanism unless a later powered test is run. Global and national rating scales must remain separate; additional sector/issuer/bond heterogeneity is optional post-core work. | N9: Descriptive evidence + optional bounded heterogeneity estimation | O9: MR-01, MR-03, MR-16; group definitions | P9: Rating evidence is documented with exact-sample coverage and explicit scale/source rules; the response no longer relies on an untested rating mechanism. Optional heterogeneity estimates, if any, are clearly secondary and powered. | Q9: Yes - response/descriptive minimum scope; extra estimation optional | R9: In progress | S9: 7-Oct-2026: rating data/method audit completed. Global LT LC >=1-agency coverage is 41.6%; Brazilian national-scale >=1-agency coverage is 75.8% but is a distinct descriptive scale. Baseline rating control rejected due coverage/selection; files committed as b087203. Remaining work is presentation in the issuer/company table or appendix and jury-response wording.
