Workbook

Sheet README
A1: TFM - Master Revision Matrix v17
A2: Single source of truth for the jury-revision process. Updated 2-Oct-2026: the Econometric Panel Data Freeze Gate remains active. The pre-freeze audits for VIX, nominal Fed 3M Forward and nominal USD/BRL are complete. USD/BRL passed the same six-stage audit: source/ticker recorded as USDBRL Curncy; clean monthly history over the thesis window; end-of-month/last-weekday convention; exact month-by-month mapping into all 4,229 panel rows across 164 panel months; no baseline transformation or rescaling; and an economic label clarified as nominal USD/BRL in BRL per USD, where an increase denotes BRL depreciation. The original Bloomberg formula is not retained in the values-only macro workbook, so that provenance limitation remains documented. Current pre-freeze work moves to GDP YoY and then the remaining baseline explanatory variables. No final baseline, diagnostic or robustness regression should be rerun before the gate passes.
A4: Purpose and governance
A5: Purpose | B5: Use the Master Matrix as the authoritative record of every jury issue, Martin's disposition, the required evidence/change, dependencies and completion status.
A6: Workflow status | B6: WP-03 remains closed. WP-04 remains deferred only at its regression stage. The VIX, nominal Fed 3M Forward and nominal USD/BRL pre-freeze audits are complete. USD/BRL passed source/ticker -> raw series -> monthly convention -> full-sample panel match -> transformation/scaling -> economic-label review. Current Data Freeze Gate work moves to GDP YoY and then the remaining baseline regressors. If RER is ultimately substituted for NER in the final core table, RER must be audited separately before panel freeze. After every baseline explanatory variable is audited or explicitly accepted unchanged, freeze panel_main_and_robustness.xlsx once, rerun the FE-Driscoll-Kraay core table, and only then run diagnostics/robustness including WP-04 Models 5-6.
A7: Scope rule | B7: Every jury point must map to a change, diagnostic, defense answer or reasoned non-change. Not every suggested extension must be estimated.
A8: v16 update | B8: 2-Oct-2026: nominal Fed 3M Forward audit completed end-to-end. Bloomberg USSOC Curncy / PX_LAST (3M USD OIS) matched all 164 distinct panel months exactly (0 mismatches; max absolute difference 0.0). Baseline Stata uses the series directly in percentage points with no log, standardization or /100 scaling; only the separate macro-difference robustness creates D.fed_3m_forward. Thesis wording now keeps “Fed 3M Forward” as the intuitive label but defines the underlying 3M USD OIS precisely and states that it is forward-looking in economic content, not a forward-starting 3Mx3M rate. MR-09 is closed; any post-freeze raw/partial correlations and final VIX sign/H1 interpretation are tracked under MR-18/MR-19. Next pre-freeze audit: USD/BRL.
A9: v17 update | B9: 2-Oct-2026: nominal USD/BRL audit completed end-to-end. The macro workbook records USDBRL Curncy and BRL-per-USD semantics; the original Bloomberg formula/raw source layer is not retained and no second repo provenance trace was found. The thesis-window raw series contains 187 uninterrupted monthly observations from Jan-2010 to Jul-2025, with no zeros/blanks/duplicate months and every observation dated on the last weekday of the month. The econometric panel uses usd_brl with 0 blanks, one value per month, 0 missing source months and 0 mismatches across 4,229 rows / 164 panel months (Dec-2010 to Jun-2025). Baseline Stata uses the nominal spot level directly, with no log/rescaling/standardization; D.usd_brl is separate robustness only. Economic label frozen as nominal USD/BRL (BRL per USD); higher values mean BRL depreciation. Next pre-freeze audit: GDP YoY. RER remains a separate construction that must be audited before freeze if it enters the final core table.
A10: Authoritative inputs
A11: Source file / message | B11: Role | C11: Date/pages | D11: How used | E11: Current status
A12: TFM_Maestria_Economia_Siqueira_Thiago_Abril_10_2026.pdf | B12: Submitted thesis baseline | C12: 69 pages | D12: Locations, equations, tables, figures and annexes | E12: Frozen baseline
A13: Ailin - Informe Preliminar TFM_Siqueira_Thiago (2).pdf | B13: Jury report + Martin annotations | C13: 11 pages | D13: Criticisms A-01 to A-18 and annotated dispositions | E13: Integrated
A14: Maximo Sangiacomo - Evaluacion_TFM_Siqueira_Thiago (2).pdf | B14: Jury report + Martin annotations | C14: 5 pages | D14: Criticisms M-01 to M-18 and priority technical exercises | E14: Integrated - primary substantive priority
A15: Devolucion DM - Daniel Milia.pdf | B15: Third jury report | C15: 18-Sep-2026; 3 pages | D15: Criticisms D-01 to D-18 and defense guidance | E15: Integrated; director reviewed 24-Sep-2026
A16: Martin Grandes - WhatsApp audio/text | B16: Director follow-up guidance | C16: Sep-2026; latest 27-Sep-2026 | D16: SELIC, dynamics, sovereign ceiling, DK/PCSE, nominal FED3M, table design, robustness sequence, definitive Sovereign Risk (BRL) construction, common-reference two-spread specification and deadlines | E16: Integrated as MG-01 to MG-21
A17: Proceso de presentacion y evaluacion del Trabajo Final - Res.CD 1313/2023 | B17: Institutional process | C17: Sep-2023; 1 page | D17: Formal stages and generic time windows | E17: Exact project deadline still to enter
A18: Tabla para nuevas estimaciones panel-Siqueira & Grandes 25-9-2026.docx | B18: Director-provided estimation template | C18: 25-Sep-2026; 1 page | D18: Exact four-column FE-Driscoll-Kraay variable-inclusion grid and requested output statistics | E18: Integrated; two layout ambiguities flagged for confirmation
A19: Revision categories
A20: Category | B20: Definition | C20: Default implication
A21: A - Methodological issue / additional estimation | B21: Measurement, identification, data or inference concern. | C21: Change data/model and regenerate affected outputs.
A22: B - Clarification / reframing | B22: Valid criticism mainly solved through precise definitions, interpretation or wording. | C22: Rewrite after final estimates; may include a small diagnostic.
A23: C - Presentation / structure / literature / documentation | B23: Presentation, literature, reporting, provenance or reproducibility. | C23: Revise text/tables/appendix/package; not necessarily new estimation.
A24: D - Not endorsed / optional / response only | B24: Request rejected, narrowed or treated as optional/future research. | C24: No mandatory thesis change; answer in memo/defense or add only if low cost.
A26: Workbook map
A27: Dashboard | B27: Formula-driven overview of priorities, counts, current package and process status.
A28: Process & Deadlines | B28: Institutional stages, generic windows and project-specific control fields.
A29: Revision Tracker | B29: Sixteen dependency-based work packages. Update Status and Working notes.
A30: Master Matrix | B30: Thirty-four consolidated revision issues across all jurors and director guidance.
A31: Juror Log | B31: Every distinct juror criticism mapped to one or more master issues.
A32: Director Guidance | B32: Traceability for Martin's audio/text decisions, including the 25-Sep-2026 estimation plan and definitive sovereign-risk definition.
A33: Overlap Map | B33: Unified resolution of recurring issues to prevent duplicate work.
A34: Action Sequence | B34: Dependency order that minimizes rework.
A35: Estimation Plan | B35: Exact 25-Sep-2026 paper/seminar model grid, optional SELIC checks, ambiguities and delivery controls.
A36: v4 Change Log | B36: Historical changes introduced on 24-Sep-2026.
A37: v5 Change Log | B37: Exact changes introduced from Martin Grandes' 25-Sep-2026 instructions.
A38: v6 Change Log | B38: Changes introduced from Martin Grandes' 25-Sep-2026 sovereign-risk clarification and workflow handoff from WP-01 to WP-02.
... A49: v17 Change Log | B49: Changes introduced on 2-Oct-2026 after completing the six-step nominal USD/BRL audit and moving the Data Freeze Gate to GDP YoY while preserving the separate RER pre-freeze dependency.

Sheet Dashboard
A1: Revision Dashboard
A2: Formula-driven from the Master Matrix, Revision Tracker and Process & Deadlines. Updated through 2-Oct-2026: the VIX, nominal Fed 3M Forward and nominal USD/BRL pre-freeze audits are complete. USD/BRL passed all six stages: USDBRL Curncy recorded in the macro workbook; 187 uninterrupted thesis-window monthly observations; last-weekday month-end convention; exact panel mapping across 4,229 rows / 164 panel months with zero mismatches; no baseline rescaling or transformation; and BRL-per-USD economic labeling. The original Bloomberg formula is not retained in the values-only workbook and that provenance limitation is documented. Current Data Freeze Gate task is GDP YoY, followed by the remaining baseline regressors. If RER enters the final core specification, it requires its own pre-freeze audit. WP-04 regression-dependent steps and all final baseline/robustness estimation remain deferred until the final panel is frozen.
A4: Issue portfolio
A5: Metric | B5: Count | C5: Meaning | E5: Martin position | F5: Count | G5: Meaning
A6: Total master issues | B6: =COUNTA('Master Matrix'!A4:A200) | C6: Distinct consolidated issues. | E6: Agrees / strongly agrees | F6: =COUNTIF('Master Matrix'!H4:H200,E6) | G6: Explicitly endorsed.
A7: Critical priority | B7: =COUNTIF('Master Matrix'!D4:D200,"Critical") | C7: Can affect acceptance or downstream results. | E7: Partially agrees | F7: =COUNTIF('Master Matrix'!H4:H200,E7) | G7: Accepted with scope limits.
A8: Category A | B8: =COUNTIF('Master Matrix'!K4:K200,"A*") | C8: Measurement/diagnostics/estimation. | E8: Disagrees / not endorsed | F8: =COUNTIF('Master Matrix'!H4:H200,E8) | G8: Response only or future research.
A9: Category B | B9: =COUNTIF('Master Matrix'!K4:K200,"B*") | C9: Clarification/reframing. | E9: No explicit position | F9: =COUNTIF('Master Matrix'!H4:H200,E9) | G9: No direct disposition.
A10: Category C | B10: =COUNTIF('Master Matrix'!K4:K200,"C*") | C10: Presentation/literature/documentation.
A11: Category D | B11: =COUNTIF('Master Matrix'!K4:K200,"D*") | C11: Optional or non-endorsed.
A12: Changes required | B12: =COUNTIF('Master Matrix'!Q4:Q200,"Yes*") | C12: Mandatory/minimum-scope changes.
A13: Done | B13: =COUNTIF('Master Matrix'!R4:R200,"Done") | C13: Completed master issues.
A15: Critical workstreams - recommended order
A16: Order | B16: Workstream | C16: Master issues | D16: Why
A17: 1 | B17: Correct spread construction - measurement audit closed | C17: MR-03 | D17: Dependent-variable measurement audit completed; downstream regressions remain to be regenerated.
A18: 2 | B18: Sovereign Risk (BRL) construction and terminology - closed | C18: MR-01 / MR-02 | D18: Closed 29-Sep: 582/582 LTN+NTN-F sovereign observations validated against same-date exact-tenor DI; geometric spreads and exact-node handling verified; pytest 5/5; commit b551414 pushed. Thesis now uses sovereign_spread_brl, removes CDS language, and distinguishes the nominal sovereign DI benchmark from the IPCA-real corporate benchmark.
A19: 3 | B19: Issue-size identification - closed (WP-03) | C19: MR-14 | D19: Closed 30-Sep: amount_issued_to_bs_tot_asset reconstructed for 4,229/4,229 observations; 98/103 bonds (95.15%) vary within bond; variable retained in bond FE; ‰ units and relative-size interpretation documented; one-quarter-lagged denominator reserved as robustness.
A20: 4 | B20: Baseline explanatory-variable audits / Data Freeze Gate - CURRENT | C20: MR-09 closed pre-freeze; remaining baseline regressors | D20: VIX, Fed 3M Forward and nominal USD/BRL pre-freeze audits passed. USD/BRL: source label/ticker = USDBRL Curncy; 187 uninterrupted monthly source observations from Jan-2010 to Jul-2025; all dates follow last-weekday month-end convention; 4,229 panel rows / 164 distinct panel months map exactly with 0 blanks, 0 conflicting within-month values, 0 missing source months and 0 mismatches; baseline usd_brl enters directly in BRL per USD levels with no log/rescaling/standardization; D.usd_brl is robustness only; higher USD/BRL denotes BRL depreciation. CURRENT: audit GDP YoY using the same six-step sequence, then continue through the remaining baseline regressors. RER is not validated by the NER audit and must be audited separately before freeze if selected for the final core table. Do not rerun final baseline/robustness regressions before the freeze gate passes.
A21: 5 | B21: Single DK results table and inference reset - AFTER DATA FREEZE | C21: MR-16 / MR-17 / MR-18 / MR-24 | D21: Only after the final panel is frozen: rerun the four-model FE-Driscoll-Kraay baseline table using the finalized regressor definitions, then diagnostics and targeted robustness checks including the referee-only Brazil 3M DI exercise.
A22: 6 | B22: Ratings/sector heterogeneity | C22: MR-06 / MR-07 | D22: Convert ex-post explanations into bounded tests.
A23: 7 | B23: Hypothesis-result/sign rewrite | C23: MR-19 / MR-30 / MR-31 / MR-32 | D23: Daniel's valid contribution is primarily expositional and follows empirical freeze.
A24: 8 | B24: Replication and resubmission | C24: MR-27 | D24: Required alongside the revised thesis.
A25: Live revision status
A26: Current package | B26: =IFERROR(INDEX('Revision Tracker'!B12:B100,MATCH("In progress",'Revision Tracker'!J12:J100,0)),"")
A27: Current task | B27: =IFERROR(INDEX('Revision Tracker'!E12:E100,MATCH("In progress",'Revision Tracker'!J12:J100,0)),"")
A28: Completed packages | B28: =COUNTIF('Revision Tracker'!J12:J100,"Done") | C28: of 16
A29: Overall progress | B29: =B28/16
A30: Current gate | B30: =IFERROR(INDEX('Revision Tracker'!K12:K100,MATCH("In progress",'Revision Tracker'!J12:J100,0)),"")
A32: Institutional process status
A33: Third report | B33: ='Process & Deadlines'!B5
A34: Daniel resolution | B34: ='Process & Deadlines'!B6
A35: Director review | B35: ='Process & Deadlines'!B7
A36: Current branch | B36: ='Process & Deadlines'!B8
A37: Official due date | B37: ='Process & Deadlines'!B9
A38: Days remaining | B38: ='Process & Deadlines'!B10
A39: Next formal step | B39: ='Process & Deadlines'!B11
A40: Seminar table target | B40: ='Process & Deadlines'!B13

Sheet Process & Deadlines
A1: Institutional Process & Deadlines
A2: Official generic time windows plus project-specific controls. Enter the exact official resubmission deadline when confirmed.
A4: Current project control
A5: Third jury report received | B5: Yes - Daniel Milia report dated 18-Sep-2026
A6: Daniel formal resolution | B6: Pasa a Defensa (favorable)
A7: Director review of Daniel | B7: Completed 24-Sep-2026 - less substantive; selective exposition/diagnostics/bibliography changes
A8: Current formal branch | B8: Awaiting official confirmation
A9: Official resubmission deadline
A10: Days remaining | B10: =IF(B9="","",B9-TODAY())
A11: Next formal step | B11: Confirm Ailin and Maximo formal resolutions, exact due date and whether a revised filing is formally required.
A12: Control note | B12: The user reports that a deadline exists, but the exact date is not in the process sheet.
A13: Paper/seminar table target | B13: 30-Sep-2026 - one consolidated FE-Driscoll-Kraay table for Martin (core four models; SELIC 3M Forward only as optional referee diagnostic)
A14: Official process and generic time windows
A15: Step | B15: Process stage | C15: Trigger | D15: Official time limit | E15: Current relevance | F15: Owner | G15: Status | H15: Evidence / next action
A16: 1 | B16: PTFM evaluation | C16: Formal receipt of project proposal | D16: 30 days | E16: Historical - not current | F16: Academic authority | G16: Not current | H16: Included for completeness.
A17: 2 | B17: PTFM correction, if required | C17: Authority requests project corrections | D17: 1 to 3 months | E17: Historical - not current | F17: Student + director | G17: Not current | H17: Not the current thesis-evaluation branch.
A18: 3 | B18: TFM review / jury convocation | C18: Formal receipt of TFM | D18: 45 days | E18: Completed | F18: Academic authority | G18: Completed | H18: The thesis was sent to three jurors.
A19: 4 | B19: Preliminary individual reports | C19: Jurors receive the TFM | D19: 45 days | E19: Completed - all three reports received | F19: Each juror | G19: Completed | H19: Daniel is the third report; dated 18-Sep-2026 and favorable.
A20: 5 | B20: Revision and resubmission, if formally required | C20: One or more resolutions require revision | D20: 1 to 4 months, set by authority | E20: Current only if official branch is revision | F20: Student + director | G20: Pending confirmation | H20: Enter the exact date in C9.
A21: 6 | B21: Second preliminary reports | C21: Revised TFM is formally resubmitted | D21: 45 days | E21: Contingent on revision branch | F21: Each juror | G21: Not started | H21: Jurors decide whether the revised version can pass to defense.
A22: 7 | B22: Oral and public defense | C22: Three favorable reports received | D22: Within 45 days | E22: Current if all three resolutions are favorable | F22: Program direction + student + jurors | G22: Pending confirmation | H22: Confirm Ailin/Maximo resolutions and coordinate defense date.
A24: Source: Proceso de presentacion y evaluacion del Trabajo Final de Maestria o Especializacion, Res.CD No. 1313/23 (Sep-2023). Daniel status: Devolucion DM - Daniel Milia, 18-Sep-2026. Director reviews: WhatsApp, 24-27 Sep-2026, including definitive Sovereign Risk (BRL), preferred common-reference two-spread specification and referee-only SELIC clarifications. Estimation template: Tabla para nuevas estimaciones panel, 25-Sep-2026.

Sheet Revision Tracker
A1: TFM Jury Revision Tracker
A2: Sixteen dependency-based work packages consolidate 34 master issues. Updated 2-Oct-2026: the Econometric Panel Data Freeze Gate remains active. WP-06 has completed the VIX, Fed 3M Forward and nominal USD/BRL pre-freeze audits. USD/BRL passed all six stages with exact 4,229-row / 164-month panel mapping, level scaling in BRL per USD and clarified depreciation semantics. The original Bloomberg formula is not retained in the values-only workbook, which is documented as a provenance limitation. Current Data Freeze Gate task: audit GDP YoY, then the remaining baseline regressors. If RER is used in the final core table, it must be audited separately before freeze. No final baseline/robustness estimation should run before the gate passes.
A4: Current package | B4: =IFERROR(INDEX(B12:B100,MATCH("In progress",J12:J100,0)),"")
A5: Current task | B5: =IFERROR(INDEX(E12:E100,MATCH("In progress",J12:J100,0)),"")
A6: Completed packages | B6: =COUNTIF(J12:J100,"Done")
A7: Overall progress | B7: =B6/16
A8: Current status | B8: =IFERROR(INDEX(J12:J100,MATCH("In progress",J12:J100,0)),"")
A9: Gate before moving on | B9: =IFERROR(INDEX(K12:K100,MATCH("In progress",J12:J100,0)),"")
A11: Seq. | B11: WP ID | C11: Phase | D11: Master issue IDs | E11: Work package | F11: Why this is sequenced here | G11: Thesis location(s) | H11: Concrete deliverable | I11: Dependencies | J11: Status | K11: Gate / acceptance criterion | L11: Working notes
A12: 1 | B12: WP-01 | C12: Measurement | D12: MR-03 | E12: Recalculate the corporate spread using consistent compounding | F12: The dependent variable feeds every regression and conclusion. | G12: Sec. 2.2; Sec. 4.3; Sec. 4.5.2; Annex 8.7; all results | H12: Audited conventions; corrected spread series; old-vs-new comparison; unit tests. | I12: Submitted code/data and curve audit | J12: Done | K12: Approve formula, units, day-count, compounding and field types; benchmark/corporate inputs pass hand checks. | L12: Completed 25-Sep-2026: corrected the 2012-2013 NTN-B field contamination, revalidated the relevant government-curve inputs, checked corporate bond price/yield fields, and closed the corporate-spread measurement audit. Downstream estimates will be regenerated after WP-02.
A13: 2 | B13: WP-02 | C13: Measurement | D13: MR-01, MR-02 | E13: Verify Sovereign Risk (BRL) construction, common-reference logic and terminology | F13: Martin confirmed the intended sovereign regressor and preferred two-spread transmission specification. The nominal sovereign implementation was validated end-to-end: LTN and NTN-F government yields are compared with the same-date DI reference curve at exact BUS/252 residual tenor. Thesis terminology and documentation were subsequently aligned, including the distinction between the nominal sovereign DI benchmark and the IPCA-real corporate benchmark. | G13: Secs. 2.2, 4.3, 4.5.1-4.5.3, 5.2.3; Annex 8.3 and 8.8-8.9 | H13: COMPLETED: code/formula audit; 252 LTN + 330 NTN-F maturity-matched sovereign spreads; same-date exact-tenor DI benchmark; geometric annual-effective spread; exact-node interpolation guard; regression tests; variable rename to sovereign_spread_brl; removal of synthetic-CDS wording; explicit methodology/appendix formula; literature/two-spread rationale; corporate-IPCA versus nominal-DI indexation clarification; affected figures/tables relabeled. | I13: WP-01 | J13: Done | K13: Corporate Spread is documented against the matched IPCA-real reference curve and sovereign_spread_brl against the matched nominal DI reference curve, each at the appropriate date/tenor/indexation. The thesis explains why the two spreads are modeled separately rather than collapsed into a direct corporate-minus-sovereign spread; CDS terminology is removed. Any final search for unintended USD CDS usage is a pre-estimation integrity check and does not reopen WP-02. | L13: Closed 29-Sep-2026. Nominal Sovereign Risk (BRL) implementation validated on 582/582 observations with 0 missing benchmarks and max absolute benchmark difference 5.33e-13 bp; spread arithmetic independently verified; BZDIOVRA cash + liquid DI futures + Pre x DI swaps; exact BUS/252 tenor; pytest 5/5; commit b551414 pushed. Thesis edits confirmed complete: sovereign_spread_brl adopted, synthetic-CDS wording removed, explicit construction added in methodology/annex, corporate IPCA-real versus nominal sovereign DI benchmark distinction documented, and relevant diagrams/table labels updated. Final coefficients remain provisional until all explanatory-variable audits are complete.
A14: 3 | B14: WP-03 | C14: Data audit | D14: MR-14 | E14: Audit amount_issued_to_bs_tot_asset and within-bond variation | F14: A time-invariant issue-size variable cannot be estimated in bond FE. | G14: Table 1 H6; Secs. 4.5.3 and 4.7; Table 3; Sec. 5.2.4; Annex 8.6.2 and Table 7; Figure 3 | H14: COMPLETED: raw-field trace from AMT_ISSUED and issuer BS_TOT_ASSET; full-panel reconstruction; within-bond variation diagnostics; timing/scaling audit; retain/rename decision; one-quarter-lagged denominator robustness construction; thesis wording/table/figure alignment. | I14: Raw panel and construction code | J14: Done | K14: PASSED: 4,229/4,229 panel observations reconstructed from raw sources; 98/103 bonds (95.15%) have within-bond variation; the regressor is identified in bond FE; ‰ units, quarterly timing and interpretation are documented; lagged-quarter timing robustness is available. | L14: Closed 30-Sep-2026. The jury concern applies to AMT_ISSUED in levels, but the estimated variable is AMT_ISSUED / BS_TOT_ASSET. AMT_ISSUED is fixed by bond; quarterly issuer assets generate within-bond variation. Raw-source reconstruction matched all 4,229 panel observations essentially exactly. 98/103 bonds vary within bond; five very-short-history bonds do not. The stored scale is per-mille (‰). A one-quarter-lagged BS_TOT_ASSET version retains 4,223/4,229 observations, correlates 0.9918 with the original, and preserves 98/103 varying bonds; its six missing observations are limited to two Serena bonds in 2022Q1 due to unavailable 2021Q4 assets. Decision: retain the existing contemporaneous relative-size variable in the main specification, reserve the lagged denominator as robustness, and interpret the coefficient as relative issue size versus issuer scale—not as a change in original amount issued. Thesis edits were completed across H6, methodology/FE identification, results, conclusions, Tables 3/7, Figure 3 and Annex 8.6.2.
A15: 4 | B15: WP-04 | C15: Variables | D15: MR-04 | E15: Clarify SELIC baseline non-inclusion and run referee-only SELIC 3M Forward check(s) | F15: SELIC anchors the short end of the local reference curve and its influence propagates through the curve; Martin's 3M Forward SELIC exercise is only a low-cost referee diagnostic, not a competing baseline specification. | G15: Secs. 3.1-3.3, 4.3, 4.5.3, 5.2-5.4, 6.1 | H15: Dual-rationale note; correlations/VIF; optional SELIC 3M Forward check(s) under the specified exclusions; label the exercise referee-only and decide whether it is worth reporting only after seeing its informational value. | I15: WP-01; final curve definitions | J15: Deferred | K15: Baseline omission is explicit; the local-curve embedding of SELIC is explained; any SELIC 3M Forward check follows the required exclusions, is labeled referee-only and does not replace the preferred model. | L15: 1-Oct-2026 sequencing update: thesis Section 4.5.3 already justifies baseline SELIC non-inclusion, and the referee-only Brazil 3M DI proxy (YCSW0089 Index 3M) has been validated/downloaded for Dec-2010 to Dec-2025 with a reproducible BQNT notebook and README. Data preparation is complete. Regression-dependent closure is intentionally deferred under the Econometric Panel Data Freeze Gate: do not merge this robustness-only series into the authoritative panel or run Models 5-6 until the remaining baseline explanatory variables are audited/accepted unchanged and the final panel is frozen. After the core baseline rerun, review correlations/VIF/incremental information and run Model 5 (retain nominal FED3M) and Model 6 (omit FED3M), both omitting FX and Sovereign Risk (BRL).
A16: 5 | B16: WP-05 | C16: Heterogeneity | D16: MR-06, MR-07 | E16: Test sovereign transmission by ratings and sector groups | F16: Post-hoc explanations must be converted into bounded tests. | G16: Secs. 3.1, 3.3.2, 4.1, 4.3, 5.2.3, 6.1, 6.3 | H16: Rating tiers; sector groups; interactions; equality tests; group counts; optional issuer/bond slopes where powered. | I16: WP-02; rating rules | J16: Not started | K16: Homogeneity is tested with adequate-cell groups; small-T issuer/bond estimates are labeled imprecise.
A17: 6 | B17: WP-06 | C17: Data Freeze Gate | D17: MR-09 closed; remaining baseline regressors | E17: Complete explanatory-variable Data Freeze Gate (VIX + Fed + USD/BRL passed; GDP YoY current) | F17: Daniel asks for a direct H1-result link and better explanation of the negative sign. | G17: Secs. 3.1, 3.3.1, 4.1, 4.5.3, 5.2.1, 6.1 | H17: VIX PRE-FREEZE COMPLETE. FED 3M FORWARD SIX-STEP AUDIT COMPLETE. NOMINAL USD/BRL SIX-STEP AUDIT COMPLETE: macro workbook records USDBRL Curncy and BRL-per-USD semantics; original Bloomberg formula/raw-source layer is not retained and no duplicate repo provenance trace was found; 187 uninterrupted monthly observations Jan-2010 to Jul-2025 with no zeros/blanks/duplicate months; all observations use the last weekday of the month; panel variable usd_brl has 0 blanks, one value per month and exact source matching across 4,229 rows / 164 panel months; baseline enters in nominal BRL-per-USD levels with no log/rescaling/standardization; D.usd_brl is robustness only; higher values mean BRL depreciation. CURRENT: audit GDP YoY through source/ticker -> raw series -> monthly convention -> panel match -> transformation/scaling -> economic label, then continue through the remaining baseline regressors. If RER replaces NER in the final core table, RER requires a separate pre-freeze audit. POST-FREEZE: correlations/sequential DK and final counterintuitive-sign interpretation are handled under MR-18/MR-19. | I17: VIX, Fed and nominal USD/BRL fully validated; GDP YoY is the next baseline audit; final diagnostics/estimation blocked by Data Freeze Gate | J17: In progress | K17: Global-factor block and nominal USD/BRL pre-freeze audit PASSED. Continue until every remaining baseline explanatory variable is audited or explicitly accepted unchanged; if RER is selected for the final core table, audit RER separately before freeze. Then rebuild/freeze panel_main_and_robustness.xlsx as the authoritative input. Post-freeze correlations and final VIX sign/H1 interpretation remain under MR-18/MR-19. | L17: 2-Oct-2026 USD/BRL audit closure: macro workbook column D identifies “USDBRL Spot Exchange Rate - Price of 1 USD in BRL” / USDBRL Curncy. Upstream Bloomberg formula/raw source is not retained in the values-only workbook and repo-wide search found no second ticker trace, so this provenance limitation is explicit. Thesis-window source series contains 187 monthly observations from Jan-2010 through Jul-2025, no zeros/blanks/duplicate months, range 1.5493-6.1736, and every date is the last weekday of the month. Panel ts.usd_brl contains 0 blanks across 4,229 rows; 164 unique panel months from Dec-2010 through Jun-2025; no within-month conflicts; no source-month gaps; and 0 month-by-month mismatches. Stata uses usd_brl directly in levels; no log, /100, *100, z-score or standardization is applied. D_usd_brl = D.usd_brl exists only in the macro-differences robustness. Economic label: nominal USD/BRL (BRL per USD), month-end spot; an increase denotes BRL depreciation. Next Data Freeze Gate audit: GDP YoY. Separate caution: if RER replaces NER in the final core specification, the RER construction must be audited before panel freeze.
A18: 7 | B18: WP-07 | C18: Estimator | D18: MR-16, MR-17, MR-23 | E18: Reset inference to one bond-FE Driscoll-Kraay table; remove plain FE and PCSE | F18: Martin confirmed the PCSE rationale and requested no separate conventional-FE or PCSE columns. | G18: Secs. 4.2, 4.6, 4.8, 5.1-5.3; Tables 2-3; Annex 8.10-8.11 | H18: Audited logs; diagnostics; final DK setup/lag; precise PCSE exclusion note; one-table layout. | I18: WP-01 to WP-06 final variable definitions | J18: Not started | K18: All main significance uses one DK setup; diagnostics are shown; the core table has no separate plain-FE or PCSE columns. | L18: PCSE rationale confirmed 25-Sep-2026: imbalance and limited common time overlap weaken covariance estimation.
A19: 8 | B19: WP-08 | C19: Estimator | D19: MR-18 | E19: Produce the single four-model DK table and targeted robustness checks | F19: Immediate paper/seminar deliverable requested by Martin for 30-Sep-2026. | G19: Secs. 4.6-4.8, 5.1-5.4; Annex 8.11 | H19: Four core FE-DK columns using nominal FED3M; sovereign/local-macro and NER/RER variants; within R2/rho; referee-only optional SELIC Models 5-6; correlation matrix. | I19: WP-01, WP-02, WP-04, WP-07; confirm template ambiguities | J19: Not started | K19: Core grid matches the director template; old FED3M Real is excluded; NER/RER and stacking ambiguities are confirmed; any SELIC columns are separate, referee-only diagnostics. | L19: Target 30-Sep-2026. Attached table marks both NER and RER in Model 1 and keeps firm/bond controls in all columns; confirm before final code. 27-Sep: SELIC 3M Forward is only a referee check, not a baseline extension.
A20: 9 | B20: WP-09 | C20: Robustness | D20: MR-25 | E20: Address stale OTC pricing as a competing explanation | F20: Lagged quotes may mechanically create anomalous signs. | G20: Secs. 2.1.1, 4.5.2, 4.6, 5.2.1, 5.2.3, 6.1-6.3; Annex 8.2 and 8.5 | H20: Literature/limitation plus one feasible diagnostic or documented data limit. | I20: WP-01; source fields; WP-07 | J20: Not started | K20: Flight-to-quality is not stated as fact before stale pricing is considered.
A21: 10 | B21: WP-10 | C21: Identification | D21: MR-13, MR-15 | E21: Clarify identifying variation and panel imbalance | F21: Common regressors vary monthly; bond histories are unequal. | G21: Secs. 4.2-4.4, 4.7-4.8, 5.1, 5.3-5.4, 6.1; Annex 8.10 | H21: Variation-level table and T_i/coverage profile. | I21: WP-03 and WP-07 | J21: Not started | K21: Months, bonds, issuers, T_i distribution and FE limits are reported.
A22: 11 | B22: WP-11 | C22: Text/literature | D22: MR-11, MR-12, MR-21, MR-32, MR-34 | E22: Correct language and make bounded literature/theory updates | F22: Daniel's literature comments are secondary and should support, not expand, the empirical design. | G22: Introduction; Secs. 3-4; references; defense literature map | H22: Non-causal wording; citation corrections; construct-proxy table; closest-study comparison. | I22: Final empirical framing from WP-04, WP-08, WP-09 | J22: Not started | K22: Every citation supports the statement; the gap/proxies are demonstrated without theoretical overhaul.
A23: 12 | B23: WP-12 | C23: Reporting | D23: MR-22, MR-24 | E23: Build the single consolidated regression table and run table-to-text checks | F23: Final DK evidence must be readable and auditable. | G23: Table 3; Sec. 5.2.2; Annex Table 7 | H23: One FE-DK table with SE, N, panel dimensions, within R2, rho, DK lag/FE metadata and diagnostics panel. | I23: WP-08 final estimates | J23: Not started | K23: The requested four core columns and any optional SELIC columns are readable, auditable and matched exactly by the prose. | L23: Table design source: Martin's 25-Sep-2026 template.
A24: 13 | B24: WP-13 | C24: Interpretation | D24: MR-19, MR-26 | E24: Rewrite results and explain counterintuitive signs | F24: Daniel's central contribution is better H-result linkage; Brazil-specific mechanisms must be separated from evidence. | G24: Secs. 5.2-5.4 and 6.1-6.3 | H24: Robust/partial/null/unresolved hierarchy; H-result map; Brazil-specific mechanisms. | I24: WP-02, WP-04, WP-05, WP-08, WP-09, WP-12 | J24: Not started | K24: Every hypothesis and sign is tied to a final table or labeled as a mechanism/limitation.
A25: 14 | B25: WP-14 | C25: Narrative | D25: MR-30, MR-31, MR-32, MR-33 | E25: Rewrite gap, contribution, abstract/conclusions and final copy-edit | F25: Do this only after the empirical freeze; Daniel is treated selectively as exposition. | G25: Resumen/Abstract; Introduction; Secs. 5.4 and 6; entire-thesis QA | H25: Closest-study contribution; one central question; hypothesis scorecard; final language consistency. | I25: WP-13 | J25: Not started | K25: Question, contribution, tables and conclusions are consistent and appropriately bounded.
A26: 15 | B26: WP-15 | C26: Reproducibility | D26: MR-27, MR-28 | E26: Complete replication package and data provenance | F26: Ailin requests a runnable pipeline and Martin agrees. | G26: Secs. 4.4-4.5; Annex 8.1-8.14; source notes | H26: README, environment, scripts, queries, dates, hashes, consolidation rules, curve settings and clean-run evidence. | I26: All final code/outputs | J26: Not started | K26: A clean run regenerates every permitted output and provenance is complete.
A27: 16 | B27: WP-16 | C27: Resubmission | D27: MR-05, MR-08, MR-10, MR-20, MR-29; synthesis MR-30/31/32 | E27: Prepare response memo, defense and Bordeaux/Geneva materials | F27: All comments must receive a change, diagnostic, answer or reasoned non-change. | G27: Response memo; future research; defense/seminar deck; deadline checklist | H27: Issue-by-issue memo; final single DK seminar table; diagnostics; scoped non-changes; confirmed deadlines; concise Bordeaux/Geneva deck. | I27: WP-01 to WP-15 | J27: Not started | K27: Every observation maps to evidence or a reasoned non-change; seminar materials use the agreed table; deadlines and formal branch are tracked. | L27: Near-term table target recorded as 30-Sep-2026.

Sheet Master Matrix
A1: Master Revision Matrix
A2: One row per distinct issue across all three jurors. Overlaps are consolidated so the same problem is solved once. Updated through 2-Oct-2026: WP-03/MR-14 is closed; MR-04/WP-04 regression work remains deferred under the Data Freeze Gate; MR-09 is closed as a VIX/global-proxy data-definition issue; the companion Fed 3M Forward and nominal USD/BRL six-step audits are also complete. Current pre-freeze work moves to GDP YoY and the remaining baseline regressors. If RER is selected for the final core table, it must be audited separately before freeze. Post-freeze correlations and final counterintuitive-sign interpretation remain under MR-18/MR-19.
A3: ID | B3: Source IDs | C3: Overlap group | D3: Priority | E3: Juror(s) | F3: Consolidated juror criticism | G3: Report location | H3: Martin position | I3: Martin annotation / evidence | J3: My diagnosis | K3: Revision category | L3: Thesis location | M3: Required action | N3: Estimation / work type | O3: Dependencies | P3: Acceptance criterion | Q3: Change required? | R3: Status | S3: Working notes
A4: MR-01 | B4: A-03, A-10, A-13; M-04, M-17, M-18; D-10, D-17 | C4: OG-01 | D4: Critical | E4: Ailin + Maximo + Daniel | F4: The sovereign-risk regressor and the dependent corporate spread share the IPCA benchmark. The jury asks whether this creates mechanical covariance and how the negative coefficient should be interpreted. | G4: Ailin pp. 2, 6-7 and M1; Maximo p. 2 sec. 1.2 and pp. 4-5; Daniel pp. 2-3 | H4: Agrees / strongly agrees | I4: 24-Sep-2026: Martin identifies this as the main priority and frames corporate excess/shortfall relative to the sovereign through the sovereign-ceiling hypothesis. 25-Sep: the sovereign regressor is a local BRL sovereign spread, government YTM minus the matched local risk-free/reference yield, not a CDS. 27-Sep: USD CDS 5Y was never part of the economic model. Corporate Spread and Sovereign Risk (BRL) should remain separate spreads over the same local reference curve so the model estimates the response of corporate spread to sovereign risk; a direct corporate-minus-sovereign spread is a related alternative, not the preferred econometric specification. | J4: Resolved. The jurors' shared-benchmark/mechanical-covariance concern was separated from the actual final implementation. Corporate spreads are measured against an IPCA-real reference curve, while sovereign_spread_brl uses nominal LTN/NTN-F minus the DI reference curve. The thesis now states that each spread is matched to its own instrument/indexation benchmark and explains why they remain separate variables in the sovereign-transmission regression. | K4: A - Methodological issue / additional estimation | L4: Sec. 2.2; Sec. 4.3; Sec. 4.5.1-4.5.3; Sec. 5.2.3; Annex 8.3 and 8.8-8.9 | M4: Completed: audit/document both formulas and tenor matching; distinguish the IPCA-real corporate benchmark from the nominal DI sovereign benchmark; explain the preferred two-spread transmission specification and the direct corporate-minus-sovereign alternative; remove synthetic-CDS terminology and align thesis figures/tables/appendix. Final model-panel integrity checks are deferred to the pre-estimation gate. | N4: Code/formula audit + terminology correction + re-estimation if implementation changes | O4: MR-03 measurement audit; local curve inputs; government-bond matching | P4: The thesis and code use explicit Corporate Spread and sovereign_spread_brl constructions with date/tenor/indexation matching appropriate to each instrument. The shared-benchmark concern is addressed without falsely claiming an identical curve; the two-spread specification is justified; no CDS label or pure-default interpretation remains. Final estimates will be refreshed only after the remaining regressor audits. | Q4: Yes | R4: Done | S4: Closed 29-Sep-2026. Sovereign code audit: 252 LTN + 330 NTN-F = 582 observations; 582/582 DI benchmarks reproduced; 0 missing; max abs diff 5.33e-13 bp; geometric spread verified; exact-node guard; pytest 5/5; commit b551414 pushed. Thesis edits completed across Resumen/Abstract, sovereign-risk literature/methodology, results terminology, annex construction, and Figures 3/4. Corporate IPCA-real versus nominal sovereign DI benchmark distinction is now explicit.
A5: MR-02 | B5: A-03, A-13; M-04 | C5: OG-01 | D5: High | E5: Ailin + Maximo | F5: The labels synthetic CDS BRL and risk-free real curve overstate what is measured when the benchmark includes sovereign NTN-B yields and market-basis components. | G5: Ailin pp. 2, 6-7; Maximo p. 2 sec. 1.2 | H5: Agrees / strongly agrees | I5: 25-Sep-2026: Martin explicitly rejects the "synthetic CDS" label; there is no credit default swap in the construction. 27-Sep: he further clarifies that USD CDS 5Y was never part of the economic model and should not be introduced. The intended object remains a maturity-matched local-currency sovereign spread: government-bond yield minus the relevant futures/swap/interpolated local reference curve yield. | J5: Resolved. The final variable is sovereign_spread_brl / local-currency sovereign spread, not a CDS. The nominal DI reference curve and exact-tenor matching are documented, and language that could imply a pure default-protection measure was removed. The corporate IPCA-real benchmark is described separately so the indexation treatment is transparent. | K5: B - Clarification / reframing | L5: Resumen/Abstract; Sec. 2.2; Sec. 4.5.1-4.5.3; Sec. 5.2.3; Annex 8.3 and 8.8-8.9; Glossary | M5: Completed: rename the variable consistently as sovereign_spread_brl / sovereign risk in local currency; define it algebraically as government YTM versus the matched nominal DI reference yield; explain the DI curve construction and tenor matching; remove synthetic CDS BRL from thesis text, diagrams and table labels. Keep the director-confirmed USD CDS 5Y non-use as a final pre-estimation code-integrity check only. | N5: Terminology correction + code/formula verification | O5: MR-01 measurement decision | P5: One name and one formula are used throughout; the variable is never described as a CDS; the nominal DI reference curve and maturity matching are transparent; the implementation reproduces the documented construction; the IPCA-real corporate benchmark is separately identified. No USD CDS variable is to be introduced into the model. | Q5: Yes | R5: Done | S5: Closed 29-Sep-2026 after thesis terminology and documentation cleanup. sovereign_spread_brl replaces synthetic_cds_brl; p.26-27 and Annex 8.8 construction rewritten; Resumen/Abstract, results text, tables/diagrams and Mermaid source relabeled; DI curve description updated to dynamic cash + liquid futures + Pre x DI swaps and framed as a local nominal market reference rather than an absolute risk-free rate.
A6: MR-03 | B6: A-05 | C6: OG-02 | D6: Critical | E6: Ailin | F6: Spreads were computed by linear subtraction of yields despite compounding conventions. Ailin requests a geometric or log-consistent spread on matched curves. | G6: Ailin p. 2 sec. 2(c), p. 7, M2 | H6: Agrees / strongly agrees | I6: Martin explicitly instructed a recalculation. This remains WP-01 and precedes every re-estimation. | J6: Genuine dependent-variable measurement correction. Exact units, signs, field types and compounding must be audited before coding. | K6: A - Methodological issue / additional estimation | L6: Sec. 2.2 eq. (1); Sec. 4.3; Sec. 4.5.2 eq. (3); Annex 8.7; all empirical outputs | M6: Recompute each bond-month spread with consistent compounding, matched tenor and consistent YTM/zero conventions. Unit-test hand cases, compare old versus new series, and regenerate all estimates, tables and conclusions. | N6: Dependent-variable rebuild + full re-estimation | O6: Curve and yield convention audit | P6: Formula, units, day count and compounding are documented; old/new summary statistics and hand checks reproduce; all downstream outputs use the corrected series. | Q6: Yes | R6: In progress | S6: Corporate-spread measurement stage completed 25-Sep-2026: NTN-B 2012-2013 field contamination corrected and corporate yield inputs rechecked. MR-03 remains open only because downstream estimates/tables still need regeneration with the corrected series.
A7: MR-04 | B7: A-02, A-04, A-14 | C7: OG-02 | D7: High | E7: Ailin | F7: Subtracting the real curve implicitly imposes unit exposure to the curve factor; the level/slope of Brazilian real rates may be omitted. | G7: Ailin p. 2 sec. 2(b), pp. 5-7, M3 | H7: Partially agrees | I7: 25-Sep-2026: baseline SELIC non-inclusion has two reasons: UIP implies overlap with FED3M plus expected BRL depreciation, and SELIC anchors the short end of the local reference curve. 27-Sep: Martin reinforces that the local curve already embeds the SELIC effect and that the SELIC 3M Forward exercise is only for the referee; after seeing the result, decide whether it adds enough information to show or publish. | J7: Baseline omission is economically defensible and the referee-only domestic short-rate proxy is now fully sourced/documented. Because Models 5-6 depend on the final common regressor set, the regression stage is intentionally parked until all baseline explanatory variables are audited and the authoritative panel is frozen. | K7: A - Methodological issue / additional estimation | L7: Secs. 3.1-3.3; Sec. 4.3; Sec. 4.5.3; Sec. 5.2-5.4; Sec. 6.1 | M7: Explain the dual rationale for excluding SELIC from the baseline, including its role at the short end of the local reference curve. Report common-block correlations/VIF. If feasible, run the scoped SELIC 3M Forward referee checks: (i) omit FX and sovereign spread; (ii) also omit FED3M Forward. Label them referee-only and decide whether to retain them in the paper only if informative. | N7: Clarification + diagnostics + optional two-column robustness | O7: MR-03; final curve definitions | P7: The baseline SELIC omission is explicit and tied to both UIP overlap and the curve construction; any SELIC 3M Forward columns obey the required exclusions, are labeled referee-only, and are not treated as a baseline replacement. | Q7: Yes - clarification / minimum scope | R7: Deferred | S7: 1-Oct-2026: thesis rationale and Brazil 3M DI data package are complete. Regression-dependent closure is deferred, not dropped. After the Data Freeze Gate: merge/validate brazil_3m_di as a robustness-only series, review correlations/VIF, and run the two scoped referee diagnostics under Martin's exclusions.
A8: MR-05 | B8: A-02, A-04, A-14 | C8: OG-02 | D8: Low | E8: Ailin | F8: Ailin proposes a full two-step Fama-MacBeth factor model with bond-specific betas to the real curve. | G8: Ailin pp. 5-7, M3 | H8: Disagrees / not endorsed | I8: Martin does not endorse a full theoretical redesign; treat it as a future extension. Current work should use bounded grouped heterogeneity tests. | J8: Interesting but disproportionate as a mandatory revision. | K8: D - Not endorsed / optional / response only | L8: Potentially Sec. 4.3-4.8 and Annex A | M8: Do not redesign the TFM around Fama-MacBeth. Mention it as future research and address the core concern through MR-04 and MR-06. | N8: No mandatory estimation | O8: MR-04 and MR-06 | P8: Response memo explains the scoped remedy and future extension. | Q8: No - response only | R8: Not started
A9: MR-06 | B9: A-07; M-01, M-16, M-17; D-10, D-18 | C9: OG-03 | D9: Critical | E9: Ailin + Maximo + Daniel | F9: The theory allows heterogeneous sovereign transmission, but the submitted model estimates one average coefficient and then invokes heterogeneous issuers to explain the sign. | G9: Ailin pp. 2, 9-10; Maximo pp. 1, 4; Daniel pp. 2-3 | H9: Agrees / strongly agrees | I9: Test heterogeneity parsimoniously. Martin later clarified that issuer-level and, where powered, bond-level estimates may be informative, but small-T slopes can be imprecise. Sector/industry and rating groups are the current priority. | J9: Real model-result consistency issue; avoid 103 underpowered separate slopes. | K9: A - Methodological issue / additional estimation | L9: Secs. 3.1, 3.3.2, 4.1, 4.3, 5.2.3, 6.1, 6.3 | M9: Estimate staged heterogeneity: broad rating tiers; defensible sector groups; issuer/bond slopes only where T is adequate. Report counts, confidence intervals and equality tests. | N9: Additional estimation | O9: MR-01, MR-03, MR-16; group definitions | P9: At least one defensible rating and sector test is reported; small-cell limitations are explicit and explanations follow estimates. | Q9: Yes | R9: Not started
A10: MR-07 | B10: A-07; M-01, M-16, M-17 | C10: OG-03 | D10: High | E10: Ailin + Maximo | F10: Local-currency credit quality is used ex post to explain the sovereign coefficient but is absent from the model. | G10: Ailin pp. 2, 9-10; Maximo pp. 1, 4 | H10: Partially agrees | I10: Martin supports a compact rating-tier test but not an unlimited interaction battery. | J10: A compact rating interaction is the cleanest direct test if rating timing and cells are defensible. | K10: A - Methodological issue / additional estimation | L10: Sec. 5.2.3; Sec. 6.1 and 6.3; variable section 4.5.3 | M10: Add broad local-currency rating tiers, define timing/missing treatment, interact with the sovereign factor and test equality. | N10: New data field + additional estimation | O10: MR-06; rating source/timing rule | P10: Rating definitions, dates, counts and equality tests are documented. | Q10: Yes - minimum scope | R10: Not started
A11: MR-08 | B11: M-16, M-17, M-18 | C11: OG-03 | D11: Low | E11: Maximo | F11: Test flight-to-quality explanations with crisis/event dummies and interactions. | G11: Maximo p. 4 and defense questions | H11: Disagrees / not endorsed | I11: Useful but optional/future research; the thesis must have a bounded end. | J11: Potentially informative but secondary after ratings, sectors and stale-price checks. | K11: D - Not endorsed / optional / response only | L11: Sec. 5.2.1, 5.2.3, 6.1, 6.3 | M11: Keep as future research unless a pre-specified low-cost robustness can be added. Do not present flight-to-quality as a finding. | N11: Optional interaction estimation | O11: MR-06 and MR-07 | P11: Narrative labels this as a possible mechanism unless directly tested. | Q11: No - response only | R11: Not started
A12: MR-09 | B12: A-01, A-06; M-03, M-10, M-18; D-09, D-18 | C12: OG-04 | D12: High | E12: Ailin + Maximo + Daniel | F12: VIX differs from the proxy in the cited reference, is not pure risk aversion, and its negative sign relative to H1 requires an explicit conditional interpretation. | G12: Ailin pp. 1, 7-8; Maximo pp. 1, 3, 5; Daniel pp. 2-3 | H12: Agrees / strongly agrees | I12: 24-Sep-2026: Daniel mainly requires clearer hypothesis-result links and better explanations of counterintuitive signs. Keep VIX if justified; do not overstate robustness. | J12: Retain VIX as a global volatility/financial-stress proxy, not pure risk aversion, and interpret it conditionally after sequential models. | K12: B - Clarification / reframing | L12: Secs. 3.1, 3.3.1, H1/Table 1, Sec. 4.5.3, Sec. 5.2.1, Sec. 6.1 | M12: CLOSED PRE-FREEZE. VIX source/monthly history/panel mapping/scaling/economic label are validated and the thesis frames VIX as expected S&P 500 implied volatility used as a proxy for global financial stress, not pure risk aversion. The companion Fed 3M Forward audit also passed all six stages: Bloomberg USSOC Curncy / PX_LAST (3M USD OIS), daily history, month-end convention, 164/164 exact panel match, native percentage-point scaling and corrected technical definition. Final coefficient-movement/correlation diagnostics and final VIX sign/H1 prose are downstream tasks under MR-18/MR-19 after the frozen-panel DK rerun; they do not keep MR-09 open. | N12: Data/source audit + text revision + diagnostic; optional alternative proxy | O12: MR-18 correlation matrix | P12: PASSED: the VIX construct/proxy is justified and accurately labeled; its source, monthly mapping and scaling are validated. The companion nominal Fed control is independently sourced and reproduced end-to-end, including 164/164 exact panel-month matches and a technically correct OIS definition. Any post-freeze correlation table and final sign interpretation are assigned to MR-18/MR-19. | Q12: Yes | R12: Done | S12: Closed 2-Oct-2026. VIX pre-freeze audit passed (187/187 monthly history check; 4,229/4,229 panel mapping; raw index-point scaling; corrected financial-stress wording). Fed 3M Forward audit passed all six stages: USSOC Curncy / PX_LAST (3M USD OIS); daily/raw coverage confirmed; month-end/last-available-quote convention validated; 164/164 distinct panel months exact with 0 mismatches and max abs diff 0.0; baseline Stata uses native percentage-point values without rescaling; thesis definition now states the exact ticker/field, OIS instrument, month-end convention and that the series is not forward-starting. Reproducible BQNT notebook and README are version-controlled in fb7748d. Remaining post-freeze correlation/sign work is consolidated under MR-18/MR-19.
A13: MR-10 | B13: A-06 | C13: OG-04 | D13: Low | E13: Ailin | F13: Replace or complement VIX with a large composite PCA index. | G13: Ailin pp. 7-8, M4 | H13: Disagrees / not endorsed | I13: No mandatory replacement. Acknowledge alternatives; at most use one transparent proxy. | J13: Large extension with substantial discretion; not necessary to resolve the core criticism. | K13: D - Not endorsed / optional / response only | L13: Would affect Sec. 4.5.3, all regressions and Annex A | M13: Do not build the PCA as a mandatory revision. Mention as future research; optionally show one simple alternative proxy. | N13: No mandatory estimation | O13: MR-09 | P13: Response memo explains the narrower remedy. | Q13: No - response only | R13: Not started
A14: MR-11 | B14: A-02, A-04, A-12; D-03, D-15 | C14: OG-05 | D14: High | E14: Ailin + Daniel | F14: The literature bridge to factor exposure, stale OTC pricing and the closest empirical studies is too descriptive or incomplete. | G14: Ailin pp. 1, 3, 5-7; Daniel pp. 1-3 | H14: Partially agrees | I14: 24-Sep-2026: Daniel is less substantial than the other reports; bibliography is a minor, targeted correction. Add only literature that supports the actual specification, tests and limits. | J14: A concise, critical comparison is warranted; no theoretical overhaul. | K14: C - Presentation / structure / literature / documentation | L14: Secs. 3.1-3.3, 4.6-4.7, 5.2-5.4; References | M14: Add a concise factor/stale-price bridge and directly compare the closest local-currency corporate-debt and panel-method papers. Correct minor bibliography issues. | N14: Literature and interpretation rewrite | O14: MR-04, MR-25, MR-34 | P14: Each added reference is tied to a specific construct, test or limitation. | Q14: Yes | R14: Not started
A15: MR-12 | B15: M-02; D-07, D-17 | C15: OG-06 | D15: High | E15: Maximo + Daniel | F15: The thesis sometimes uses causal language although the design is observational and correlational. | G15: Maximo p. 1; Daniel pp. 2-3 | H15: No explicit position | I15: No direct Martin comment; consistent with the general instruction to avoid overstatement. | J15: Valid, low-cost wording correction. | K15: B - Clarification / reframing | L15: Sec. 4.3, 4.7; Resumen/Abstract; Conclusions | M15: Audit causal verbs and replace them with conditional-association language unless a specific identification argument supports causality. | N15: Text-only global edit | O15: Final model wording after MR-19 | P15: Abstract, methods, results and conclusions use consistent non-causal language. | Q15: Yes | R15: Not started
A16: MR-13 | B16: M-05; D-05, D-17 | C16: OG-07 | D16: High | E16: Maximo + Daniel | F16: The 4,229 rows do not equal 4,229 independent macro observations; the panel is strongly unbalanced with unequal bond histories. | G16: Maximo p. 2; Daniel pp. 2-3 | H16: Agrees / strongly agrees | I16: Clarify the effective monthly dimension and the panel-balance profile; do not overstate precision or generalizability. | J16: Does not invalidate panel estimation, but affects inference and exposition. | K16: B - Clarification / reframing | L16: Secs. 4.2-4.4, 5.1; Annex 8.10 | M16: Report observations, months, bonds and issuers separately; add T_i distribution, entry/exit years and annual coverage. | N16: Method clarification + table metadata | O16: MR-16 and MR-24 | P16: Methods and tables distinguish all dimensions and state unequal coverage clearly. | Q16: Yes | R16: Not started
A17: MR-14 | B17: M-06, M-17; D-11, D-18 | C17: OG-07 | D17: Critical | E17: Maximo + Daniel | F17: A time-invariant issue-size variable should be absorbed by bond fixed effects, yet a coefficient is reported; the sign also changes under PCSE. | G17: Maximo pp. 2, 4; Daniel pp. 2-3 | H17: Agrees / strongly agrees | I17: Audit the construction. Issue size itself is invariant; any variation must come from the denominator or timing. | J17: Resolved. The time-invariance concern applies to AMT_ISSUED in levels, not to the estimated ratio. The actual regressor is AMT_ISSUED / BS_TOT_ASSET; quarterly issuer assets create time variation. In the estimation sample 98/103 bonds (95.15%) exhibit within-bond variation, so the ratio is identified under bond fixed effects. The coefficient measures changes in relative issue size versus issuer scale, not changes in the original issue amount. | K17: A - Methodological issue / additional estimation | L17: Table 1 H6; Secs. 4.5.3 and 4.7; Table 3; Sec. 5.2.4; Sec. 6.1-6.2.2; Annex 8.6.2 and Table 7; Figure 3 | M17: Completed: trace AMT_ISSUED and issuer BS_TOT_ASSET from raw inputs; reconstruct the full panel; quantify within/between variation and quarterly timing; document the ‰ scale; retain and rename/define the variable consistently; revise FE identification and interpretation; keep a one-quarter-lagged denominator as timing robustness. | N17: Data audit + possible model revision | O17: Raw panel and code | P17: Passed: 4,229/4,229 observations reproduce from raw sources; 98/103 bonds vary within bond; the final variable name and ‰ units match construction; the thesis states that identification comes from the time-varying denominator and does not interpret the coefficient as the effect of changing AMT_ISSUED. | Q17: Yes | R17: Done | S17: Closed 30-Sep-2026. Full raw-source reconciliation matched the thesis panel essentially exactly. Within-bond audit: 98/103 bonds vary (95.15%); five bonds with <=1 distinct value have very short histories. Timing check showed the contemporaneous quarterly denominator; a Q-1 denominator robustness was built (4,223/4,229 available; corr=0.9918; same 98/103 varying bonds). Main specification retains the audited contemporaneous ratio. Thesis updated in H6, Sec. 4.5.3, Sec. 4.7, results/conclusions, Tables 3/7, Figure 3 and Annex 8.6.2.
A18: MR-15 | B18: M-06; D-05 | C18: OG-07 | D18: Medium | E18: Maximo + Daniel | F18: Most regressors vary at month or firm-month level while same-firm bonds can have different spreads; substantial bond-time variation remains unexplained. | G18: Maximo p. 2; Daniel p. 2 | H18: Partially agrees | I18: Clarify what fixed effects do and do not absorb; no model can cover every bond-time factor. | J18: Primarily a scope and interpretation issue. | K18: B - Clarification / reframing | L18: Secs. 4.7-4.8, 5.3-5.4, 6.1 and limitations | M18: Explain identification at month, firm-month and bond-month levels; interpret low within R2 without claiming model failure. | N18: Clarification; optional controls | O18: MR-13 and MR-14 | P18: The thesis states FE limits and unexplained variation transparently. | Q18: Yes | R18: Not started
