Workbook

Sheet metadata
A1: bond_id | B1: id_bb_global | C1: ticker | D1: issue_dt | E1: maturity | F1: derived_type | G1: ID_ISIN | H1: source_convention
A2: EH582517 Corp | B2: BBG0000TMWW5 | C2: BLTN | D2: 39724 | E2: 40544 | F2: LTN | G2: {=_xll.BDP(A2,$G$1)} -> BRSTNCLTN6C7 | H2: Historical price source | I2: ANDE PX_LAST
A3: EH984665 Corp | B3: BBG00009GLZ7 | C3: BLTN | D3: 39870 | E3: 40909 | F3: LTN | G3: {=_xll.BDP(A3,$G$1)} -> BRSTNCLTN6E3 | H3: Historical price date | I3: OBS_DATE
A4: EH892164 Corp | B4: BBG00008RVX7 | C4: BLTN | D4: 39997 | E4: 40725 | F4: LTN | G4: {=_xll.BDP(A4,$G$1)} -> BRSTNCLTN6G8 | H4: YAS price override | I4: YAS_BOND_PX = ANDE PX_LAST
A5: EI103101 Corp | B5: BBG00008RQ68 | C5: BLTN | D5: 40186 | E5: 41091 | F5: LTN | G5: {=_xll.BDP(A5,$G$1)} -> BRSTNCLTN6I4 | H5: YAS settlement date | I5: SETTLE_DT = OBS_DATE
A6: EI112870 Corp | B6: BBG0000G88K5 | C6: BLTN | D6: 40193 | E6: 40634 | F6: LTN | G6: {=_xll.BDP(A6,$G$1)} -> BRSTNCLTN6J2 | H6: Eligible bond-date cells | I6: 1056
A7: EI319458 Corp | B7: BBG0000GCY50 | C7: BLTN | D7: 40367 | E7: 40817 | F7: LTN | G7: {=_xll.BDP(A7,$G$1)} -> BRSTNCLTN6K0
A8: EI396297 Corp | B8: BBG0015S01L4 | C8: BLTN | D8: 40424 | E8: 41275 | F8: LTN | G8: {=_xll.BDP(A8,$G$1)} -> BRSTNCLTN6H6
A9: EI491572 Corp | B9: BBG0019VLDL4 | C9: BLTN | D9: 40515 | E9: 41365 | F9: LTN | G9: {=_xll.BDP(A9,$G$1)} -> BRSTNCLTN6L8
A10: EI532240 Corp | B10: BBG001D0XTY5 | C10: BLTN | D10: 40550 | E10: 42005 | F10: LTN | G10: {=_xll.BDP(A10,$G$1)} -> BRSTNCLTN6N4
A11: EI539699 Corp | B11: BBG001DCRGB9 | C11: BLTN | D11: 40557 | E11: 41000 | F11: LTN | G11: {=_xll.BDP(A11,$G$1)} -> BRSTNCLTN6O2
A12: EI600364 Corp | B12: BBG001KFMVB6 | C12: BLTN | D12: 40606 | E12: 41456 | F12: LTN | G12: {=_xll.BDP(A12,$G$1)} -> BRSTNCLTN6P9
A13: EI740276 Corp | B13: BBG001W4GJP7 | C13: BLTN | D13: 40732 | E13: 41183 | F13: LTN | G13: {=_xll.BDP(A13,$G$1)} -> BRSTNCLTN6Q7
A14: EI740364 Corp | B14: BBG001W4HV97 | C14: BLTN | D14: 40732 | E14: 41640 | F14: LTN | G14: {=_xll.BDP(A14,$G$1)} -> BRSTNCLTN6M6
A15: EI896969 Corp | B15: BBG0029PGRL0 | C15: BLTN | D15: 40879 | E15: 41730 | F15: LTN | G15: {=_xll.BDP(A15,$G$1)} -> BRSTNCLTN6R5
A16: EI946581 Corp | B16: BBG002D4G9N0 | C16: BLTN | D16: 40914 | E16: 42370 | F16: LTN | G16: {=_xll.BDP(A16,$G$1)} -> BRSTNCLTN6S3
A17: EJ122920 Corp | B17: BBG002VS2DT7 | C17: BLTN | D17: 41004 | E17: 41821 | F17: LTN | G17: {=_xll.BDP(A17,$G$1)} -> BRSTNCLTN6T1
A18: EJ279019 Corp | B18: BBG00366YRC3 | C18: BLTN | D18: 41096 | E18: 41548 | F18: LTN | G18: {=_xll.BDP(A18,$G$1)} -> BRSTNCLTN6U9
... A43: EK016928 Corp | B43: BBG005T8QGS5 | C43: BNTNF | D43: 41649 | E43: 45658 | F43: NTNF | G43: {=_xll.BDP(A43,$G$1)} -> BRSTNCNTF170

Sheet hp
C4: id | D4: EH582517 Corp | E4: EH984665 Corp | F4: EH892164 Corp | G4: EI103101 Corp | H4: EI112870 Corp | I4: EI319458 Corp | J4: EI396297 Corp | K4: EI491572 Corp | L4: EI532240 Corp | M4: EI539699 Corp | N4: EI600364 Corp | O4: EI740276 Corp | P4: EI740364 Corp | Q4: EI896969 Corp | R4: EI946581 Corp | S4: EJ122920 Corp | T4: EJ279019 Corp | U4: EJ393182 Corp | V4: EJ393177 Corp | W4: EJ622341 Corp | X4: EJ622346 Corp | Y4: EJ745910 Corp | Z4: EJ869056 Corp | AA4: EK019971 Corp | AB4: EK016988 Corp | AC4: EK367819 Corp | AD4: EK367825 Corp | AE4: EK367849 Corp | AF4: EK690056 Corp | AG4: AF180711 Corp | AH4: AF180712 Corp | AI4: ED961585 Corp | AJ4: EF399861 Corp | AK4: EG090250 Corp | AL4: EG623122 Corp | AM4: EG623130 Corp | AN4: EI138329 Corp | AO4: EI396317 Corp | AP4: EI946569 Corp | AQ4: EJ060294 Corp | AR4: EJ501365 Corp | AS4: EK016928 Corp
C5: 40542 | D5: {=_xll.BDH(SUBSTITUTE(D$4," Corp","@ANDE Corp"),"PX_LAST",$C5,$C5,"days=all","dts=h","fill=0","QtTyp=P")} -> 999.19644 | E5: {=_xll.BDH(SUBSTITUTE(E$4," Corp","@ANDE Corp"),"PX_LAST",$C5,$C5,"days=all","dts=h","fill=0","QtTyp=P")} -> 0 | F5: {=_xll.BDH(SUBSTITUTE(F$4," Corp","@ANDE Corp"),"PX_LAST",$C5,$C5,"days=all","dts=h","fill=0","QtTyp=P")} -> 946.49069 | G5: {=_xll.BDH(SUBSTITUTE(G$4," Corp","@ANDE Corp"),"PX_LAST",$C5,$C5,"days=all","dts=h","fill=0","QtTyp=P")} -> 840.16432 | H5: {=_xll.BDH(SUBSTITUTE(H$4," Corp","@ANDE Corp"),"PX_LAST",$C5,$C5,"days=all","dts=h","fill=0","QtTyp=P")} -> 973.48717 | I5: {=_xll.BDH(SUBSTITUTE(I$4," Corp","@ANDE Corp"),"PX_LAST",$C5,$C5,"days=all","dts=h","fill=0","QtTyp=P")} -> 918.19058 | J5: {=_xll.BDH(SUBSTITUTE(J$4," Corp","@ANDE Corp"),"PX_LAST",$C5,$C5,"days=all","dts=h","fill=0","QtTyp=P")} -> 792.31365 | K5: {=_xll.BDH(SUBSTITUTE(K$4," Corp","@ANDE Corp"),"PX_LAST",$C5,$C5,"days=all","dts=h","fill=0","QtTyp=P")} -> 769.9159 | L5: 0 | M5: 0 | N5: 0 | O5: 0 | P5: 0 | Q5: 0 | R5: 0 | S5: 0 | T5: 0 | U5: 0 | V5: 0 | W5: 0 | X5: 0 | Y5: 0 | Z5: 0 | AA5: 0 | AB5: 0 | AC5: 0 | AD5: 0 | AE5: 0 | AF5: 0 | AG5: 0 | AH5: 0 | AI5: {=_xll.BDH(SUBSTITUTE(AI$4," Corp","@ANDE Corp"),"PX_LAST",$C5,$C5,"days=all","dts=h","fill=0","QtTyp=P")} -> 1030.0507 | AJ5: {=_xll.BDH(SUBSTITUTE(AJ$4," Corp","@ANDE Corp"),"PX_LAST",$C5,$C5,"days=all","dts=h","fill=0","QtTyp=P")} -> 995.76001 | AK5: {=_xll.BDH(SUBSTITUTE(AK$4," Corp","@ANDE Corp"),"PX_LAST",$C5,$C5,"days=all","dts=h","fill=0","QtTyp=P")} -> 966.03168 | AL5: {=_xll.BDH(SUBSTITUTE(AL$4," Corp","@ANDE Corp"),"PX_LAST",$C5,$C5,"days=all","dts=h","fill=0","QtTyp=P")} -> 1047.966 | AM5: {=_xll.BDH(SUBSTITUTE(AM$4," Corp","@ANDE Corp"),"PX_LAST",$C5,$C5,"days=all","dts=h","fill=0","QtTyp=P")} -> 1010.0607 | AN5: {=_xll.BDH(SUBSTITUTE(AN$4," Corp","@ANDE Corp"),"PX_LAST",$C5,$C5,"days=all","dts=h","fill=0","QtTyp=P")} -> 931.34702 | AO5: {=_xll.BDH(SUBSTITUTE(AO$4," Corp","@ANDE Corp"),"PX_LAST",$C5,$C5,"days=all","dts=h","fill=0","QtTyp=P")} -> 983.67022 | AP5: 0 | AQ5: 0 | AR5: 0 | AS5: 0
C6: 40574 | D6: 0 | E6: {=_xll.BDH(SUBSTITUTE(E$4," Corp","@ANDE Corp"),"PX_LAST",$C6,$C6,"days=all","dts=h","fill=0","QtTyp=P")} -> 0 | F6: {=_xll.BDH(SUBSTITUTE(F$4," Corp","@ANDE Corp"),"PX_LAST",$C6,$C6,"days=all","dts=h","fill=0","QtTyp=P")} -> 954.55399 | G6: {=_xll.BDH(SUBSTITUTE(G$4," Corp","@ANDE Corp"),"PX_LAST",$C6,$C6,"days=all","dts=h","fill=0","QtTyp=P")} -> 843.4387 | H6: {=_xll.BDH(SUBSTITUTE(H$4," Corp","@ANDE Corp"),"PX_LAST",$C6,$C6,"days=all","dts=h","fill=0","QtTyp=P")} -> 982.13896 | I6: {=_xll.BDH(SUBSTITUTE(I$4," Corp","@ANDE Corp"),"PX_LAST",$C6,$C6,"days=all","dts=h","fill=0","QtTyp=P")} -> 925.37077 | J6: {=_xll.BDH(SUBSTITUTE(J$4," Corp","@ANDE Corp"),"PX_LAST",$C6,$C6,"days=all","dts=h","fill=0","QtTyp=P")} -> 791.98573 | K6: {=_xll.BDH(SUBSTITUTE(K$4," Corp","@ANDE Corp"),"PX_LAST",$C6,$C6,"days=all","dts=h","fill=0","QtTyp=P")} -> 767.60627 | L6: {=_xll.BDH(SUBSTITUTE(L$4," Corp","@ANDE Corp"),"PX_LAST",$C6,$C6,"days=all","dts=h","fill=0","QtTyp=P")} -> 618.90154 | M6: {=_xll.BDH(SUBSTITUTE(M$4," Corp","@ANDE Corp"),"PX_LAST",$C6,$C6,"days=all","dts=h","fill=0","QtTyp=P")} -> 870.65887 | N6: 0 | O6: 0 | P6: 0 | Q6: 0 | R6: 0 | S6: 0 | T6: 0 | U6: 0 | V6: 0 | W6: 0 | X6: 0 | Y6: 0 | Z6: 0 | AA6: 0 | AB6: 0 | AC6: 0 | AD6: 0 | AE6: 0 | AF6: 0 | AG6: 0 | AH6: 0 | AI6: {=_xll.BDH(SUBSTITUTE(AI$4," Corp","@ANDE Corp"),"PX_LAST",$C6,$C6,"days=all","dts=h","fill=0","QtTyp=P")} -> 988.4755 | AJ6: {=_xll.BDH(SUBSTITUTE(AJ$4," Corp","@ANDE Corp"),"PX_LAST",$C6,$C6,"days=all","dts=h","fill=0","QtTyp=P")} -> 940.25932 | AK6: {=_xll.BDH(SUBSTITUTE(AK$4," Corp","@ANDE Corp"),"PX_LAST",$C6,$C6,"days=all","dts=h","fill=0","QtTyp=P")} -> 894.03252 | AL6: 0 | AM6: {=_xll.BDH(SUBSTITUTE(AM$4," Corp","@ANDE Corp"),"PX_LAST",$C6,$C6,"days=all","dts=h","fill=0","QtTyp=P")} -> 961.89724 | AN6: {=_xll.BDH(SUBSTITUTE(AN$4," Corp","@ANDE Corp"),"PX_LAST",$C6,$C6,"days=all","dts=h","fill=0","QtTyp=P")} -> 851.57745 | AO6: {=_xll.BDH(SUBSTITUTE(AO$4," Corp","@ANDE Corp"),"PX_LAST",$C6,$C6,"days=all","dts=h","fill=0","QtTyp=P")} -> 921.75111 | AP6: 0 | AQ6: 0 | AR6: 0 | AS6: 0
C7: 40602 | D7: 0 | E7: {=_xll.BDH(SUBSTITUTE(E$4," Corp","@ANDE Corp"),"PX_LAST",$C7,$C7,"days=all","dts=h","fill=0","QtTyp=P")} -> 0 | F7: {=_xll.BDH(SUBSTITUTE(F$4," Corp","@ANDE Corp"),"PX_LAST",$C7,$C7,"days=all","dts=h","fill=0","QtTyp=P")} -> 962.55698 | G7: {=_xll.BDH(SUBSTITUTE(G$4," Corp","@ANDE Corp"),"PX_LAST",$C7,$C7,"days=all","dts=h","fill=0","QtTyp=P")} -> 851.58468 | H7: {=_xll.BDH(SUBSTITUTE(H$4," Corp","@ANDE Corp"),"PX_LAST",$C7,$C7,"days=all","dts=h","fill=0","QtTyp=P")} -> 990.41693 | I7: {=_xll.BDH(SUBSTITUTE(I$4," Corp","@ANDE Corp"),"PX_LAST",$C7,$C7,"days=all","dts=h","fill=0","QtTyp=P")} -> 932.93404 | J7: {=_xll.BDH(SUBSTITUTE(J$4," Corp","@ANDE Corp"),"PX_LAST",$C7,$C7,"days=all","dts=h","fill=0","QtTyp=P")} -> 801.64896 | K7: {=_xll.BDH(SUBSTITUTE(K$4," Corp","@ANDE Corp"),"PX_LAST",$C7,$C7,"days=all","dts=h","fill=0","QtTyp=P")} -> 778.58878 | L7: {=_xll.BDH(SUBSTITUTE(L$4," Corp","@ANDE Corp"),"PX_LAST",$C7,$C7,"days=all","dts=h","fill=0","QtTyp=P")} -> 631.0005 | M7: {=_xll.BDH(SUBSTITUTE(M$4," Corp","@ANDE Corp"),"PX_LAST",$C7,$C7,"days=all","dts=h","fill=0","QtTyp=P")} -> 877.99392 | N7: 0 | O7: 0 | P7: 0 | Q7: 0 | R7: 0 | S7: 0 | T7: 0 | U7: 0 | V7: 0 | W7: 0 | X7: 0 | Y7: 0 | Z7: 0 | AA7: 0 | AB7: 0 | AC7: 0 | AD7: 0 | AE7: 0 | AF7: 0 | AG7: 0 | AH7: 0 | AI7: {=_xll.BDH(SUBSTITUTE(AI$4," Corp","@ANDE Corp"),"PX_LAST",$C7,$C7,"days=all","dts=h","fill=0","QtTyp=P")} -> 996.53918 | AJ7: {=_xll.BDH(SUBSTITUTE(AJ$4," Corp","@ANDE Corp"),"PX_LAST",$C7,$C7,"days=all","dts=h","fill=0","QtTyp=P")} -> 954.79579 | AK7: {=_xll.BDH(SUBSTITUTE(AK$4," Corp","@ANDE Corp"),"PX_LAST",$C7,$C7,"days=all","dts=h","fill=0","QtTyp=P")} -> 919.11184 | AL7: 0 | AM7: {=_xll.BDH(SUBSTITUTE(AM$4," Corp","@ANDE Corp"),"PX_LAST",$C7,$C7,"days=all","dts=h","fill=0","QtTyp=P")} -> 973.4379 | AN7: {=_xll.BDH(SUBSTITUTE(AN$4," Corp","@ANDE Corp"),"PX_LAST",$C7,$C7,"days=all","dts=h","fill=0","QtTyp=P")} -> 884.78991 | AO7: {=_xll.BDH(SUBSTITUTE(AO$4," Corp","@ANDE Corp"),"PX_LAST",$C7,$C7,"days=all","dts=h","fill=0","QtTyp=P")} -> 938.85137 | AP7: 0 | AQ7: 0 | AR7: 0 | AS7: 0
C8: 40633 | D8: 0 | E8: {=_xll.BDH(SUBSTITUTE(E$4," Corp","@ANDE Corp"),"PX_LAST",$C8,$C8,"days=all","dts=h","fill=0","QtTyp=P")} -> 0 | F8: {=_xll.BDH(SUBSTITUTE(F$4," Corp","@ANDE Corp"),"PX_LAST",$C8,$C8,"days=all","dts=h","fill=0","QtTyp=P")} -> 972.22627 | G8: {=_xll.BDH(SUBSTITUTE(G$4," Corp","@ANDE Corp"),"PX_LAST",$C8,$C8,"days=all","dts=h","fill=0","QtTyp=P")} -> 862.66705 | H8: {=_xll.BDH(SUBSTITUTE(H$4," Corp","@ANDE Corp"),"PX_LAST",$C8,$C8,"days=all","dts=h","fill=0","QtTyp=P")} -> 999.56106 | I8: {=_xll.BDH(SUBSTITUTE(I$4," Corp","@ANDE Corp"),"PX_LAST",$C8,$C8,"days=all","dts=h","fill=0","QtTyp=P")} -> 943.76255 | J8: {=_xll.BDH(SUBSTITUTE(J$4," Corp","@ANDE Corp"),"PX_LAST",$C8,$C8,"days=all","dts=h","fill=0","QtTyp=P")} -> 810.58154 | K8: {=_xll.BDH(SUBSTITUTE(K$4," Corp","@ANDE Corp"),"PX_LAST",$C8,$C8,"days=all","dts=h","fill=0","QtTyp=P")} -> 786.23758 | L8: {=_xll.BDH(SUBSTITUTE(L$4," Corp","@ANDE Corp"),"PX_LAST",$C8,$C8,"days=all","dts=h","fill=0","QtTyp=P")} -> 629.84514 | ... N8: {=_xll.BDH(SUBSTITUTE(N$4," Corp","@ANDE Corp"),"PX_LAST",$C8,$C8,"days=all","dts=h","fill=0","QtTyp=P")} -> 761.35682 | O8: 0 | P8: 0 | Q8: 0 | R8: 0 | S8: 0 | T8: 0 | U8: 0 | V8: 0 | W8: 0 | X8: 0 | Y8: 0 | Z8: 0 | AA8: 0 | AB8: 0 | AC8: 0 | AD8: 0 | AE8: 0 | AF8: 0 | AG8: 0 | AH8: 0 | AI8: {=_xll.BDH(SUBSTITUTE(AI$4," Corp","@ANDE Corp"),"PX_LAST",$C8,$C8,"days=all","dts=h","fill=0","QtTyp=P")} -> 1009.3218 | AJ8: {=_xll.BDH(SUBSTITUTE(AJ$4," Corp","@ANDE Corp"),"PX_LAST",$C8,$C8,"days=all","dts=h","fill=0","QtTyp=P")} -> 959.89119 | AK8: {=_xll.BDH(SUBSTITUTE(AK$4," Corp","@ANDE Corp"),"PX_LAST",$C8,$C8,"days=all","dts=h","fill=0","QtTyp=P")} -> 910.53647 | AL8: 0 | AM8: {=_xll.BDH(SUBSTITUTE(AM$4," Corp","@ANDE Corp"),"PX_LAST",$C8,$C8,"days=all","dts=h","fill=0","QtTyp=P")} -> 984.09262 | AN8: {=_xll.BDH(SUBSTITUTE(AN$4," Corp","@ANDE Corp"),"PX_LAST",$C8,$C8,"days=all","dts=h","fill=0","QtTyp=P")} -> 871.58418 | AO8: {=_xll.BDH(SUBSTITUTE(AO$4," Corp","@ANDE Corp"),"PX_LAST",$C8,$C8,"days=all","dts=h","fill=0","QtTyp=P")} -> 939.28759 | AP8: 0 | AQ8: 0 | AR8: 0 | AS8: 0
C9: 40662 | D9: 0 | E9: {=_xll.BDH(SUBSTITUTE(E$4," Corp","@ANDE Corp"),"PX_LAST",$C9,$C9,"days=all","dts=h","fill=0","QtTyp=P")} -> 0 | F9: {=_xll.BDH(SUBSTITUTE(F$4," Corp","@ANDE Corp"),"PX_LAST",$C9,$C9,"days=all","dts=h","fill=0","QtTyp=P")} -> 980.33146 | G9: {=_xll.BDH(SUBSTITUTE(G$4," Corp","@ANDE Corp"),"PX_LAST",$C9,$C9,"days=all","dts=h","fill=0","QtTyp=P")} -> 869.20783 | H9: 0 | I9: {=_xll.BDH(SUBSTITUTE(I$4," Corp","@ANDE Corp"),"PX_LAST",$C9,$C9,"days=all","dts=h","fill=0","QtTyp=P")} -> 951.30077 | J9: {=_xll.BDH(SUBSTITUTE(J$4," Corp","@ANDE Corp"),"PX_LAST",$C9,$C9,"days=all","dts=h","fill=0","QtTyp=P")} -> 817.91111 | K9: {=_xll.BDH(SUBSTITUTE(K$4," Corp","@ANDE Corp"),"PX_LAST",$C9,$C9,"days=all","dts=h","fill=0","QtTyp=P")} -> 794.37003 | L9: {=_xll.BDH(SUBSTITUTE(L$4," Corp","@ANDE Corp"),"PX_LAST",$C9,$C9,"days=all","dts=h","fill=0","QtTyp=P")} -> 641.78492 | M9: {=_xll.BDH(SUBSTITUTE(M$4," Corp","@ANDE Corp"),"PX_LAST",$C9,$C9,"days=all","dts=h","fill=0","QtTyp=P")} -> 896.21379 | N9: {=_xll.BDH(SUBSTITUTE(N$4," Corp","@ANDE Corp"),"PX_LAST",$C9,$C9,"days=all","dts=h","fill=0","QtTyp=P")} -> 769.98675 | O9: 0 | P9: 0 | Q9: 0 | R9: 0 | S9: 0 | T9: 0 | U9: 0 | V9: 0 | W9: 0 | X9: 0 | Y9: 0 | Z9: 0 | AA9: 0 | AB9: 0 | AC9: 0 | AD9: 0 | AE9: 0 | AF9: 0 | AG9: 0 | AH9: 0 | AI9: {=_xll.BDH(SUBSTITUTE(AI$4," Corp","@ANDE Corp"),"PX_LAST",$C9,$C9,"days=all","dts=h","fill=0","QtTyp=P")} -> 1016.7711 | AJ9: {=_xll.BDH(SUBSTITUTE(AJ$4," Corp","@ANDE Corp"),"PX_LAST",$C9,$C9,"days=all","dts=h","fill=0","QtTyp=P")} -> 973.75241 | AK9: {=_xll.BDH(SUBSTITUTE(AK$4," Corp","@ANDE Corp"),"PX_LAST",$C9,$C9,"days=all","dts=h","fill=0","QtTyp=P")} -> 930.52655 | AL9: 0 | AM9: {=_xll.BDH(SUBSTITUTE(AM$4," Corp","@ANDE Corp"),"PX_LAST",$C9,$C9,"days=all","dts=h","fill=0","QtTyp=P")} -> 993.12689 | AN9: {=_xll.BDH(SUBSTITUTE(AN$4," Corp","@ANDE Corp"),"PX_LAST",$C9,$C9,"days=all","dts=h","fill=0","QtTyp=P")} -> 894.74604 | AO9: {=_xll.BDH(SUBSTITUTE(AO$4," Corp","@ANDE Corp"),"PX_LAST",$C9,$C9,"days=all","dts=h","fill=0","QtTyp=P")} -> 955.61115 | AP9: 0 | AQ9: 0 | AR9: 0 | AS9: 0
C10: 40694 | D10: 0 | E10: {=_xll.BDH(SUBSTITUTE(E$4," Corp","@ANDE Corp"),"PX_LAST",$C10,$C10,"days=all","dts=h","fill=0","QtTyp=P")} -> 0 | F10: {=_xll.BDH(SUBSTITUTE(F$4," Corp","@ANDE Corp"),"PX_LAST",$C10,$C10,"days=all","dts=h","fill=0","QtTyp=P")} -> 990.05358 | G10: {=_xll.BDH(SUBSTITUTE(G$4," Corp","@ANDE Corp"),"PX_LAST",$C10,$C10,"days=all","dts=h","fill=0","QtTyp=P")} -> 879.41311 | H10: 0 | I10: {=_xll.BDH(SUBSTITUTE(I$4," Corp","@ANDE Corp"),"PX_LAST",$C10,$C10,"days=all","dts=h","fill=0","QtTyp=P")} -> 960.7788 | J10: {=_xll.BDH(SUBSTITUTE(J$4," Corp","@ANDE Corp"),"PX_LAST",$C10,$C10,"days=all","dts=h","fill=0","QtTyp=P")} -> 828.77985 | K10: {=_xll.BDH(SUBSTITUTE(K$4," Corp","@ANDE Corp"),"PX_LAST",$C10,$C10,"days=all","dts=h","fill=0","QtTyp=P")} -> 805.49623 | L10: {=_xll.BDH(SUBSTITUTE(L$4," Corp","@ANDE Corp"),"PX_LAST",$C10,$C10,"days=all","dts=h","fill=0","QtTyp=P")} -> 653.00725 | M10: {=_xll.BDH(SUBSTITUTE(M$4," Corp","@ANDE Corp"),"PX_LAST",$C10,$C10,"days=all","dts=h","fill=0","QtTyp=P")} -> 905.90005 | N10: {=_xll.BDH(SUBSTITUTE(N$4," Corp","@ANDE Corp"),"PX_LAST",$C10,$C10,"days=all","dts=h","fill=0","QtTyp=P")} -> 781.55249 | O10: 0 | P10: 0 | Q10: 0 | R10: 0 | S10: 0 | T10: 0 | U10: 0 | V10: 0 | W10: 0 | X10: 0 | Y10: 0 | Z10: 0 | AA10: 0 | AB10: 0 | AC10: 0 | AD10: 0 | AE10: 0 | AF10: 0 | AG10: 0 | AH10: 0 | AI10: {=_xll.BDH(SUBSTITUTE(AI$4," Corp","@ANDE Corp"),"PX_LAST",$C10,$C10,"days=all","dts=h","fill=0","QtTyp=P")} -> 1027.0253 | AJ10: {=_xll.BDH(SUBSTITUTE(AJ$4," Corp","@ANDE Corp"),"PX_LAST",$C10,$C10,"days=all","dts=h","fill=0","QtTyp=P")} -> 987.98501 | AK10: {=_xll.BDH(SUBSTITUTE(AK$4," Corp","@ANDE Corp"),"PX_LAST",$C10,$C10,"days=all","dts=h","fill=0","QtTyp=P")} -> 946.49932 | AL10: 0 | AM10: {=_xll.BDH(SUBSTITUTE(AM$4," Corp","@ANDE Corp"),"PX_LAST",$C10,$C10,"days=all","dts=h","fill=0","QtTyp=P")} -> 1005.9476 | AN10: {=_xll.BDH(SUBSTITUTE(AN$4," Corp","@ANDE Corp"),"PX_LAST",$C10,$C10,"days=all","dts=h","fill=0","QtTyp=P")} -> 912.66539 | AO10: {=_xll.BDH(SUBSTITUTE(AO$4," Corp","@ANDE Corp"),"PX_LAST",$C10,$C10,"days=all","dts=h","fill=0","QtTyp=P")} -> 971.27406 | AP10: 0 | AQ10: 0 | AR10: 0 | AS10: 0
C11: 40724 | D11: 0 | E11: {=_xll.BDH(SUBSTITUTE(E$4," Corp","@ANDE Corp"),"PX_LAST",$C11,$C11,"days=all","dts=h","fill=0","QtTyp=P")} -> 0 | F11: {=_xll.BDH(SUBSTITUTE(F$4," Corp","@ANDE Corp"),"PX_LAST",$C11,$C11,"days=all","dts=h","fill=0","QtTyp=P")} -> 999.54214 | G11: {=_xll.BDH(SUBSTITUTE(G$4," Corp","@ANDE Corp"),"PX_LAST",$C11,$C11,"days=all","dts=h","fill=0","QtTyp=P")} -> 886.76654 | H11: 0 | I11: {=_xll.BDH(SUBSTITUTE(I$4," Corp","@ANDE Corp"),"PX_LAST",$C11,$C11,"days=all","dts=h","fill=0","QtTyp=P")} -> 969.91757 | J11: {=_xll.BDH(SUBSTITUTE(J$4," Corp","@ANDE Corp"),"PX_LAST",$C11,$C11,"days=all","dts=h","fill=0","QtTyp=P")} -> 834.69535 | K11: {=_xll.BDH(SUBSTITUTE(K$4," Corp","@ANDE Corp"),"PX_LAST",$C11,$C11,"days=all","dts=h","fill=0","QtTyp=P")} -> 810.67114 | L11: {=_xll.BDH(SUBSTITUTE(L$4," Corp","@ANDE Corp"),"PX_LAST",$C11,$C11,"days=all","dts=h","fill=0","QtTyp=P")} -> 656.61357 | M11: {=_xll.BDH(SUBSTITUTE(M$4," Corp","@ANDE Corp"),"PX_LAST",$C11,$C11,"days=all","dts=h","fill=0","QtTyp=P")} -> 914.05053 | N11: {=_xll.BDH(SUBSTITUTE(N$4," Corp","@ANDE Corp"),"PX_LAST",$C11,$C11,"days=all","dts=h","fill=0","QtTyp=P")} -> 786.51817 | O11: 0 | P11: 0 | Q11: 0 | R11: 0 | S11: 0 | T11: 0 | U11: 0 | V11: 0 | W11: 0 | X11: 0 | Y11: 0 | Z11: 0 | AA11: 0 | AB11: 0 | AC11: 0 | AD11: 0 | AE11: 0 | AF11: 0 | AG11: 0 | AH11: 0 | AI11: {=_xll.BDH(SUBSTITUTE(AI$4," Corp","@ANDE Corp"),"PX_LAST",$C11,$C11,"days=all","dts=h","fill=0","QtTyp=P")} -> 1036.5137 | AJ11: {=_xll.BDH(SUBSTITUTE(AJ$4," Corp","@ANDE Corp"),"PX_LAST",$C11,$C11,"days=all","dts=h","fill=0","QtTyp=P")} -> 993.28163 | AK11: {=_xll.BDH(SUBSTITUTE(AK$4," Corp","@ANDE Corp"),"PX_LAST",$C11,$C11,"days=all","dts=h","fill=0","QtTyp=P")} -> 953.59354 | AL11: 0 | AM11: {=_xll.BDH(SUBSTITUTE(AM$4," Corp","@ANDE Corp"),"PX_LAST",$C11,$C11,"days=all","dts=h","fill=0","QtTyp=P")} -> 1013.3301 | AN11: {=_xll.BDH(SUBSTITUTE(AN$4," Corp","@ANDE Corp"),"PX_LAST",$C11,$C11,"days=all","dts=h","fill=0","QtTyp=P")} -> 920.02585 | AO11: {=_xll.BDH(SUBSTITUTE(AO$4," Corp","@ANDE Corp"),"PX_LAST",$C11,$C11,"days=all","dts=h","fill=0","QtTyp=P")} -> 977.85691 | AP11: 0 | AQ11: 0 | AR11: 0 | AS11: 0
C12: 40753 | D12: 0 | E12: {=_xll.BDH(SUBSTITUTE(E$4," Corp","@ANDE Corp"),"PX_LAST",$C12,$C12,"days=all","dts=h","fill=0","QtTyp=P")} -> 0 | F12: 0 | G12: {=_xll.BDH(SUBSTITUTE(G$4," Corp","@ANDE Corp"),"PX_LAST",$C12,$C12,"days=all","dts=h","fill=0","QtTyp=P")} -> 896.3173 | H12: 0 | I12: {=_xll.BDH(SUBSTITUTE(I$4," Corp","@ANDE Corp"),"PX_LAST",$C12,$C12,"days=all","dts=h","fill=0","QtTyp=P")} -> 979.27278 | J12: {=_xll.BDH(SUBSTITUTE(J$4," Corp","@ANDE Corp"),"PX_LAST",$C12,$C12,"days=all","dts=h","fill=0","QtTyp=P")} -> 843.12066 | K12: {=_xll.BDH(SUBSTITUTE(K$4," Corp","@ANDE Corp"),"PX_LAST",$C12,$C12,"days=all","dts=h","fill=0","QtTyp=P")} -> 818.66744 | L12: {=_xll.BDH(SUBSTITUTE(L$4," Corp","@ANDE Corp"),"PX_LAST",$C12,$C12,"days=all","dts=h","fill=0","QtTyp=P")} -> 658.27624 | M12: {=_xll.BDH(SUBSTITUTE(M$4," Corp","@ANDE Corp"),"PX_LAST",$C12,$C12,"days=all","dts=h","fill=0","QtTyp=P")} -> 923.42467 | N12: {=_xll.BDH(SUBSTITUTE(N$4," Corp","@ANDE Corp"),"PX_LAST",$C12,$C12,"days=all","dts=h","fill=0","QtTyp=P")} -> 793.77399 | O12: {=_xll.BDH(SUBSTITUTE(O$4," Corp","@ANDE Corp"),"PX_LAST",$C12,$C12,"days=all","dts=h","fill=0","QtTyp=P")} -> 868.91343 | P12: {=_xll.BDH(SUBSTITUTE(P$4," Corp","@ANDE Corp"),"PX_LAST",$C12,$C12,"days=all","dts=h","fill=0","QtTyp=P")} -> 744.66213 | Q12: 0 | R12: 0 | S12: 0 | T12: 0 | U12: 0 | V12: 0 | W12: 0 | X12: 0 | Y12: 0 | Z12: 0 | AA12: 0 | AB12: 0 | AC12: 0 | AD12: 0 | AE12: 0 | AF12: 0 | AG12: 0 | AH12: 0 | AI12: {=_xll.BDH(SUBSTITUTE(AI$4," Corp","@ANDE Corp"),"PX_LAST",$C12,$C12,"days=all","dts=h","fill=0","QtTyp=P")} -> 997.60878 | AJ12: {=_xll.BDH(SUBSTITUTE(AJ$4," Corp","@ANDE Corp"),"PX_LAST",$C12,$C12,"days=all","dts=h","fill=0","QtTyp=P")} -> 951.23625 | AK12: {=_xll.BDH(SUBSTITUTE(AK$4," Corp","@ANDE Corp"),"PX_LAST",$C12,$C12,"days=all","dts=h","fill=0","QtTyp=P")} -> 901.39527 | AL12: 0 | AM12: {=_xll.BDH(SUBSTITUTE(AM$4," Corp","@ANDE Corp"),"PX_LAST",$C12,$C12,"days=all","dts=h","fill=0","QtTyp=P")} -> 974.08842 | AN12: {=_xll.BDH(SUBSTITUTE(AN$4," Corp","@ANDE Corp"),"PX_LAST",$C12,$C12,"days=all","dts=h","fill=0","QtTyp=P")} -> 863.568 | AO12: {=_xll.BDH(SUBSTITUTE(AO$4," Corp","@ANDE Corp"),"PX_LAST",$C12,$C12,"days=all","dts=h","fill=0","QtTyp=P")} -> 932.13832 | AP12: 0 | AQ12: 0 | AR12: 0 | AS12: 0
C13: 40786 | D13: 0 | E13: {=_xll.BDH(SUBSTITUTE(E$4," Corp","@ANDE Corp"),"PX_LAST",$C13,$C13,"days=all","dts=h","fill=0","QtTyp=P")} -> 0 | F13: 0 | G13: {=_xll.BDH(SUBSTITUTE(G$4," Corp","@ANDE Corp"),"PX_LAST",$C13,$C13,"days=all","dts=h","fill=0","QtTyp=P")} -> 914.28875 | H13: 0 | I13: {=_xll.BDH(SUBSTITUTE(I$4," Corp","@ANDE Corp"),"PX_LAST",$C13,$C13,"days=all","dts=h","fill=0","QtTyp=P")} -> 989.88856 | J13: {=_xll.BDH(SUBSTITUTE(J$4," Corp","@ANDE Corp"),"PX_LAST",$C13,$C13,"days=all","dts=h","fill=0","QtTyp=P")} -> 868.53593 | K13: {=_xll.BDH(SUBSTITUTE(K$4," Corp","@ANDE Corp"),"PX_LAST",$C13,$C13,"days=all","dts=h","fill=0","QtTyp=P")} -> 846.63905 | L13: {=_xll.BDH(SUBSTITUTE(L$4," Corp","@ANDE Corp"),"PX_LAST",$C13,$C13,"days=all","dts=h","fill=0","QtTyp=P")} -> 694.97559 | M13: {=_xll.BDH(SUBSTITUTE(M$4," Corp","@ANDE Corp"),"PX_LAST",$C13,$C13,"days=all","dts=h","fill=0","QtTyp=P")} -> 937.86048 | N13: {=_xll.BDH(SUBSTITUTE(N$4," Corp","@ANDE Corp"),"PX_LAST",$C13,$C13,"days=all","dts=h","fill=0","QtTyp=P")} -> 824.24018 | O13: {=_xll.BDH(SUBSTITUTE(O$4," Corp","@ANDE Corp"),"PX_LAST",$C13,$C13,"days=all","dts=h","fill=0","QtTyp=P")} -> 890.72566 | P13: {=_xll.BDH(SUBSTITUTE(P$4," Corp","@ANDE Corp"),"PX_LAST",$C13,$C13,"days=all","dts=h","fill=0","QtTyp=P")} -> 778.31165 | Q13: 0 | R13: 0 | S13: 0 | T13: 0 | U13: 0 | V13: 0 | W13: 0 | X13: 0 | Y13: 0 | Z13: 0 | AA13: 0 | AB13: 0 | AC13: 0 | AD13: 0 | AE13: 0 | AF13: 0 | AG13: 0 | AH13: 0 | AI13: {=_xll.BDH(SUBSTITUTE(AI$4," Corp","@ANDE Corp"),"PX_LAST",$C13,$C13,"days=all","dts=h","fill=0","QtTyp=P")} -> 1009.9149 | AJ13: {=_xll.BDH(SUBSTITUTE(AJ$4," Corp","@ANDE Corp"),"PX_LAST",$C13,$C13,"days=all","dts=h","fill=0","QtTyp=P")} -> 990.69003 | AK13: {=_xll.BDH(SUBSTITUTE(AK$4," Corp","@ANDE Corp"),"PX_LAST",$C13,$C13,"days=all","dts=h","fill=0","QtTyp=P")} -> 954.97578 | AL13: 0 | AM13: {=_xll.BDH(SUBSTITUTE(AM$4," Corp","@ANDE Corp"),"PX_LAST",$C13,$C13,"days=all","dts=h","fill=0","QtTyp=P")} -> 1002.5208 | AN13: {=_xll.BDH(SUBSTITUTE(AN$4," Corp","@ANDE Corp"),"PX_LAST",$C13,$C13,"days=all","dts=h","fill=0","QtTyp=P")} -> 929.26675 | AO13: {=_xll.BDH(SUBSTITUTE(AO$4," Corp","@ANDE Corp"),"PX_LAST",$C13,$C13,"days=all","dts=h","fill=0","QtTyp=P")} -> 977.76183 | AP13: 0 | AQ13: 0 | AR13: 0 | AS13: 0
C14: 40816 | D14: 0 | E14: {=_xll.BDH(SUBSTITUTE(E$4," Corp","@ANDE Corp"),"PX_LAST",$C14,$C14,"days=all","dts=h","fill=0","QtTyp=P")} -> 0 | F14: 0 | G14: {=_xll.BDH(SUBSTITUTE(G$4," Corp","@ANDE Corp"),"PX_LAST",$C14,$C14,"days=all","dts=h","fill=0","QtTyp=P")} -> 927.93126 | H14: 0 | I14: {=_xll.BDH(SUBSTITUTE(I$4," Corp","@ANDE Corp"),"PX_LAST",$C14,$C14,"days=all","dts=h","fill=0","QtTyp=P")} -> 999.55371 | J14: {=_xll.BDH(SUBSTITUTE(J$4," Corp","@ANDE Corp"),"PX_LAST",$C14,$C14,"days=all","dts=h","fill=0","QtTyp=P")} -> 883.86741 | K14: {=_xll.BDH(SUBSTITUTE(K$4," Corp","@ANDE Corp"),"PX_LAST",$C14,$C14,"days=all","dts=h","fill=0","QtTyp=P")} -> 862.55815 | L14: {=_xll.BDH(SUBSTITUTE(L$4," Corp","@ANDE Corp"),"PX_LAST",$C14,$C14,"days=all","dts=h","fill=0","QtTyp=P")} -> 706.04838 | M14: {=_xll.BDH(SUBSTITUTE(M$4," Corp","@ANDE Corp"),"PX_LAST",$C14,$C14,"days=all","dts=h","fill=0","QtTyp=P")} -> 950.18664 | N14: {=_xll.BDH(SUBSTITUTE(N$4," Corp","@ANDE Corp"),"PX_LAST",$C14,$C14,"days=all","dts=h","fill=0","QtTyp=P")} -> 839.69787 | O14: {=_xll.BDH(SUBSTITUTE(O$4," Corp","@ANDE Corp"),"PX_LAST",$C14,$C14,"days=all","dts=h","fill=0","QtTyp=P")} -> 905.30427 | P14: {=_xll.BDH(SUBSTITUTE(P$4," Corp","@ANDE Corp"),"PX_LAST",$C14,$C14,"days=all","dts=h","fill=0","QtTyp=P")} -> 791.0818 | Q14: 0 | R14: 0 | S14: 0 | T14: 0 | U14: 0 | V14: 0 | W14: 0 | X14: 0 | Y14: 0 | Z14: 0 | AA14: 0 | AB14: 0 | AC14: 0 | AD14: 0 | AE14: 0 | AF14: 0 | AG14: 0 | AH14: 0 | AI14: {=_xll.BDH(SUBSTITUTE(AI$4," Corp","@ANDE Corp"),"PX_LAST",$C14,$C14,"days=all","dts=h","fill=0","QtTyp=P")} -> 1021.5229 | AJ14: {=_xll.BDH(SUBSTITUTE(AJ$4," Corp","@ANDE Corp"),"PX_LAST",$C14,$C14,"days=all","dts=h","fill=0","QtTyp=P")} -> 1006.4522 | AK14: {=_xll.BDH(SUBSTITUTE(AK$4," Corp","@ANDE Corp"),"PX_LAST",$C14,$C14,"days=all","dts=h","fill=0","QtTyp=P")} -> 968.1444 | AL14: 0 | AM14: {=_xll.BDH(SUBSTITUTE(AM$4," Corp","@ANDE Corp"),"PX_LAST",$C14,$C14,"days=all","dts=h","fill=0","QtTyp=P")} -> 1019.6791 | AN14: {=_xll.BDH(SUBSTITUTE(AN$4," Corp","@ANDE Corp"),"PX_LAST",$C14,$C14,"days=all","dts=h","fill=0","QtTyp=P")} -> 941.03449 | AO14: {=_xll.BDH(SUBSTITUTE(AO$4," Corp","@ANDE Corp"),"PX_LAST",$C14,$C14,"days=all","dts=h","fill=0","QtTyp=P")} -> 992.11906 | AP14: 0 | AQ14: 0 | AR14: 0 | AS14: 0
C15: 40847 | D15: 0 | E15: {=_xll.BDH(SUBSTITUTE(E$4," Corp","@ANDE Corp"),"PX_LAST",$C15,$C15,"days=all","dts=h","fill=0","QtTyp=P")} -> 0 | F15: 0 | G15: {=_xll.BDH(SUBSTITUTE(G$4," Corp","@ANDE Corp"),"PX_LAST",$C15,$C15,"days=all","dts=h","fill=0","QtTyp=P")} -> 935.43753 | H15: 0 | I15: 0 | J15: {=_xll.BDH(SUBSTITUTE(J$4," Corp","@ANDE Corp"),"PX_LAST",$C15,$C15,"days=all","dts=h","fill=0","QtTyp=P")} -> 891.23163 | K15: {=_xll.BDH(SUBSTITUTE(K$4," Corp","@ANDE Corp"),"PX_LAST",$C15,$C15,"days=all","dts=h","fill=0","QtTyp=P")} -> 869.92822 | L15: {=_xll.BDH(SUBSTITUTE(L$4," Corp","@ANDE Corp"),"PX_LAST",$C15,$C15,"days=all","dts=h","fill=0","QtTyp=P")} -> 715.32968 | M15: {=_xll.BDH(SUBSTITUTE(M$4," Corp","@ANDE Corp"),"PX_LAST",$C15,$C15,"days=all","dts=h","fill=0","QtTyp=P")} -> 958.06831 | N15: {=_xll.BDH(SUBSTITUTE(N$4," Corp","@ANDE Corp"),"PX_LAST",$C15,$C15,"days=all","dts=h","fill=0","QtTyp=P")} -> 847.4671 | O15: {=_xll.BDH(SUBSTITUTE(O$4," Corp","@ANDE Corp"),"PX_LAST",$C15,$C15,"days=all","dts=h","fill=0","QtTyp=P")} -> 912.99486 | P15: {=_xll.BDH(SUBSTITUTE(P$4," Corp","@ANDE Corp"),"PX_LAST",$C15,$C15,"days=all","dts=h","fill=0","QtTyp=P")} -> 800.25373 | Q15: 0 | R15: 0 | S15: 0 | T15: 0 | U15: 0 | V15: 0 | W15: 0 | X15: 0 | Y15: 0 | Z15: 0 | AA15: 0 | AB15: 0 | AC15: 0 | AD15: 0 | AE15: 0 | AF15: 0 | AG15: 0 | AH15: 0 | AI15: {=_xll.BDH(SUBSTITUTE(AI$4," Corp","@ANDE Corp"),"PX_LAST",$C15,$C15,"days=all","dts=h","fill=0","QtTyp=P")} -> 1029.9979 | AJ15: {=_xll.BDH(SUBSTITUTE(AJ$4," Corp","@ANDE Corp"),"PX_LAST",$C15,$C15,"days=all","dts=h","fill=0","QtTyp=P")} -> 1017.6473 | AK15: {=_xll.BDH(SUBSTITUTE(AK$4," Corp","@ANDE Corp"),"PX_LAST",$C15,$C15,"days=all","dts=h","fill=0","QtTyp=P")} -> 980.88756 | AL15: 0 | AM15: {=_xll.BDH(SUBSTITUTE(AM$4," Corp","@ANDE Corp"),"PX_LAST",$C15,$C15,"days=all","dts=h","fill=0","QtTyp=P")} -> 1028.2582 | AN15: {=_xll.BDH(SUBSTITUTE(AN$4," Corp","@ANDE Corp"),"PX_LAST",$C15,$C15,"days=all","dts=h","fill=0","QtTyp=P")} -> 952.01018 | AO15: {=_xll.BDH(SUBSTITUTE(AO$4," Corp","@ANDE Corp"),"PX_LAST",$C15,$C15,"days=all","dts=h","fill=0","QtTyp=P")} -> 1004.6524 | AP15: 0 | AQ15: 0 | AR15: 0 | AS15: 0
C16: 40877 | D16: 0 | E16: {=_xll.BDH(SUBSTITUTE(E$4," Corp","@ANDE Corp"),"PX_LAST",$C16,$C16,"days=all","dts=h","fill=0","QtTyp=P")} -> 0 | F16: 0 | G16: {=_xll.BDH(SUBSTITUTE(G$4," Corp","@ANDE Corp"),"PX_LAST",$C16,$C16,"days=all","dts=h","fill=0","QtTyp=P")} -> 945.47921 | H16: 0 | I16: 0 | J16: {=_xll.BDH(SUBSTITUTE(J$4," Corp","@ANDE Corp"),"PX_LAST",$C16,$C16,"days=all","dts=h","fill=0","QtTyp=P")} -> 904.37712 | K16: {=_xll.BDH(SUBSTITUTE(K$4," Corp","@ANDE Corp"),"PX_LAST",$C16,$C16,"days=all","dts=h","fill=0","QtTyp=P")} -> 884.2486 | L16: {=_xll.BDH(SUBSTITUTE(L$4," Corp","@ANDE Corp"),"PX_LAST",$C16,$C16,"days=all","dts=h","fill=0","QtTyp=P")} -> 736.49904 | M16: {=_xll.BDH(SUBSTITUTE(M$4," Corp","@ANDE Corp"),"PX_LAST",$C16,$C16,"days=all","dts=h","fill=0","QtTyp=P")} -> 966.8155 | N16: {=_xll.BDH(SUBSTITUTE(N$4," Corp","@ANDE Corp"),"PX_LAST",$C16,$C16,"days=all","dts=h","fill=0","QtTyp=P")} -> 863.31975 | O16: {=_xll.BDH(SUBSTITUTE(O$4," Corp","@ANDE Corp"),"PX_LAST",$C16,$C16,"days=all","dts=h","fill=0","QtTyp=P")} -> 924.5038 | P16: {=_xll.BDH(SUBSTITUTE(P$4," Corp","@ANDE Corp"),"PX_LAST",$C16,$C16,"days=all","dts=h","fill=0","QtTyp=P")} -> 819.72454 | Q16: 0 | R16: 0 | S16: 0 | T16: 0 | U16: 0 | V16: 0 | W16: 0 | X16: 0 | Y16: 0 | Z16: 0 | AA16: 0 | AB16: 0 | AC16: 0 | AD16: 0 | AE16: 0 | AF16: 0 | AG16: 0 | AH16: 0 | AI16: {=_xll.BDH(SUBSTITUTE(AI$4," Corp","@ANDE Corp"),"PX_LAST",$C16,$C16,"days=all","dts=h","fill=0","QtTyp=P")} -> 1038.9528 | AJ16: {=_xll.BDH(SUBSTITUTE(AJ$4," Corp","@ANDE Corp"),"PX_LAST",$C16,$C16,"days=all","dts=h","fill=0","QtTyp=P")} -> 1040.1122 | AK16: {=_xll.BDH(SUBSTITUTE(AK$4," Corp","@ANDE Corp"),"PX_LAST",$C16,$C16,"days=all","dts=h","fill=0","QtTyp=P")} -> 1009.0702 | AL16: 0 | AM16: {=_xll.BDH(SUBSTITUTE(AM$4," Corp","@ANDE Corp"),"PX_LAST",$C16,$C16,"days=all","dts=h","fill=0","QtTyp=P")} -> 1043.1239 | AN16: {=_xll.BDH(SUBSTITUTE(AN$4," Corp","@ANDE Corp"),"PX_LAST",$C16,$C16,"days=all","dts=h","fill=0","QtTyp=P")} -> 981.07401 | AO16: {=_xll.BDH(SUBSTITUTE(AO$4," Corp","@ANDE Corp"),"PX_LAST",$C16,$C16,"days=all","dts=h","fill=0","QtTyp=P")} -> 1030.3798 | AP16: 0 | AQ16: 0 | AR16: 0 | AS16: 0
C17: 40906 | D17: 0 | E17: {=_xll.BDH(SUBSTITUTE(E$4," Corp","@ANDE Corp"),"PX_LAST",$C17,$C17,"days=all","dts=h","fill=0","QtTyp=P")} -> 0 | F17: 0 | G17: {=_xll.BDH(SUBSTITUTE(G$4," Corp","@ANDE Corp"),"PX_LAST",$C17,$C17,"days=all","dts=h","fill=0","QtTyp=P")} -> 952.23426 | H17: 0 | I17: 0 | J17: {=_xll.BDH(SUBSTITUTE(J$4," Corp","@ANDE Corp"),"PX_LAST",$C17,$C17,"days=all","dts=h","fill=0","QtTyp=P")} -> 907.95657 | K17: {=_xll.BDH(SUBSTITUTE(K$4," Corp","@ANDE Corp"),"PX_LAST",$C17,$C17,"days=all","dts=h","fill=0","QtTyp=P")} -> 886.48605 | L17: {=_xll.BDH(SUBSTITUTE(L$4," Corp","@ANDE Corp"),"PX_LAST",$C17,$C17,"days=all","dts=h","fill=0","QtTyp=P")} -> 732.58897 | M17: {=_xll.BDH(SUBSTITUTE(M$4," Corp","@ANDE Corp"),"PX_LAST",$C17,$C17,"days=all","dts=h","fill=0","QtTyp=P")} -> 974.79378 | N17: {=_xll.BDH(SUBSTITUTE(N$4," Corp","@ANDE Corp"),"PX_LAST",$C17,$C17,"days=all","dts=h","fill=0","QtTyp=P")} -> 863.51333 | O17: {=_xll.BDH(SUBSTITUTE(O$4," Corp","@ANDE Corp"),"PX_LAST",$C17,$C17,"days=all","dts=h","fill=0","QtTyp=P")} -> 929.68268 | P17: {=_xll.BDH(SUBSTITUTE(P$4," Corp","@ANDE Corp"),"PX_LAST",$C17,$C17,"days=all","dts=h","fill=0","QtTyp=P")} -> 816.94672 | Q17: {=_xll.BDH(SUBSTITUTE(Q$4," Corp","@ANDE Corp"),"PX_LAST",$C17,$C17,"days=all","dts=h","fill=0","QtTyp=P")} -> 795.38577 | R17: 0 | S17: 0 | T17: 0 | U17: 0 | V17: 0 | W17: 0 | X17: 0 | Y17: 0 | Z17: 0 | AA17: 0 | AB17: 0 | AC17: 0 | AD17: 0 | AE17: 0 | AF17: 0 | AG17: 0 | AH17: 0 | AI17: {=_xll.BDH(SUBSTITUTE(AI$4," Corp","@ANDE Corp"),"PX_LAST",$C17,$C17,"days=all","dts=h","fill=0","QtTyp=P")} -> 1047.9467 | AJ17: {=_xll.BDH(SUBSTITUTE(AJ$4," Corp","@ANDE Corp"),"PX_LAST",$C17,$C17,"days=all","dts=h","fill=0","QtTyp=P")} -> 1038.4205 | AK17: {=_xll.BDH(SUBSTITUTE(AK$4," Corp","@ANDE Corp"),"PX_LAST",$C17,$C17,"days=all","dts=h","fill=0","QtTyp=P")} -> 1009.1104 | AL17: 0 | AM17: {=_xll.BDH(SUBSTITUTE(AM$4," Corp","@ANDE Corp"),"PX_LAST",$C17,$C17,"days=all","dts=h","fill=0","QtTyp=P")} -> 1047.5022 | AN17: {=_xll.BDH(SUBSTITUTE(AN$4," Corp","@ANDE Corp"),"PX_LAST",$C17,$C17,"days=all","dts=h","fill=0","QtTyp=P")} -> 979.64652 | AO17: {=_xll.BDH(SUBSTITUTE(AO$4," Corp","@ANDE Corp"),"PX_LAST",$C17,$C17,"days=all","dts=h","fill=0","QtTyp=P")} -> 1027.4858 | AP17: 0 | AQ17: 0 | AR17: 0 | AS17: 0
C18: 40939 | D18: 0 | E18: 0 | F18: 0 | G18: {=_xll.BDH(SUBSTITUTE(G$4," Corp","@ANDE Corp"),"PX_LAST",$C18,$C18,"days=all","dts=h","fill=0","QtTyp=P")} -> 962.14973 | H18: 0 | I18: 0 | J18: {=_xll.BDH(SUBSTITUTE(J$4," Corp","@ANDE Corp"),"PX_LAST",$C18,$C18,"days=all","dts=h","fill=0","QtTyp=P")} -> 919.74438 | K18: {=_xll.BDH(SUBSTITUTE(K$4," Corp","@ANDE Corp"),"PX_LAST",$C18,$C18,"days=all","dts=h","fill=0","QtTyp=P")} -> 899.23288 | L18: {=_xll.BDH(SUBSTITUTE(L$4," Corp","@ANDE Corp"),"PX_LAST",$C18,$C18,"days=all","dts=h","fill=0","QtTyp=P")} -> 745.07367 | M18: {=_xll.BDH(SUBSTITUTE(M$4," Corp","@ANDE Corp"),"PX_LAST",$C18,$C18,"days=all","dts=h","fill=0","QtTyp=P")} -> 984.02455 | N18: {=_xll.BDH(SUBSTITUTE(N$4," Corp","@ANDE Corp"),"PX_LAST",$C18,$C18,"days=all","dts=h","fill=0","QtTyp=P")} -> 877.34628 | O18: {=_xll.BDH(SUBSTITUTE(O$4," Corp","@ANDE Corp"),"PX_LAST",$C18,$C18,"days=all","dts=h","fill=0","QtTyp=P")} -> 940.4078 | P18: {=_xll.BDH(SUBSTITUTE(P$4," Corp","@ANDE Corp"),"PX_LAST",$C18,$C18,"days=all","dts=h","fill=0","QtTyp=P")} -> 831.80988 | Q18: {=_xll.BDH(SUBSTITUTE(Q$4," Corp","@ANDE Corp"),"PX_LAST",$C18,$C18,"days=all","dts=h","fill=0","QtTyp=P")} -> 809.61076 | R18: {=_xll.BDH(SUBSTITUTE(R$4," Corp","@ANDE Corp"),"PX_LAST",$C18,$C18,"days=all","dts=h","fill=0","QtTyp=P")} -> 666.00333 | S18: 0 | T18: 0 | U18: 0 | V18: 0 | W18: 0 | X18: 0 | Y18: 0 | Z18: 0 | AA18: 0 | AB18: 0 | AC18: 0 | AD18: 0 | AE18: 0 | AF18: 0 | AG18: 0 | AH18: 0 | AI18: 0 | AJ18: {=_xll.BDH(SUBSTITUTE(AJ$4," Corp","@ANDE Corp"),"PX_LAST",$C18,$C18,"days=all","dts=h","fill=0","QtTyp=P")} -> 1006.9698 | AK18: {=_xll.BDH(SUBSTITUTE(AK$4," Corp","@ANDE Corp"),"PX_LAST",$C18,$C18,"days=all","dts=h","fill=0","QtTyp=P")} -> 972.32801 | AL18: 0 | AM18: {=_xll.BDH(SUBSTITUTE(AM$4," Corp","@ANDE Corp"),"PX_LAST",$C18,$C18,"days=all","dts=h","fill=0","QtTyp=P")} -> 1011.6782 | AN18: {=_xll.BDH(SUBSTITUTE(AN$4," Corp","@ANDE Corp"),"PX_LAST",$C18,$C18,"days=all","dts=h","fill=0","QtTyp=P")} -> 932.69276 | AO18: {=_xll.BDH(SUBSTITUTE(AO$4," Corp","@ANDE Corp"),"PX_LAST",$C18,$C18,"days=all","dts=h","fill=0","QtTyp=P")} -> 994.6409 | AP18: {=_xll.BDH(SUBSTITUTE(AP$4," Corp","@ANDE Corp"),"PX_LAST",$C18,$C18,"days=all","dts=h","fill=0","QtTyp=P")} -> 0 | AQ18: 0 | AR18: 0 | AS18: 0
C19: 40968 | D19: 0 | E19: 0 | F19: 0 | G19: {=_xll.BDH(SUBSTITUTE(G$4," Corp","@ANDE Corp"),"PX_LAST",$C19,$C19,"days=all","dts=h","fill=0","QtTyp=P")} -> 969.59272 | H19: 0 | I19: 0 | J19: {=_xll.BDH(SUBSTITUTE(J$4," Corp","@ANDE Corp"),"PX_LAST",$C19,$C19,"days=all","dts=h","fill=0","QtTyp=P")} -> 928.07009 | K19: {=_xll.BDH(SUBSTITUTE(K$4," Corp","@ANDE Corp"),"PX_LAST",$C19,$C19,"days=all","dts=h","fill=0","QtTyp=P")} -> 908.19438 | L19: {=_xll.BDH(SUBSTITUTE(L$4," Corp","@ANDE Corp"),"PX_LAST",$C19,$C19,"days=all","dts=h","fill=0","QtTyp=P")} -> 755.03421 | M19: {=_xll.BDH(SUBSTITUTE(M$4," Corp","@ANDE Corp"),"PX_LAST",$C19,$C19,"days=all","dts=h","fill=0","QtTyp=P")} -> 991.32899 | N19: {=_xll.BDH(SUBSTITUTE(N$4," Corp","@ANDE Corp"),"PX_LAST",$C19,$C19,"days=all","dts=h","fill=0","QtTyp=P")} -> 886.87761 | O19: {=_xll.BDH(SUBSTITUTE(O$4," Corp","@ANDE Corp"),"PX_LAST",$C19,$C19,"days=all","dts=h","fill=0","QtTyp=P")} -> 948.32712 | P19: {=_xll.BDH(SUBSTITUTE(P$4," Corp","@ANDE Corp"),"PX_LAST",$C19,$C19,"days=all","dts=h","fill=0","QtTyp=P")} -> 841.61914 | Q19: {=_xll.BDH(SUBSTITUTE(Q$4," Corp","@ANDE Corp"),"PX_LAST",$C19,$C19,"days=all","dts=h","fill=0","QtTyp=P")} -> 819.82437 | R19: {=_xll.BDH(SUBSTITUTE(R$4," Corp","@ANDE Corp"),"PX_LAST",$C19,$C19,"days=all","dts=h","fill=0","QtTyp=P")} -> 676.17548 | S19: 0 | T19: 0 | U19: 0 | V19: 0 | W19: 0 | X19: 0 | Y19: 0 | Z19: 0 | AA19: 0 | AB19: 0 | AC19: 0 | AD19: 0 | AE19: 0 | AF19: 0 | AG19: 0 | AH19: 0 | AI19: 0 | AJ19: {=_xll.BDH(SUBSTITUTE(AJ$4," Corp","@ANDE Corp"),"PX_LAST",$C19,$C19,"days=all","dts=h","fill=0","QtTyp=P")} -> 1018.3312 | AK19: {=_xll.BDH(SUBSTITUTE(AK$4," Corp","@ANDE Corp"),"PX_LAST",$C19,$C19,"days=all","dts=h","fill=0","QtTyp=P")} -> 984.21784 | AL19: 0 | AM19: {=_xll.BDH(SUBSTITUTE(AM$4," Corp","@ANDE Corp"),"PX_LAST",$C19,$C19,"days=all","dts=h","fill=0","QtTyp=P")} -> 1020.7105 | AN19: {=_xll.BDH(SUBSTITUTE(AN$4," Corp","@ANDE Corp"),"PX_LAST",$C19,$C19,"days=all","dts=h","fill=0","QtTyp=P")} -> 948.70962 | AO19: {=_xll.BDH(SUBSTITUTE(AO$4," Corp","@ANDE Corp"),"PX_LAST",$C19,$C19,"days=all","dts=h","fill=0","QtTyp=P")} -> 1007.6325 | AP19: {=_xll.BDH(SUBSTITUTE(AP$4," Corp","@ANDE Corp"),"PX_LAST",$C19,$C19,"days=all","dts=h","fill=0","QtTyp=P")} -> 974.29167 | AQ19: 0 | AR19: 0 | AS19: 0
C20: 40998 | D20: 0 | E20: 0 | F20: 0 | G20: {=_xll.BDH(SUBSTITUTE(G$4," Corp","@ANDE Corp"),"PX_LAST",$C20,$C20,"days=all","dts=h","fill=0","QtTyp=P")} -> 978.52265 | H20: 0 | I20: 0 | J20: {=_xll.BDH(SUBSTITUTE(J$4," Corp","@ANDE Corp"),"PX_LAST",$C20,$C20,"days=all","dts=h","fill=0","QtTyp=P")} -> 937.41053 | K20: {=_xll.BDH(SUBSTITUTE(K$4," Corp","@ANDE Corp"),"PX_LAST",$C20,$C20,"days=all","dts=h","fill=0","QtTyp=P")} -> 917.87532 | L20: {=_xll.BDH(SUBSTITUTE(L$4," Corp","@ANDE Corp"),"PX_LAST",$C20,$C20,"days=all","dts=h","fill=0","QtTyp=P")} -> 764.4222 | M20: {=_xll.BDH(SUBSTITUTE(M$4," Corp","@ANDE Corp"),"PX_LAST",$C20,$C20,"days=all","dts=h","fill=0","QtTyp=P")} -> 999.65178 | N20: {=_xll.BDH(SUBSTITUTE(N$4," Corp","@ANDE Corp"),"PX_LAST",$C20,$C20,"days=all","dts=h","fill=0","QtTyp=P")} -> 896.8251 | O20: {=_xll.BDH(SUBSTITUTE(O$4," Corp","@ANDE Corp"),"PX_LAST",$C20,$C20,"days=all","dts=h","fill=0","QtTyp=P")} -> 957.50322 | P20: {=_xll.BDH(SUBSTITUTE(P$4," Corp","@ANDE Corp"),"PX_LAST",$C20,$C20,"days=all","dts=h","fill=0","QtTyp=P")} -> 851.23982 | Q20: {=_xll.BDH(SUBSTITUTE(Q$4," Corp","@ANDE Corp"),"PX_LAST",$C20,$C20,"days=all","dts=h","fill=0","QtTyp=P")} -> 829.35136 | R20: {=_xll.BDH(SUBSTITUTE(R$4," Corp","@ANDE Corp"),"PX_LAST",$C20,$C20,"days=all","dts=h","fill=0","QtTyp=P")} -> 684.89934 | S20: 0 | T20: 0 | U20: 0 | V20: 0 | W20: 0 | X20: 0 | Y20: 0 | Z20: 0 | AA20: 0 | AB20: 0 | AC20: 0 | AD20: 0 | AE20: 0 | AF20: 0 | AG20: 0 | AH20: 0 | AI20: 0 | AJ20: {=_xll.BDH(SUBSTITUTE(AJ$4," Corp","@ANDE Corp"),"PX_LAST",$C20,$C20,"days=all","dts=h","fill=0","QtTyp=P")} -> 1029.7286 | AK20: {=_xll.BDH(SUBSTITUTE(AK$4," Corp","@ANDE Corp"),"PX_LAST",$C20,$C20,"days=all","dts=h","fill=0","QtTyp=P")} -> 998.65005 | AL20: 0 | AM20: {=_xll.BDH(SUBSTITUTE(AM$4," Corp","@ANDE Corp"),"PX_LAST",$C20,$C20,"days=all","dts=h","fill=0","QtTyp=P")} -> 1030.9268 | AN20: {=_xll.BDH(SUBSTITUTE(AN$4," Corp","@ANDE Corp"),"PX_LAST",$C20,$C20,"days=all","dts=h","fill=0","QtTyp=P")} -> 966.38409 | AO20: {=_xll.BDH(SUBSTITUTE(AO$4," Corp","@ANDE Corp"),"PX_LAST",$C20,$C20,"days=all","dts=h","fill=0","QtTyp=P")} -> 1020.0227 | AP20: {=_xll.BDH(SUBSTITUTE(AP$4," Corp","@ANDE Corp"),"PX_LAST",$C20,$C20,"days=all","dts=h","fill=0","QtTyp=P")} -> 989.2914 | AQ20: {=_xll.BDH(SUBSTITUTE(AQ$4," Corp","@ANDE Corp"),"PX_LAST",$C20,$C20,"days=all","dts=h","fill=0","QtTyp=P")} -> 949.20418 | AR20: 0 | AS20: 0
C21: 41029 | D21: 0 | E21: 0 | F21: 0 | G21: {=_xll.BDH(SUBSTITUTE(G$4," Corp","@ANDE Corp"),"PX_LAST",$C21,$C21,"days=all","dts=h","fill=0","QtTyp=P")} -> 985.83029 | H21: 0 | I21: 0 | J21: {=_xll.BDH(SUBSTITUTE(J$4," Corp","@ANDE Corp"),"PX_LAST",$C21,$C21,"days=all","dts=h","fill=0","QtTyp=P")} -> 947.51729 | K21: {=_xll.BDH(SUBSTITUTE(K$4," Corp","@ANDE Corp"),"PX_LAST",$C21,$C21,"days=all","dts=h","fill=0","QtTyp=P")} -> 929.36986 | L21: {=_xll.BDH(SUBSTITUTE(L$4," Corp","@ANDE Corp"),"PX_LAST",$C21,$C21,"days=all","dts=h","fill=0","QtTyp=P")} -> 783.73912 | M21: 0 | N21: {=_xll.BDH(SUBSTITUTE(N$4," Corp","@ANDE Corp"),"PX_LAST",$C21,$C21,"days=all","dts=h","fill=0","QtTyp=P")} -> 910.22694 | O21: {=_xll.BDH(SUBSTITUTE(O$4," Corp","@ANDE Corp"),"PX_LAST",$C21,$C21,"days=all","dts=h","fill=0","QtTyp=P")} -> 966.25273 | P21: {=_xll.BDH(SUBSTITUTE(P$4," Corp","@ANDE Corp"),"PX_LAST",$C21,$C21,"days=all","dts=h","fill=0","QtTyp=P")} -> 867.51611 | Q21: {=_xll.BDH(SUBSTITUTE(Q$4," Corp","@ANDE Corp"),"PX_LAST",$C21,$C21,"days=all","dts=h","fill=0","QtTyp=P")} -> 847.63148 | R21: {=_xll.BDH(SUBSTITUTE(R$4," Corp","@ANDE Corp"),"PX_LAST",$C21,$C21,"days=all","dts=h","fill=0","QtTyp=P")} -> 705.15218 | S21: {=_xll.BDH(SUBSTITUTE(S$4," Corp","@ANDE Corp"),"PX_LAST",$C21,$C21,"days=all","dts=h","fill=0","QtTyp=P")} -> 826.59826 | T21: 0 | U21: 0 | V21: 0 | W21: 0 | X21: 0 | Y21: 0 | Z21: 0 | AA21: 0 | AB21: 0 | AC21: 0 | AD21: 0 | AE21: 0 | AF21: 0 | AG21: 0 | AH21: 0 | AI21: 0 | AJ21: {=_xll.BDH(SUBSTITUTE(AJ$4," Corp","@ANDE Corp"),"PX_LAST",$C21,$C21,"days=all","dts=h","fill=0","QtTyp=P")} -> 1048.4584 | AK21: {=_xll.BDH(SUBSTITUTE(AK$4," Corp","@ANDE Corp"),"PX_LAST",$C21,$C21,"days=all","dts=h","fill=0","QtTyp=P")} -> 1027.7157 | AL21: 0 | AM21: {=_xll.BDH(SUBSTITUTE(AM$4," Corp","@ANDE Corp"),"PX_LAST",$C21,$C21,"days=all","dts=h","fill=0","QtTyp=P")} -> 1041.8213 | AN21: {=_xll.BDH(SUBSTITUTE(AN$4," Corp","@ANDE Corp"),"PX_LAST",$C21,$C21,"days=all","dts=h","fill=0","QtTyp=P")} -> 995.55084 | AO21: {=_xll.BDH(SUBSTITUTE(AO$4," Corp","@ANDE Corp"),"PX_LAST",$C21,$C21,"days=all","dts=h","fill=0","QtTyp=P")} -> 1043.9167 | AP21: {=_xll.BDH(SUBSTITUTE(AP$4," Corp","@ANDE Corp"),"PX_LAST",$C21,$C21,"days=all","dts=h","fill=0","QtTyp=P")} -> 1019.5085 | AQ21: {=_xll.BDH(SUBSTITUTE(AQ$4," Corp","@ANDE Corp"),"PX_LAST",$C21,$C21,"days=all","dts=h","fill=0","QtTyp=P")} -> 982.0325 | AR21: 0 | AS21: 0
C22: 41060 | D22: 0 | E22: 0 | F22: 0 | G22: {=_xll.BDH(SUBSTITUTE(G$4," Corp","@ANDE Corp"),"PX_LAST",$C22,$C22,"days=all","dts=h","fill=0","QtTyp=P")} -> 993.21763 | H22: 0 | I22: 0 | J22: {=_xll.BDH(SUBSTITUTE(J$4," Corp","@ANDE Corp"),"PX_LAST",$C22,$C22,"days=all","dts=h","fill=0","QtTyp=P")} -> 955.97651 | K22: {=_xll.BDH(SUBSTITUTE(K$4," Corp","@ANDE Corp"),"PX_LAST",$C22,$C22,"days=all","dts=h","fill=0","QtTyp=P")} -> 938.63743 | L22: {=_xll.BDH(SUBSTITUTE(L$4," Corp","@ANDE Corp"),"PX_LAST",$C22,$C22,"days=all","dts=h","fill=0","QtTyp=P")} -> 799.45844 | M22: 0 | N22: {=_xll.BDH(SUBSTITUTE(N$4," Corp","@ANDE Corp"),"PX_LAST",$C22,$C22,"days=all","dts=h","fill=0","QtTyp=P")} -> 920.34404 | O22: {=_xll.BDH(SUBSTITUTE(O$4," Corp","@ANDE Corp"),"PX_LAST",$C22,$C22,"days=all","dts=h","fill=0","QtTyp=P")} -> 974.08968 | P22: {=_xll.BDH(SUBSTITUTE(P$4," Corp","@ANDE Corp"),"PX_LAST",$C22,$C22,"days=all","dts=h","fill=0","QtTyp=P")} -> 880.00491 | Q22: {=_xll.BDH(SUBSTITUTE(Q$4," Corp","@ANDE Corp"),"PX_LAST",$C22,$C22,"days=all","dts=h","fill=0","QtTyp=P")} -> 861.42953 | R22: {=_xll.BDH(SUBSTITUTE(R$4," Corp","@ANDE Corp"),"PX_LAST",$C22,$C22,"days=all","dts=h","fill=0","QtTyp=P")} -> 721.22345 | S22: {=_xll.BDH(SUBSTITUTE(S$4," Corp","@ANDE Corp"),"PX_LAST",$C22,$C22,"days=all","dts=h","fill=0","QtTyp=P")} -> 842.1819 | T22: 0 | U22: 0 | V22: 0 | W22: 0 | X22: 0 | Y22: 0 | Z22: 0 | AA22: 0 | AB22: 0 | AC22: 0 | AD22: 0 | AE22: 0 | AF22: 0 | AG22: 0 | AH22: 0 | AI22: 0 | AJ22: {=_xll.BDH(SUBSTITUTE(AJ$4," Corp","@ANDE Corp"),"PX_LAST",$C22,$C22,"days=all","dts=h","fill=0","QtTyp=P")} -> 1062.8678 | AK22: {=_xll.BDH(SUBSTITUTE(AK$4," Corp","@ANDE Corp"),"PX_LAST",$C22,$C22,"days=all","dts=h","fill=0","QtTyp=P")} -> 1052.227 | AL22: 0 | AM22: {=_xll.BDH(SUBSTITUTE(AM$4," Corp","@ANDE Corp"),"PX_LAST",$C22,$C22,"days=all","dts=h","fill=0","QtTyp=P")} -> 1051.0906 | AN22: {=_xll.BDH(SUBSTITUTE(AN$4," Corp","@ANDE Corp"),"PX_LAST",$C22,$C22,"days=all","dts=h","fill=0","QtTyp=P")} -> 1028.6747 | AO22: {=_xll.BDH(SUBSTITUTE(AO$4," Corp","@ANDE Corp"),"PX_LAST",$C22,$C22,"days=all","dts=h","fill=0","QtTyp=P")} -> 1064.2515 | AP22: {=_xll.BDH(SUBSTITUTE(AP$4," Corp","@ANDE Corp"),"PX_LAST",$C22,$C22,"days=all","dts=h","fill=0","QtTyp=P")} -> 1048.8336 | AQ22: {=_xll.BDH(SUBSTITUTE(AQ$4," Corp","@ANDE Corp"),"PX_LAST",$C22,$C22,"days=all","dts=h","fill=0","QtTyp=P")} -> 1010.2494 | AR22: 0 | AS22: 0
C23: 41089 | D23: 0 | E23: 0 | F23: 0 | G23: {=_xll.BDH(SUBSTITUTE(G$4," Corp","@ANDE Corp"),"PX_LAST",$C23,$C23,"days=all","dts=h","fill=0","QtTyp=P")} -> 999.67778 | H23: 0 | I23: 0 | J23: {=_xll.BDH(SUBSTITUTE(J$4," Corp","@ANDE Corp"),"PX_LAST",$C23,$C23,"days=all","dts=h","fill=0","QtTyp=P")} -> 963.53742 | K23: {=_xll.BDH(SUBSTITUTE(K$4," Corp","@ANDE Corp"),"PX_LAST",$C23,$C23,"days=all","dts=h","fill=0","QtTyp=P")} -> 947.13164 | L23: {=_xll.BDH(SUBSTITUTE(L$4," Corp","@ANDE Corp"),"PX_LAST",$C23,$C23,"days=all","dts=h","fill=0","QtTyp=P")} -> 813.12369 | M23: 0 | N23: {=_xll.BDH(SUBSTITUTE(N$4," Corp","@ANDE Corp"),"PX_LAST",$C23,$C23,"days=all","dts=h","fill=0","QtTyp=P")} -> 929.83132 | O23: {=_xll.BDH(SUBSTITUTE(O$4," Corp","@ANDE Corp"),"PX_LAST",$C23,$C23,"days=all","dts=h","fill=0","QtTyp=P")} -> 980.71307 | P23: {=_xll.BDH(SUBSTITUTE(P$4," Corp","@ANDE Corp"),"PX_LAST",$C23,$C23,"days=all","dts=h","fill=0","QtTyp=P")} -> 890.80046 | Q23: {=_xll.BDH(SUBSTITUTE(Q$4," Corp","@ANDE Corp"),"PX_LAST",$C23,$C23,"days=all","dts=h","fill=0","QtTyp=P")} -> 872.21523 | R23: {=_xll.BDH(SUBSTITUTE(R$4," Corp","@ANDE Corp"),"PX_LAST",$C23,$C23,"days=all","dts=h","fill=0","QtTyp=P")} -> 736.33994 | S23: {=_xll.BDH(SUBSTITUTE(S$4," Corp","@ANDE Corp"),"PX_LAST",$C23,$C23,"days=all","dts=h","fill=0","QtTyp=P")} -> 853.60471 | T23: 0 | U23: 0 | V23: 0 | W23: 0 | X23: 0 | Y23: 0 | Z23: 0 | AA23: 0 | AB23: 0 | AC23: 0 | AD23: 0 | AE23: 0 | AF23: 0 | AG23: 0 | AH23: 0 | AI23: 0 | AJ23: {=_xll.BDH(SUBSTITUTE(AJ$4," Corp","@ANDE Corp"),"PX_LAST",$C23,$C23,"days=all","dts=h","fill=0","QtTyp=P")} -> 1075.3639 | AK23: {=_xll.BDH(SUBSTITUTE(AK$4," Corp","@ANDE Corp"),"PX_LAST",$C23,$C23,"days=all","dts=h","fill=0","QtTyp=P")} -> 1075.0383 | AL23: 0 | AM23: {=_xll.BDH(SUBSTITUTE(AM$4," Corp","@ANDE Corp"),"PX_LAST",$C23,$C23,"days=all","dts=h","fill=0","QtTyp=P")} -> 1059.2854 | AN23: {=_xll.BDH(SUBSTITUTE(AN$4," Corp","@ANDE Corp"),"PX_LAST",$C23,$C23,"days=all","dts=h","fill=0","QtTyp=P")} -> 1054.4135 | AO23: {=_xll.BDH(SUBSTITUTE(AO$4," Corp","@ANDE Corp"),"PX_LAST",$C23,$C23,"days=all","dts=h","fill=0","QtTyp=P")} -> 1080.8415 | AP23: {=_xll.BDH(SUBSTITUTE(AP$4," Corp","@ANDE Corp"),"PX_LAST",$C23,$C23,"days=all","dts=h","fill=0","QtTyp=P")} -> 1069.0321 | AQ23: {=_xll.BDH(SUBSTITUTE(AQ$4," Corp","@ANDE Corp"),"PX_LAST",$C23,$C23,"days=all","dts=h","fill=0","QtTyp=P")} -> 1041.6604 | AR23: 0 | AS23: 0
C24: 41121 | D24: 0 | E24: 0 | F24: 0 | G24: 0 | H24: 0 | I24: 0 | J24: {=_xll.BDH(SUBSTITUTE(J$4," Corp","@ANDE Corp"),"PX_LAST",$C24,$C24,"days=all","dts=h","fill=0","QtTyp=P")} -> 970.63837 | K24: {=_xll.BDH(SUBSTITUTE(K$4," Corp","@ANDE Corp"),"PX_LAST",$C24,$C24,"days=all","dts=h","fill=0","QtTyp=P")} -> 954.58304 | L24: {=_xll.BDH(SUBSTITUTE(L$4," Corp","@ANDE Corp"),"PX_LAST",$C24,$C24,"days=all","dts=h","fill=0","QtTyp=P")} -> 821.66896 | M24: 0 | N24: {=_xll.BDH(SUBSTITUTE(N$4," Corp","@ANDE Corp"),"PX_LAST",$C24,$C24,"days=all","dts=h","fill=0","QtTyp=P")} -> 937.15717 | O24: {=_xll.BDH(SUBSTITUTE(O$4," Corp","@ANDE Corp"),"PX_LAST",$C24,$C24,"days=all","dts=h","fill=0","QtTyp=P")} -> 987.51372 | P24: {=_xll.BDH(SUBSTITUTE(P$4," Corp","@ANDE Corp"),"PX_LAST",$C24,$C24,"days=all","dts=h","fill=0","QtTyp=P")} -> 897.42989 | Q24: {=_xll.BDH(SUBSTITUTE(Q$4," Corp","@ANDE Corp"),"PX_LAST",$C24,$C24,"days=all","dts=h","fill=0","QtTyp=P")} -> 878.66948 | R24: {=_xll.BDH(SUBSTITUTE(R$4," Corp","@ANDE Corp"),"PX_LAST",$C24,$C24,"days=all","dts=h","fill=0","QtTyp=P")} -> 748.14921 | S24: {=_xll.BDH(SUBSTITUTE(S$4," Corp","@ANDE Corp"),"PX_LAST",$C24,$C24,"days=all","dts=h","fill=0","QtTyp=P")} -> 859.92482 | T24: {=_xll.BDH(SUBSTITUTE(T$4," Corp","@ANDE Corp"),"PX_LAST",$C24,$C24,"days=all","dts=h","fill=0","QtTyp=P")} -> 917.80031 | U24: 0 | V24: 0 | W24: 0 | X24: 0 | Y24: 0 | Z24: 0 | AA24: 0 | AB24: 0 | AC24: 0 | AD24: 0 | AE24: 0 | AF24: 0 | AG24: 0 | AH24: 0 | AI24: 0 | AJ24: {=_xll.BDH(SUBSTITUTE(AJ$4," Corp","@ANDE Corp"),"PX_LAST",$C24,$C24,"days=all","dts=h","fill=0","QtTyp=P")} -> 1034.2494 | AK24: {=_xll.BDH(SUBSTITUTE(AK$4," Corp","@ANDE Corp"),"PX_LAST",$C24,$C24,"days=all","dts=h","fill=0","QtTyp=P")} -> 1046.1198 | AL24: 0 | AM24: {=_xll.BDH(SUBSTITUTE(AM$4," Corp","@ANDE Corp"),"PX_LAST",$C24,$C24,"days=all","dts=h","fill=0","QtTyp=P")} -> 1017.9533 | AN24: {=_xll.BDH(SUBSTITUTE(AN$4," Corp","@ANDE Corp"),"PX_LAST",$C24,$C24,"days=all","dts=h","fill=0","QtTyp=P")} -> 1040.5249 | AO24: {=_xll.BDH(SUBSTITUTE(AO$4," Corp","@ANDE Corp"),"PX_LAST",$C24,$C24,"days=all","dts=h","fill=0","QtTyp=P")} -> 1042.5685 | AP24: {=_xll.BDH(SUBSTITUTE(AP$4," Corp","@ANDE Corp"),"PX_LAST",$C24,$C24,"days=all","dts=h","fill=0","QtTyp=P")} -> 1045.9845 | AQ24: {=_xll.BDH(SUBSTITUTE(AQ$4," Corp","@ANDE Corp"),"PX_LAST",$C24,$C24,"days=all","dts=h","fill=0","QtTyp=P")} -> 1035.5115 | AR24: 0 | AS24: 0
C25: 41152 | D25: 0 | E25: 0 | F25: 0 | G25: 0 | H25: 0 | I25: 0 | J25: {=_xll.BDH(SUBSTITUTE(J$4," Corp","@ANDE Corp"),"PX_LAST",$C25,$C25,"days=all","dts=h","fill=0","QtTyp=P")} -> 977.24674 | K25: {=_xll.BDH(SUBSTITUTE(K$4," Corp","@ANDE Corp"),"PX_LAST",$C25,$C25,"days=all","dts=h","fill=0","QtTyp=P")} -> 960.92719 | L25: {=_xll.BDH(SUBSTITUTE(L$4," Corp","@ANDE Corp"),"PX_LAST",$C25,$C25,"days=all","dts=h","fill=0","QtTyp=P")} -> 826.41284 | M25: 0 | N25: {=_xll.BDH(SUBSTITUTE(N$4," Corp","@ANDE Corp"),"PX_LAST",$C25,$C25,"days=all","dts=h","fill=0","QtTyp=P")} -> 943.4375 | O25: {=_xll.BDH(SUBSTITUTE(O$4," Corp","@ANDE Corp"),"PX_LAST",$C25,$C25,"days=all","dts=h","fill=0","QtTyp=P")} -> 994.35338 | P25: {=_xll.BDH(SUBSTITUTE(P$4," Corp","@ANDE Corp"),"PX_LAST",$C25,$C25,"days=all","dts=h","fill=0","QtTyp=P")} -> 904.06537 | Q25: {=_xll.BDH(SUBSTITUTE(Q$4," Corp","@ANDE Corp"),"PX_LAST",$C25,$C25,"days=all","dts=h","fill=0","QtTyp=P")} -> 884.81074 | R25: {=_xll.BDH(SUBSTITUTE(R$4," Corp","@ANDE Corp"),"PX_LAST",$C25,$C25,"days=all","dts=h","fill=0","QtTyp=P")} -> 754.07191 | S25: {=_xll.BDH(SUBSTITUTE(S$4," Corp","@ANDE Corp"),"PX_LAST",$C25,$C25,"days=all","dts=h","fill=0","QtTyp=P")} -> 865.91893 | T25: {=_xll.BDH(SUBSTITUTE(T$4," Corp","@ANDE Corp"),"PX_LAST",$C25,$C25,"days=all","dts=h","fill=0","QtTyp=P")} -> 924.10441 | U25: 0 | V25: 0 | W25: 0 | X25: 0 | Y25: 0 | Z25: 0 | AA25: 0 | AB25: 0 | AC25: 0 | AD25: 0 | AE25: 0 | AF25: 0 | AG25: 0 | AH25: 0 | AI25: 0 | AJ25: {=_xll.BDH(SUBSTITUTE(AJ$4," Corp","@ANDE Corp"),"PX_LAST",$C25,$C25,"days=all","dts=h","fill=0","QtTyp=P")} -> 1041.6664 | AK25: {=_xll.BDH(SUBSTITUTE(AK$4," Corp","@ANDE Corp"),"PX_LAST",$C25,$C25,"days=all","dts=h","fill=0","QtTyp=P")} -> 1052.8485 | AL25: 0 | AM25: {=_xll.BDH(SUBSTITUTE(AM$4," Corp","@ANDE Corp"),"PX_LAST",$C25,$C25,"days=all","dts=h","fill=0","QtTyp=P")} -> 1024.9537 | AN25: {=_xll.BDH(SUBSTITUTE(AN$4," Corp","@ANDE Corp"),"PX_LAST",$C25,$C25,"days=all","dts=h","fill=0","QtTyp=P")} -> 1048.6951 | AO25: {=_xll.BDH(SUBSTITUTE(AO$4," Corp","@ANDE Corp"),"PX_LAST",$C25,$C25,"days=all","dts=h","fill=0","QtTyp=P")} -> 1048.5301 | AP25: {=_xll.BDH(SUBSTITUTE(AP$4," Corp","@ANDE Corp"),"PX_LAST",$C25,$C25,"days=all","dts=h","fill=0","QtTyp=P")} -> 1054.4863 | AQ25: {=_xll.BDH(SUBSTITUTE(AQ$4," Corp","@ANDE Corp"),"PX_LAST",$C25,$C25,"days=all","dts=h","fill=0","QtTyp=P")} -> 1044.3874 | AR25: 0 | AS25: 0
C26: 41180 | D26: 0 | E26: 0 | F26: 0 | G26: 0 | H26: 0 | I26: 0 | J26: {=_xll.BDH(SUBSTITUTE(J$4," Corp","@ANDE Corp"),"PX_LAST",$C26,$C26,"days=all","dts=h","fill=0","QtTyp=P")} -> 982.52336 | K26: {=_xll.BDH(SUBSTITUTE(K$4," Corp","@ANDE Corp"),"PX_LAST",$C26,$C26,"days=all","dts=h","fill=0","QtTyp=P")} -> 966.10674 | L26: {=_xll.BDH(SUBSTITUTE(L$4," Corp","@ANDE Corp"),"PX_LAST",$C26,$C26,"days=all","dts=h","fill=0","QtTyp=P")} -> 833.94907 | M26: 0 | N26: {=_xll.BDH(SUBSTITUTE(N$4," Corp","@ANDE Corp"),"PX_LAST",$C26,$C26,"days=all","dts=h","fill=0","QtTyp=P")} -> 948.79742 | O26: {=_xll.BDH(SUBSTITUTE(O$4," Corp","@ANDE Corp"),"PX_LAST",$C26,$C26,"days=all","dts=h","fill=0","QtTyp=P")} -> 999.71592 | P26: {=_xll.BDH(SUBSTITUTE(P$4," Corp","@ANDE Corp"),"PX_LAST",$C26,$C26,"days=all","dts=h","fill=0","QtTyp=P")} -> 910.5118 | Q26: {=_xll.BDH(SUBSTITUTE(Q$4," Corp","@ANDE Corp"),"PX_LAST",$C26,$C26,"days=all","dts=h","fill=0","QtTyp=P")} -> 891.87355 | R26: {=_xll.BDH(SUBSTITUTE(R$4," Corp","@ANDE Corp"),"PX_LAST",$C26,$C26,"days=all","dts=h","fill=0","QtTyp=P")} -> 759.5617 | S26: {=_xll.BDH(SUBSTITUTE(S$4," Corp","@ANDE Corp"),"PX_LAST",$C26,$C26,"days=all","dts=h","fill=0","QtTyp=P")} -> 873.44659 | T26: {=_xll.BDH(SUBSTITUTE(T$4," Corp","@ANDE Corp"),"PX_LAST",$C26,$C26,"days=all","dts=h","fill=0","QtTyp=P")} -> 929.8658 | U26: 0 | V26: 0 | W26: 0 | X26: 0 | Y26: 0 | Z26: 0 | AA26: 0 | AB26: 0 | AC26: 0 | AD26: 0 | AE26: 0 | AF26: 0 | AG26: 0 | AH26: 0 | AI26: 0 | AJ26: {=_xll.BDH(SUBSTITUTE(AJ$4," Corp","@ANDE Corp"),"PX_LAST",$C26,$C26,"days=all","dts=h","fill=0","QtTyp=P")} -> 1049.1872 | AK26: {=_xll.BDH(SUBSTITUTE(AK$4," Corp","@ANDE Corp"),"PX_LAST",$C26,$C26,"days=all","dts=h","fill=0","QtTyp=P")} -> 1058.1534 | AL26: 0 | AM26: {=_xll.BDH(SUBSTITUTE(AM$4," Corp","@ANDE Corp"),"PX_LAST",$C26,$C26,"days=all","dts=h","fill=0","QtTyp=P")} -> 1030.4742 | AN26: {=_xll.BDH(SUBSTITUTE(AN$4," Corp","@ANDE Corp"),"PX_LAST",$C26,$C26,"days=all","dts=h","fill=0","QtTyp=P")} -> 1045.3045 | AO26: {=_xll.BDH(SUBSTITUTE(AO$4," Corp","@ANDE Corp"),"PX_LAST",$C26,$C26,"days=all","dts=h","fill=0","QtTyp=P")} -> 1057.4379 | AP26: {=_xll.BDH(SUBSTITUTE(AP$4," Corp","@ANDE Corp"),"PX_LAST",$C26,$C26,"days=all","dts=h","fill=0","QtTyp=P")} -> 1057.6007 | AQ26: {=_xll.BDH(SUBSTITUTE(AQ$4," Corp","@ANDE Corp"),"PX_LAST",$C26,$C26,"days=all","dts=h","fill=0","QtTyp=P")} -> 1039.6268 | AR26: 0 | AS26: 0
C27: 41213 | D27: 0 | E27: 0 | F27: 0 | G27: 0 | H27: 0 | I27: 0 | J27: {=_xll.BDH(SUBSTITUTE(J$4," Corp","@ANDE Corp"),"PX_LAST",$C27,$C27,"days=all","dts=h","fill=0","QtTyp=P")} -> 988.83797 | K27: {=_xll.BDH(SUBSTITUTE(K$4," Corp","@ANDE Corp"),"PX_LAST",$C27,$C27,"days=all","dts=h","fill=0","QtTyp=P")} -> 972.71293 | L27: {=_xll.BDH(SUBSTITUTE(L$4," Corp","@ANDE Corp"),"PX_LAST",$C27,$C27,"days=all","dts=h","fill=0","QtTyp=P")} -> 848.39772 | M27: 0 | N27: {=_xll.BDH(SUBSTITUTE(N$4," Corp","@ANDE Corp"),"PX_LAST",$C27,$C27,"days=all","dts=h","fill=0","QtTyp=P")} -> 956.10782 | O27: 0 | P27: {=_xll.BDH(SUBSTITUTE(P$4," Corp","@ANDE Corp"),"PX_LAST",$C27,$C27,"days=all","dts=h","fill=0","QtTyp=P")} -> 920.33475 | Q27: {=_xll.BDH(SUBSTITUTE(Q$4," Corp","@ANDE Corp"),"PX_LAST",$C27,$C27,"days=all","dts=h","fill=0","QtTyp=P")} -> 902.90219 | R27: {=_xll.BDH(SUBSTITUTE(R$4," Corp","@ANDE Corp"),"PX_LAST",$C27,$C27,"days=all","dts=h","fill=0","QtTyp=P")} -> 777.84923 | S27: {=_xll.BDH(SUBSTITUTE(S$4," Corp","@ANDE Corp"),"PX_LAST",$C27,$C27,"days=all","dts=h","fill=0","QtTyp=P")} -> 885.56145 | T27: {=_xll.BDH(SUBSTITUTE(T$4," Corp","@ANDE Corp"),"PX_LAST",$C27,$C27,"days=all","dts=h","fill=0","QtTyp=P")} -> 938.28504 | U27: {=_xll.BDH(SUBSTITUTE(U$4," Corp","@ANDE Corp"),"PX_LAST",$C27,$C27,"days=all","dts=h","fill=0","QtTyp=P")} -> 830.90924 | V27: {=_xll.BDH(SUBSTITUTE(V$4," Corp","@ANDE Corp"),"PX_LAST",$C27,$C27,"days=all","dts=h","fill=0","QtTyp=P")} -> 743.55759 | W27: 0 | X27: 0 | Y27: 0 | Z27: 0 | AA27: 0 | AB27: 0 | AC27: 0 | AD27: 0 | AE27: 0 | AF27: 0 | AG27: 0 | AH27: 0 | AI27: 0 | AJ27: {=_xll.BDH(SUBSTITUTE(AJ$4," Corp","@ANDE Corp"),"PX_LAST",$C27,$C27,"days=all","dts=h","fill=0","QtTyp=P")} -> 1060.0796 | AK27: {=_xll.BDH(SUBSTITUTE(AK$4," Corp","@ANDE Corp"),"PX_LAST",$C27,$C27,"days=all","dts=h","fill=0","QtTyp=P")} -> 1086.1024 | AL27: 0 | AM27: {=_xll.BDH(SUBSTITUTE(AM$4," Corp","@ANDE Corp"),"PX_LAST",$C27,$C27,"days=all","dts=h","fill=0","QtTyp=P")} -> 1037.0987 | AN27: {=_xll.BDH(SUBSTITUTE(AN$4," Corp","@ANDE Corp"),"PX_LAST",$C27,$C27,"days=all","dts=h","fill=0","QtTyp=P")} -> 1088.9809 | AO27: {=_xll.BDH(SUBSTITUTE(AO$4," Corp","@ANDE Corp"),"PX_LAST",$C27,$C27,"days=all","dts=h","fill=0","QtTyp=P")} -> 1074.7848 | AP27: {=_xll.BDH(SUBSTITUTE(AP$4," Corp","@ANDE Corp"),"PX_LAST",$C27,$C27,"days=all","dts=h","fill=0","QtTyp=P")} -> 1089.7109 | AQ27: {=_xll.BDH(SUBSTITUTE(AQ$4," Corp","@ANDE Corp"),"PX_LAST",$C27,$C27,"days=all","dts=h","fill=0","QtTyp=P")} -> 1087.1329 | AR27: 0 | AS27: 0
C28: 41243 | D28: 0 | E28: 0 | F28: 0 | G28: 0 | H28: 0 | I28: 0 | J28: {=_xll.BDH(SUBSTITUTE(J$4," Corp","@ANDE Corp"),"PX_LAST",$C28,$C28,"days=all","dts=h","fill=0","QtTyp=P")} -> 994.2502 | K28: {=_xll.BDH(SUBSTITUTE(K$4," Corp","@ANDE Corp"),"PX_LAST",$C28,$C28,"days=all","dts=h","fill=0","QtTyp=P")} -> 978.1657 | L28: {=_xll.BDH(SUBSTITUTE(L$4," Corp","@ANDE Corp"),"PX_LAST",$C28,$C28,"days=all","dts=h","fill=0","QtTyp=P")} -> 853.45173 | M28: 0 | N28: {=_xll.BDH(SUBSTITUTE(N$4," Corp","@ANDE Corp"),"PX_LAST",$C28,$C28,"days=all","dts=h","fill=0","QtTyp=P")} -> 961.57003 | O28: 0 | P28: {=_xll.BDH(SUBSTITUTE(P$4," Corp","@ANDE Corp"),"PX_LAST",$C28,$C28,"days=all","dts=h","fill=0","QtTyp=P")} -> 926.94927 | Q28: {=_xll.BDH(SUBSTITUTE(Q$4," Corp","@ANDE Corp"),"PX_LAST",$C28,$C28,"days=all","dts=h","fill=0","QtTyp=P")} -> 910.1006 | R28: {=_xll.BDH(SUBSTITUTE(R$4," Corp","@ANDE Corp"),"PX_LAST",$C28,$C28,"days=all","dts=h","fill=0","QtTyp=P")} -> 779.15478 | S28: {=_xll.BDH(SUBSTITUTE(S$4," Corp","@ANDE Corp"),"PX_LAST",$C28,$C28,"days=all","dts=h","fill=0","QtTyp=P")} -> 892.73631 | T28: {=_xll.BDH(SUBSTITUTE(T$4," Corp","@ANDE Corp"),"PX_LAST",$C28,$C28,"days=all","dts=h","fill=0","QtTyp=P")} -> 944.30493 | U28: {=_xll.BDH(SUBSTITUTE(U$4," Corp","@ANDE Corp"),"PX_LAST",$C28,$C28,"days=all","dts=h","fill=0","QtTyp=P")} -> 835.10131 | V28: {=_xll.BDH(SUBSTITUTE(V$4," Corp","@ANDE Corp"),"PX_LAST",$C28,$C28,"days=all","dts=h","fill=0","QtTyp=P")} -> 743.90372 | W28: 0 | X28: 0 | Y28: 0 | Z28: 0 | AA28: 0 | AB28: 0 | AC28: 0 | AD28: 0 | AE28: 0 | AF28: 0 | AG28: 0 | AH28: 0 | AI28: 0 | AJ28: {=_xll.BDH(SUBSTITUTE(AJ$4," Corp","@ANDE Corp"),"PX_LAST",$C28,$C28,"days=all","dts=h","fill=0","QtTyp=P")} -> 1067.634 | AK28: {=_xll.BDH(SUBSTITUTE(AK$4," Corp","@ANDE Corp"),"PX_LAST",$C28,$C28,"days=all","dts=h","fill=0","QtTyp=P")} -> 1085.6708 | AL28: 0 | AM28: {=_xll.BDH(SUBSTITUTE(AM$4," Corp","@ANDE Corp"),"PX_LAST",$C28,$C28,"days=all","dts=h","fill=0","QtTyp=P")} -> 1042.7787 | AN28: {=_xll.BDH(SUBSTITUTE(AN$4," Corp","@ANDE Corp"),"PX_LAST",$C28,$C28,"days=all","dts=h","fill=0","QtTyp=P")} -> 1082.5505 | AO28: {=_xll.BDH(SUBSTITUTE(AO$4," Corp","@ANDE Corp"),"PX_LAST",$C28,$C28,"days=all","dts=h","fill=0","QtTyp=P")} -> 1081.2883 | AP28: {=_xll.BDH(SUBSTITUTE(AP$4," Corp","@ANDE Corp"),"PX_LAST",$C28,$C28,"days=all","dts=h","fill=0","QtTyp=P")} -> 1087.4465 | AQ28: {=_xll.BDH(SUBSTITUTE(AQ$4," Corp","@ANDE Corp"),"PX_LAST",$C28,$C28,"days=all","dts=h","fill=0","QtTyp=P")} -> 1076.2072 | AR28: 0 | AS28: 0
